File: TensionLab/experimentalData/1018 Steel Sample 1.csv
Time (s),Extension (mm),Load (N),Axial Strain (mm/mm),Transverse Strain (mm/mm),Thickness(m),Width(m),Final length(m),Axial gauge length(m),Transverse gauge length(m),Crosshead Rate(mm/min)
0,0,0.1,0,0,0.00624,0.01238,0.05702,0.0254,0.01238,5
0.1,0.004,21.82,0,0,,,,,,
0.2,0.014,214.86,0.00001,0,,,,,,
0.3,0.024,359.52,0.00003,0,,,,,,
0.4,0.033,450.6,0.00003,0.00001,,,,,,
0.5,0.042,552.33,0.00004,0.00002,,,,,,
0.6,0.05,608.29,0.00005,0.00002,,,,,,
0.7,0.058,714.68,0.00005,0.00002,,,,,,
0.8,0.067,786.1,0.00006,0.00002,,,,,,
0.9,0.075,874.52,0.00007,0.00003,,,,,,
1,0.084,979.49,0.00008,0.00003,,,,,,
1.1,0.092,1044.29,0.00009,0.00003,,,,,,
1.2,0.1,1157.22,0.0001,0.00004,,,,,,
1.3,0.109,1225.18,0.0001,0.00004,,,,,,
1.4,0.117,1324.88,0.0001,0.00004,,,,,,
1.5,0.125,1426.31,0.00011,0.00005,,,,,,
1.6,0.134,1539.06,0.00011,0.00005,,,,,,
1.7,0.142,1629.77,0.00011,0.00005,,,,,,
1.8,0.15,1770.52,0.00012,0.00005,,,,,,
1.9,0.159,1855.23,0.00012,0.00005,,,,,,
2,0.167,1988.62,0.00012,0.00006,,,,,,
2.1,0.175,2077.79,0.00013,0.00006,,,,,,
2.2,0.184,2180.04,0.00013,0.00006,,,,,,
2.3,0.192,2279.3,0.00013,0.00006,,,,,,
2.4,0.2,2395.8,0.00014,0.00006,,,,,,
2.5,0.208,2465.49,0.00014,0.00006,,,,,,
2.6,0.217,2594.92,0.00014,0.00006,,,,,,
2.7,0.225,2675.23,0.00015,0.00006,,,,,,
2.8,0.233,2776.44,0.00015,0.00006,,,,,,
2.9,0.242,2869.55,0.00015,0.00006,,,,,,
3,0.25,2978.25,0.00015,0.00006,,,,,,
3.1,0.259,3053.37,0.00016,0.00006,,,,,,
3.2,0.267,3165.77,0.00016,0.00006,,,,,,
3.3,0.275,3262.9,0.00016,0.00006,,,,,,
3.4,0.283,3347.59,0.00016,0.00006,,,,,,
3.5,0.292,3463.74,0.00016,0.00006,,,,,,
3.6,0.3,3558.18,0.00016,0.00006,,,,,,
3.7,0.309,3651.96,0.00016,0.00006,,,,,,
3.8,0.317,3748.07,0.00016,0.00005,,,,,,
3.9,0.325,3849.88,0.00016,0.00005,,,,,,
4,0.333,3919.33,0.00016,0.00005,,,,,,
4.1,0.342,4029.42,0.00016,0.00005,,,,,,
4.2,0.35,4102.82,0.00016,0.00005,,,,,,
4.3,0.358,4196.16,0.00016,0.00005,,,,,,
4.4,0.367,4282.89,0.00016,0.00005,,,,,,
4.5,0.375,4376.44,0.00016,0.00005,,,,,,
4.6,0.383,4469.62,0.00016,0.00005,,,,,,
4.7,0.392,4521.57,0.00016,0.00005,,,,,,
4.8,0.4,4621.38,0.00016,0.00005,,,,,,
4.9,0.409,4691.52,0.00016,0.00005,,,,,,
5,0.417,4770.72,0.00016,0.00005,,,,,,
5.1,0.425,4847.68,0.00016,0.00005,,,,,,
5.2,0.434,4924.49,0.00016,0.00005,,,,,,
5.3,0.442,4995.15,0.00016,0.00005,,,,,,
5.4,0.45,5100.06,0.00017,0.00005,,,,,,
5.5,0.458,5152.01,0.00017,0.00005,,,,,,
5.6,0.467,5238.78,0.00017,0.00005,,,,,,
5.7,0.475,5326.61,0.00017,0.00005,,,,,,
5.8,0.484,5405.45,0.00017,0.00005,,,,,,
5.9,0.492,5493.23,0.00017,0.00005,,,,,,
6,0.5,5555.87,0.00018,0.00005,,,,,,
6.1,0.508,5657.74,0.00018,0.00006,,,,,,
6.2,0.517,5736.38,0.00018,0.00005,,,,,,
6.3,0.525,5809.1,0.00019,0.00006,,,,,,
6.4,0.533,5908.36,0.00019,0.00006,,,,,,
6.5,0.542,5982.32,0.00019,0.00006,,,,,,
6.6,0.55,6066.1,0.0002,0.00006,,,,,,
6.7,0.558,6143.65,0.0002,0.00006,,,,,,
6.8,0.567,6246.46,0.00021,0.00006,,,,,,
6.9,0.575,6343.91,0.00021,0.00006,,,,,,
7,0.583,6398.89,0.00021,0.00006,,,,,,
7.1,0.592,6508.93,0.00021,0.00006,,,,,,
7.2,0.6,6595.58,0.00022,0.00006,,,,,,
7.3,0.608,6665.29,0.00023,0.00006,,,,,,
7.4,0.617,6770.64,0.00023,0.00006,,,,,,
7.5,0.625,6879.22,0.00023,0.00006,,,,,,
7.6,0.633,6949.85,0.00024,0.00007,,,,,,
7.7,0.642,7043.66,0.00024,0.00007,,,,,,
7.8,0.65,7156.99,0.00024,0.00007,,,,,,
7.9,0.658,7212.97,0.00025,0.00007,,,,,,
8,0.667,7333.13,0.00025,0.00007,,,,,,
8.1,0.675,7416.34,0.00026,0.00007,,,,,,
8.2,0.683,7503.47,0.00026,0.00007,,,,,,
8.3,0.692,7592.06,0.00027,0.00007,,,,,,
8.4,0.7,7703.14,0.00027,0.00007,,,,,,
8.5,0.709,7794.28,0.00028,0.00008,,,,,,
8.6,0.717,7885.17,0.00028,0.00008,,,,,,
8.7,0.725,7998.32,0.00029,0.00008,,,,,,
8.8,0.733,8080.08,0.00029,0.00008,,,,,,
8.9,0.742,8185.69,0.0003,0.00008,,,,,,
9,0.75,8280.44,0.0003,0.00008,,,,,,
9.1,0.758,8381.91,0.00031,0.00008,,,,,,
9.2,0.767,8462.4,0.00031,0.00009,,,,,,
9.3,0.775,8586.74,0.00032,0.00009,,,,,,
9.4,0.783,8660.87,0.00032,0.00009,,,,,,
9.5,0.792,8771.71,0.00033,0.00009,,,,,,
9.6,0.8,8863.18,0.00033,0.00009,,,,,,
9.7,0.808,8980.38,0.00034,0.00009,,,,,,
9.8,0.817,9064.37,0.00034,0.00009,,,,,,
9.9,0.825,9176.1,0.00034,0.0001,,,,,,
10,0.833,9278.2,0.00035,0.0001,,,,,,
10.1,0.842,9394.08,0.00036,0.0001,,,,,,
10.2,0.85,9472.09,0.00037,0.0001,,,,,,
10.3,0.859,9610.59,0.00037,0.0001,,,,,,
10.4,0.867,9694.21,0.00037,0.00011,,,,,,
10.5,0.875,9813.77,0.00038,0.00011,,,,,,
10.6,0.884,9925.51,0.00039,0.00011,,,,,,
10.7,0.892,10032.05,0.00039,0.00011,,,,,,
10.8,0.9,10137.39,0.0004,0.00011,,,,,,
10.9,0.908,10271.59,0.00041,0.00012,,,,,,
11,0.917,10356.82,0.00041,0.00012,,,,,,
11.1,0.925,10481.99,0.00042,0.00012,,,,,,
11.2,0.933,10584.32,0.00042,0.00012,,,,,,
11.3,0.942,10694.69,0.00043,0.00013,,,,,,
11.4,0.95,10817.98,0.00044,0.00013,,,,,,
11.5,0.958,10895.53,0.00044,0.00013,,,,,,
11.6,0.967,11026.72,0.00045,0.00014,,,,,,
11.7,0.975,11134.68,0.00046,0.00014,,,,,,
11.8,0.984,11264.61,0.00046,0.00014,,,,,,
11.9,0.992,11366.41,0.00047,0.00015,,,,,,
12,1,11477.15,0.00048,0.00015,,,,,,
12.1,1.008,11592.05,0.00048,0.00016,,,,,,
12.2,1.017,11717.21,0.00049,0.00016,,,,,,
12.3,1.025,11821.44,0.0005,0.00016,,,,,,
12.4,1.034,11942.29,0.0005,0.00016,,,,,,
12.5,1.042,12043.9,0.00051,0.00016,,,,,,
12.6,1.05,12156.16,0.00052,0.00017,,,,,,
12.7,1.058,12289.32,0.00052,0.00017,,,,,,
12.8,1.067,12387.84,0.00053,0.00017,,,,,,
12.9,1.075,12530,0.00054,0.00018,,,,,,
13,1.083,12638.69,0.00054,0.00018,,,,,,
13.1,1.092,12749.74,0.00055,0.00018,,,,,,
13.2,1.1,12862.38,0.00056,0.00019,,,,,,
13.3,1.109,12980.45,0.00057,0.00019,,,,,,
13.4,1.117,13107.78,0.00057,0.00019,,,,,,
13.5,1.125,13213.7,0.00058,0.00019,,,,,,
13.6,1.133,13348.29,0.00059,0.0002,,,,,,
13.7,1.142,13451.6,0.00059,0.0002,,,,,,
13.8,1.15,13581.88,0.0006,0.0002,,,,,,
13.9,1.158,13685.51,0.00061,0.0002,,,,,,
14,1.167,13815.96,0.00062,0.00021,,,,,,
14.1,1.175,13946.13,0.00063,0.00021,,,,,,
14.2,1.183,14053.78,0.00063,0.00021,,,,,,
14.3,1.192,14197.53,0.00064,0.00022,,,,,,
14.4,1.2,14296.16,0.00065,0.00022,,,,,,
14.5,1.209,14420.31,0.00065,0.00023,,,,,,
14.6,1.217,14539.03,0.00066,0.00023,,,,,,
14.7,1.225,14657.91,0.00067,0.00023,,,,,,
14.8,1.234,14803.59,0.00068,0.00024,,,,,,
14.9,1.242,14910.38,0.00069,0.00024,,,,,,
15,1.25,15043.2,0.00069,0.00024,,,,,,
15.1,1.259,15161.64,0.0007,0.00025,,,,,,
15.2,1.267,15293.09,0.00071,0.00025,,,,,,
15.3,1.275,15415.17,0.00072,0.00026,,,,,,
15.4,1.284,15542.31,0.00073,0.00026,,,,,,
15.5,1.292,15658.2,0.00073,0.00026,,,,,,
15.6,1.3,15792.05,0.00074,0.00027,,,,,,
15.7,1.308,15913.34,0.00075,0.00027,,,,,,
15.8,1.317,16046.47,0.00076,0.00027,,,,,,
15.9,1.325,16170.69,0.00077,0.00027,,,,,,
16,1.333,16284.31,0.00077,0.00028,,,,,,
16.1,1.342,16446.17,0.00079,0.00028,,,,,,
16.2,1.35,16549.57,0.00079,0.00028,,,,,,
16.3,1.358,16674.86,0.0008,0.00029,,,,,,
16.4,1.367,16810.62,0.00081,0.00029,,,,,,
16.5,1.375,16934.05,0.00082,0.0003,,,,,,
16.6,1.383,17072.69,0.00082,0.0003,,,,,,
16.7,1.392,17197.99,0.00083,0.00031,,,,,,
16.8,1.4,17315.55,0.00084,0.00031,,,,,,
16.9,1.408,17469.76,0.00085,0.00031,,,,,,
17,1.417,17588.79,0.00086,0.00032,,,,,,
17.1,1.425,17714.13,0.00087,0.00032,,,,,,
17.2,1.433,17858.17,0.00088,0.00033,,,,,,
17.3,1.442,17968.75,0.00089,0.00033,,,,,,
17.4,1.45,18124.07,0.0009,0.00033,,,,,,
17.5,1.458,18228.66,0.0009,0.00034,,,,,,
17.6,1.467,18367.68,0.00092,0.00034,,,,,,
17.7,1.475,18500.22,0.00092,0.00034,,,,,,
17.8,1.483,18640.62,0.00093,0.00035,,,,,,
17.9,1.492,18749.08,0.00094,0.00035,,,,,,
18,1.5,18905.47,0.00095,0.00036,,,,,,
18.1,1.508,19030.84,0.00096,0.00036,,,,,,
18.2,1.517,19157.71,0.00097,0.00037,,,,,,
18.3,1.525,19310.05,0.00098,0.00037,,,,,,
18.4,1.533,19430.76,0.00099,0.00037,,,,,,
18.5,1.542,19572.85,0.001,0.00038,,,,,,
18.6,1.55,19700.01,0.00101,0.00038,,,,,,
18.7,1.558,19833.64,0.00101,0.00039,,,,,,
18.8,1.567,19963.95,0.00102,0.00039,,,,,,
18.9,1.575,20104.94,0.00103,0.0004,,,,,,
19,1.583,20220.55,0.00105,0.0004,,,,,,
19.1,1.592,20371.82,0.00106,0.00041,,,,,,
19.2,1.6,20503.46,0.00107,0.00041,,,,,,
19.3,1.608,20629.74,0.00108,0.00042,,,,,,
19.4,1.617,20772.68,0.00108,0.00042,,,,,,
19.5,1.625,20904.23,0.00109,0.00043,,,,,,
19.6,1.633,21025.53,0.00111,0.00043,,,,,,
19.7,1.642,21180.21,0.00111,0.00044,,,,,,
19.8,1.65,21303.64,0.00112,0.00044,,,,,,
19.9,1.659,21438.68,0.00113,0.00045,,,,,,
20,1.667,21575.95,0.00115,0.00045,,,,,,
20.1,1.675,21713.46,0.00116,0.00046,,,,,,
20.2,1.683,21834.74,0.00117,0.00047,,,,,,
20.3,1.692,21992.04,0.00118,0.00047,,,,,,
20.4,1.7,22118.73,0.00119,0.00048,,,,,,
20.5,1.708,22254.32,0.0012,0.00048,,,,,,
20.6,1.717,22394.25,0.00121,0.00048,,,,,,
20.7,1.725,22516,0.00122,0.00049,,,,,,
20.8,1.734,22666.34,0.00123,0.00049,,,,,,
20.9,1.742,22801.5,0.00124,0.0005,,,,,,
21,1.75,22928.49,0.00125,0.00051,,,,,,
21.1,1.758,23057.79,0.00126,0.00051,,,,,,
21.2,1.767,23215.51,0.00127,0.00052,,,,,,
21.3,1.775,23321.3,0.00128,0.00053,,,,,,
21.4,1.783,23484.2,0.0013,0.00053,,,,,,
21.5,1.792,23604.83,0.00131,0.00054,,,,,,
21.6,1.8,23750.77,0.00132,0.00054,,,,,,
21.7,1.808,23883.84,0.00133,0.00055,,,,,,
21.8,1.817,24014.46,0.00134,0.00055,,,,,,
21.9,1.825,24136.95,0.00135,0.00056,,,,,,
22,1.834,24300.88,0.00136,0.00056,,,,,,
22.1,1.842,24422.73,0.00138,0.00057,,,,,,
22.2,1.85,24541.72,0.00139,0.00058,,,,,,
22.3,1.858,24695.98,0.0014,0.00058,,,,,,
22.4,1.867,24835.94,0.00141,0.00059,,,,,,
22.5,1.875,24957.36,0.00142,0.00059,,,,,,
22.6,1.883,25117.54,0.00144,0.0006,,,,,,
22.7,1.892,25233.54,0.00145,0.00061,,,,,,
22.8,1.9,25376.66,0.00146,0.00062,,,,,,
22.9,1.908,25523.42,0.00147,0.00062,,,,,,
23,1.917,25658.9,0.00149,0.00063,,,,,,
23.1,1.925,25776.39,0.0015,0.00063,,,,,,
23.2,1.933,25944.98,0.00151,0.00064,,,,,,
23.3,1.942,26061.21,0.00152,0.00065,,,,,,
23.4,1.95,26201.61,0.00153,0.00065,,,,,,
23.5,1.958,26351.84,0.00154,0.00066,,,,,,
23.6,1.967,26482.72,0.00156,0.00067,,,,,,
23.7,1.975,26615.04,0.00157,0.00067,,,,,,
23.8,1.983,26764.32,0.00158,0.00068,,,,,,
23.9,1.992,26893.84,0.0016,0.00069,,,,,,
24,2,27024.25,0.00161,0.00069,,,,,,
24.1,2.009,27183.94,0.00162,0.0007,,,,,,
24.2,2.017,27298.08,0.00164,0.00071,,,,,,
24.3,2.025,27442.01,0.00165,0.00071,,,,,,
24.4,2.033,27586.87,0.00166,0.00072,,,,,,
24.5,2.042,27719.22,0.00167,0.00073,,,,,,
24.6,2.05,27847.94,0.00169,0.00074,,,,,,
24.7,2.058,28012.76,0.00171,0.00074,,,,,,
24.8,2.067,28126.71,0.00172,0.00075,,,,,,
24.9,2.075,28262.8,0.00173,0.00076,,,,,,
25,2.083,28417.93,0.00174,0.00077,,,,,,
25.1,2.092,28540.27,0.00176,0.00078,,,,,,
25.2,2.1,28670.66,0.00177,0.00078,,,,,,
25.3,2.109,28832.52,0.00179,0.00079,,,,,,
25.4,2.117,28948.97,0.0018,0.0008,,,,,,
25.5,2.125,29085.28,0.00181,0.00081,,,,,,
25.6,2.133,29243.41,0.00183,0.00081,,,,,,
25.7,2.142,29374.04,0.00184,0.00082,,,,,,
25.8,2.15,29488.46,0.00186,0.00083,,,,,,
25.9,2.158,29654.16,0.00187,0.00084,,,,,,
26,2.167,29762.23,0.00188,0.00085,,,,,,
26.1,2.175,29915.42,0.0019,0.00086,,,,,,
26.2,2.184,30053.29,0.00192,0.00087,,,,,,
26.3,2.192,30180.56,0.00193,0.00088,,,,,,
26.4,2.2,30300.64,0.00195,0.00088,,,,,,
26.5,2.208,30464.31,0.00196,0.00089,,,,,,
26.6,2.217,30579.85,0.00198,0.0009,,,,,,
26.7,2.225,30717.71,0.00199,0.00091,,,,,,
26.8,2.234,30860.89,0.00201,0.00092,,,,,,
26.9,2.242,30982.23,0.00202,0.00093,,,,,,
27,2.25,31125.99,0.00204,0.00094,,,,,,
27.1,2.258,31250.59,0.00206,0.00095,,,,,,
27.2,2.267,31378.99,0.00207,0.00096,,,,,,
27.3,2.275,31523.82,0.00209,0.00097,,,,,,
27.4,2.284,31660.46,0.0021,0.00098,,,,,,
27.5,2.292,31772.58,0.00212,0.00099,,,,,,
27.6,2.3,31928.21,0.00214,0.001,,,,,,
27.7,2.308,32039.94,0.00216,0.00101,,,,,,
27.8,2.317,32174.96,0.00217,0.00102,,,,,,
27.9,2.325,32318.43,0.00219,0.00103,,,,,,
28,2.333,32441.67,0.00221,0.00104,,,,,,
28.1,2.342,32570.37,0.00222,0.00105,,,,,,
28.2,2.35,32707.17,0.00224,0.00106,,,,,,
28.3,2.358,32823.23,0.00226,0.00107,,,,,,
28.4,2.367,32973.3,0.00227,0.00108,,,,,,
28.5,2.375,33083.4,0.00229,0.00109,,,,,,
28.6,2.383,33212.84,0.00231,0.0011,,,,,,
28.7,2.392,33360.71,0.00233,0.00111,,,,,,
28.8,2.4,33480.01,0.00235,0.00112,,,,,,
28.9,2.408,33608.32,0.00236,0.00114,,,,,,
29,2.417,33723.27,0.00238,0.00115,,,,,,
29.1,2.425,33851.98,0.0024,0.00116,,,,,,
29.2,2.433,33984.36,0.00242,0.00118,,,,,,
29.3,2.442,34108.3,0.00243,0.00119,,,,,,
29.4,2.45,34225.23,0.00246,0.0012,,,,,,
29.5,2.458,34372.73,0.00247,0.00121,,,,,,
29.6,2.467,34488.14,0.00249,0.00122,,,,,,
29.7,2.475,34616.49,0.00251,0.00123,,,,,,
29.8,2.483,34741.63,0.00253,0.00124,,,,,,
29.9,2.492,34850.75,0.00255,0.00125,,,,,,
30,2.5,35005.42,0.00257,0.00127,,,,,,
30.1,2.508,35105.96,0.00259,0.00128,,,,,,
30.2,2.517,35243.72,0.00261,0.00129,,,,,,
30.3,2.525,35361.14,0.00263,0.00131,,,,,,
30.4,2.533,35475.09,0.00265,0.00132,,,,,,
30.5,2.542,35618.77,0.00267,0.00133,,,,,,
30.6,2.55,35720.27,0.00269,0.00134,,,,,,
30.7,2.559,35863.41,0.00271,0.00136,,,,,,
30.8,2.567,35968.27,0.00273,0.00137,,,,,,
30.9,2.575,36092.88,0.00276,0.00138,,,,,,
31,2.584,36222.65,0.00278,0.0014,,,,,,
31.1,2.592,36325.86,0.0028,0.00141,,,,,,
31.2,2.6,36470.56,0.00282,0.00142,,,,,,
31.3,2.608,36582.38,0.00285,0.00143,,,,,,
31.4,2.617,36700.92,0.00287,0.00145,,,,,,
31.5,2.625,36809.16,0.00289,0.00146,,,,,,
31.6,2.633,36924.65,0.00291,0.00148,,,,,,
31.7,2.642,37052.99,0.00293,0.00149,,,,,,
31.8,2.65,37162.34,0.00296,0.00151,,,,,,
31.9,2.658,37293.97,0.00298,0.00153,,,,,,
32,2.667,37394.7,0.00301,0.00155,,,,,,
32.1,2.675,37520.85,0.00303,0.00156,,,,,,
32.2,2.684,37621.78,0.00306,0.00158,,,,,,
32.3,2.692,37746.34,0.00308,0.0016,,,,,,
32.4,2.7,37860.49,0.00311,0.00162,,,,,,
32.5,2.708,37952.5,0.00313,0.00163,,,,,,
32.6,2.717,38095.36,0.00316,0.00165,,,,,,
32.7,2.725,38182.8,0.00319,0.00167,,,,,,
32.8,2.734,38319.38,0.00321,0.00168,,,,,,
32.9,2.742,38415.87,0.00324,0.0017,,,,,,
33,2.75,38532.85,0.00327,0.00172,,,,,,
33.1,2.758,38646.56,0.0033,0.00174,,,,,,
33.2,2.767,38751.57,0.00332,0.00175,,,,,,
33.3,2.775,38859.54,0.00335,0.00177,,,,,,
33.4,2.784,38975.88,0.00338,0.00179,,,,,,
33.5,2.792,39073.94,0.00342,0.00181,,,,,,
33.6,2.8,39178.29,0.00344,0.00182,,,,,,
33.7,2.809,39288.69,0.00347,0.00184,,,,,,
33.8,2.817,39386.29,0.0035,0.00186,,,,,,
33.9,2.825,39506.27,0.00354,0.00188,,,,,,
34,2.833,39592.48,0.00357,0.00191,,,,,,
34.1,2.842,39702.27,0.0036,0.00193,,,,,,
34.2,2.85,39802.97,0.00363,0.00196,,,,,,
34.3,2.859,39907.11,0.00366,0.00198,,,,,,
34.4,2.867,40009.15,0.00369,0.00201,,,,,,
34.5,2.875,40105.64,0.00373,0.00203,,,,,,
34.6,2.883,40201.45,0.00376,0.00205,,,,,,
34.7,2.892,40304.92,0.00379,0.00207,,,,,,
34.8,2.9,40402.78,0.00383,0.00209,,,,,,
34.9,2.909,40486.89,0.00386,0.00212,,,,,,
35,2.917,40595.68,0.00389,0.00214,,,,,,
35.1,2.925,40662.75,0.00393,0.00217,,,,,,
35.2,2.933,40781.66,0.00397,0.00219,,,,,,
35.3,2.942,40856.2,0.004,0.00222,,,,,,
35.4,2.95,40951.04,0.00404,0.00224,,,,,,
35.5,2.959,41041.62,0.00408,0.00227,,,,,,
35.6,2.967,41139.83,0.00411,0.00229,,,,,,
35.7,2.975,41233.03,0.00415,0.00232,,,,,,
35.8,2.983,41296.27,0.00419,0.00235,,,,,,
35.9,2.992,41415.27,0.00423,0.00237,,,,,,
36,3,41480.96,0.00427,0.00241,,,,,,
36.1,3.008,41561.39,0.00432,0.00243,,,,,,
36.2,3.017,41652.02,0.00435,0.00246,,,,,,
36.3,3.025,41733.6,0.00441,0.00249,,,,,,
36.4,3.033,41826.94,0.00444,0.00252,,,,,,
36.5,3.042,41877.48,0.00449,0.00255,,,,,,
36.6,3.05,41978.89,0.00453,0.00258,,,,,,
36.7,3.058,42059.82,0.00457,0.00262,,,,,,
36.8,3.067,42114.24,0.00462,0.00265,,,,,,
36.9,3.075,42192.73,0.00467,0.00268,,,,,,
37,3.083,42281.41,0.00471,0.00271,,,,,,
37.1,3.092,42349.47,0.00476,0.00274,,,,,,
37.2,3.1,42431.8,0.00481,0.00278,,,,,,
37.3,3.108,42476.14,0.00485,0.00282,,,,,,
37.4,3.117,42566.57,0.0049,0.00286,,,,,,
37.5,3.125,42647.01,0.00495,0.00289,,,,,,
37.6,3.133,42690.32,0.005,0.00293,,,,,,
37.7,3.142,42767.9,0.00505,0.00296,,,,,,
37.8,3.15,42844.51,0.0051,0.003,,,,,,
37.9,3.158,42900.18,0.00516,0.00305,,,,,,
38,3.167,42952.2,0.0052,0.00308,,,,,,
38.1,3.175,43021.01,0.00526,0.00312,,,,,,
38.2,3.183,43085.42,0.00531,0.00316,,,,,,
38.3,3.192,43137.93,0.00537,0.0032,,,,,,
38.4,3.2,43207.21,0.00543,0.00325,,,,,,
38.5,3.208,43270.05,0.00548,0.00329,,,,,,
38.6,3.217,43310.11,0.00554,0.00333,,,,,,
38.7,3.225,43371.44,0.0056,0.00337,,,,,,
38.8,3.234,43423.12,0.00566,0.00342,,,,,,
38.9,3.242,43498.14,0.00572,0.00346,,,,,,
39,3.25,43516.1,0.00578,0.00351,,,,,,
39.1,3.258,43572.57,0.00585,0.00356,,,,,,
39.2,3.267,43624.52,0.00591,0.0036,,,,,,
39.3,3.275,43694.8,0.00598,0.00365,,,,,,
39.4,3.284,43724.09,0.00604,0.0037,,,,,,
39.5,3.292,43764.66,0.00611,0.00374,,,,,,
39.6,3.3,43817.75,0.00617,0.0038,,,,,,
39.7,3.309,43870.81,0.00624,0.00385,,,,,,
39.8,3.317,43909.52,0.00631,0.0039,,,,,,
39.9,3.325,43942.48,0.00638,0.00395,,,,,,
40,3.334,43982.58,0.00645,0.004,,,,,,
40.1,3.342,44026.51,0.00652,0.00406,,,,,,
40.2,3.35,44078.59,0.00659,0.00411,,,,,,
40.3,3.358,44118.86,0.00666,0.00417,,,,,,
40.4,3.367,44137.5,0.00673,0.00422,,,,,,
40.5,3.375,44175.94,0.00681,0.00428,,,,,,
40.6,3.383,44228.28,0.00688,0.00434,,,,,,
40.7,3.392,44252.7,0.00696,0.00439,,,,,,
40.8,3.4,44303.61,0.00704,0.00445,,,,,,
40.9,3.409,44328.05,0.00712,0.00451,,,,,,
41,3.417,44347.62,0.00721,0.00457,,,,,,
41.1,3.425,44383.97,0.00729,0.00462,,,,,,
41.2,3.433,44425.67,0.00738,0.00468,,,,,,
41.3,3.442,44445.79,0.00746,0.00475,,,,,,
41.4,3.45,44483.12,0.00755,0.0048,,,,,,
41.5,3.459,44523.25,0.00764,0.00486,,,,,,
41.6,3.467,44542.37,0.00773,0.00492,,,,,,
41.7,3.475,44559.46,0.00782,0.00498,,,,,,
41.8,3.484,44582.24,0.00791,0.00504,,,,,,
41.9,3.492,44607.8,0.008,0.00511,,,,,,
42,3.5,44638.18,0.00809,0.00517,,,,,,
42.1,3.508,44656.33,0.00818,0.00523,,,,,,
42.2,3.517,44689.22,0.00827,0.00529,,,,,,
42.3,3.525,44723.07,0.00836,0.00536,,,,,,
42.4,3.534,44736.98,0.00846,0.00543,,,,,,
42.5,3.542,44746.43,0.00855,0.00549,,,,,,
42.6,3.55,44768.71,0.00865,0.00556,,,,,,
42.7,3.558,44795.65,0.00874,0.00563,,,,,,
42.8,3.567,44822.1,0.00884,0.0057,,,,,,
42.9,3.575,44851.88,0.00893,0.00577,,,,,,
43,3.583,44863.51,0.00903,0.00583,,,,,,
43.1,3.592,44888.48,0.00913,0.0059,,,,,,
43.2,3.6,44904.43,0.00923,0.00596,,,,,,
43.3,3.608,44916.43,0.00933,0.00603,,,,,,
43.4,3.617,44934.3,0.00943,0.0061,,,,,,
43.5,3.625,44953.16,0.00953,0.00617,,,,,,
43.6,3.634,44956.59,0.00963,0.00624,,,,,,
43.7,3.642,44972.79,0.00973,0.00631,,,,,,
43.8,3.65,44999.35,0.00983,0.00638,,,,,,
43.9,3.658,45012.6,0.00994,0.00645,,,,,,
44,3.667,45036.16,0.01004,0.00652,,,,,,
44.1,3.675,45052.19,0.01015,0.00659,,,,,,
44.2,3.683,45065.56,0.01025,0.00666,,,,,,
44.3,3.692,45073.47,0.01036,0.00673,,,,,,
44.4,3.7,45085.29,0.01047,0.0068,,,,,,
44.5,3.709,45110.04,0.01057,0.00687,,,,,,
44.6,3.717,45124.82,0.01068,0.00695,,,,,,
44.7,3.725,45141.15,0.01079,0.00701,,,,,,
44.8,3.733,45156.89,0.0109,0.00709,,,,,,
44.9,3.742,45157.93,0.011,0.00716,,,,,,
45,3.75,45162.28,0.01111,0.00723,,,,,,
45.1,3.759,45172.13,0.01122,0.00731,,,,,,
45.2,3.767,45177.09,0.01134,0.00738,,,,,,
45.3,3.775,45181.93,0.01145,0.00746,,,,,,
45.4,3.783,45189.5,0.01156,0.00753,,,,,,
45.5,3.792,45201.12,0.01167,0.0076,,,,,,
45.6,3.8,45214.22,0.01178,0.00768,,,,,,
45.7,3.809,45232.07,0.0119,0.00775,,,,,,
45.8,3.817,45249.02,0.01201,0.00782,,,,,,
45.9,3.825,45255.09,0.01212,0.0079,,,,,,
46,3.833,45263.57,0.01223,0.00797,,,,,,
46.1,3.842,45276.02,0.01235,0.00804,,,,,,
46.2,3.85,45282.77,0.01247,0.00812,,,,,,
46.3,3.859,45293.11,0.01258,0.00819,,,,,,
46.4,3.867,45306.02,0.0127,0.00827,,,,,,
46.5,3.875,45314.71,0.01282,0.00835,,,,,,
46.6,3.884,45322.59,0.01293,0.00842,,,,,,
46.7,3.892,45328.56,0.01305,0.0085,,,,,,
46.8,3.9,45338.15,0.01317,0.00858,,,,,,
46.9,3.909,45353.71,0.01329,0.00866,,,,,,
47,3.917,45355.65,0.01341,0.00873,,,,,,
47.1,3.925,45361.52,0.01354,0.00881,,,,,,
47.2,3.934,45364.78,0.01366,0.00888,,,,,,
47.3,3.942,45367.91,0.01378,0.00896,,,,,,
47.4,3.95,45370.52,0.0139,0.00904,,,,,,
47.5,3.959,45373.56,0.01402,0.00911,,,,,,
47.6,3.967,45374.03,0.01414,0.00919,,,,,,
47.7,3.975,45378.06,0.01426,0.00927,,,,,,
47.8,3.984,45378.73,0.01438,0.00935,,,,,,
47.9,3.992,45381.66,0.01451,0.00942,,,,,,
48,4,45386.93,0.01463,0.0095,,,,,,
48.1,4.008,45389.49,0.01476,0.00957,,,,,,
48.2,4.017,45397.29,0.01488,0.00965,,,,,,
48.3,4.025,45407.38,0.01501,0.00973,,,,,,
48.4,4.034,45408.15,0.01513,0.00981,,,,,,
48.5,4.042,45415.68,0.01525,0.00989,,,,,,
48.6,4.05,45418.05,0.01538,0.00997,,,,,,
48.7,4.059,45421.07,0.01551,0.01005,,,,,,
48.8,4.067,45426.91,0.01564,0.01012,,,,,,
48.9,4.075,45430.45,0.01577,0.0102,,,,,,
49,4.084,45436.86,0.0159,0.01028,,,,,,
49.1,4.092,45440.55,0.01603,0.01036,,,,,,
49.2,4.1,45446,0.01616,0.01044,,,,,,
49.3,4.108,45446.42,0.01629,0.01051,,,,,,
49.4,4.117,45445.52,0.01642,0.01059,,,,,,
49.5,4.125,45452.73,0.01656,0.01067,,,,,,
49.6,4.134,45457.52,0.01669,0.01076,,,,,,
49.7,4.142,45448.51,0.01682,0.01084,,,,,,
49.8,4.15,45455.27,0.01695,0.01092,,,,,,
49.9,4.159,45466.53,0.01707,0.01099,,,,,,
50,4.167,45462.51,0.01721,0.01107,,,,,,
50.1,4.175,45463.36,0.01734,0.01116,,,,,,
50.2,4.183,45465.92,0.01748,0.01123,,,,,,
50.3,4.192,45468.81,0.0176,0.01132,,,,,,
50.4,4.2,45469.54,0.01774,0.0114,,,,,,
50.5,4.208,45468.86,0.01787,0.01148,,,,,,
50.6,4.217,45468.62,0.01801,0.01155,,,,,,
50.7,4.225,45472.68,0.01814,0.01164,,,,,,
50.8,4.233,45472.34,0.01827,0.01172,,,,,,
50.9,4.242,45469.79,0.0184,0.01179,,,,,,
51,4.25,45470.79,0.01854,0.01188,,,,,,
51.1,4.259,45474.61,0.01867,0.01195,,,,,,
51.2,4.267,45473.87,0.01881,0.01204,,,,,,
51.3,4.275,45474.66,0.01894,0.01212,,,,,,
51.4,4.284,45474.53,0.01908,0.0122,,,,,,
51.5,4.292,45477.36,0.01921,0.01228,,,,,,
51.6,4.3,45476.57,0.01936,0.01236,,,,,,
51.7,4.308,45473.66,0.01949,0.01244,,,,,,
51.8,4.317,45472.97,0.01963,0.01252,,,,,,
51.9,4.325,45474.03,0.01977,0.0126,,,,,,
52,4.333,45474.7,0.01991,0.01268,,,,,,
52.1,4.342,45476.33,0.02005,0.01277,,,,,,
52.2,4.35,45474.71,0.02019,0.01285,,,,,,
52.3,4.358,45472.96,0.02033,0.01293,,,,,,
52.4,4.367,45475.75,0.02048,0.01301,,,,,,
52.5,4.375,45474.19,0.02062,0.0131,,,,,,
52.6,4.384,45474.02,0.02076,0.01318,,,,,,
52.7,4.392,45474.91,0.0209,0.01326,,,,,,
52.8,4.4,45471.29,0.02105,0.01335,,,,,,
52.9,4.408,45468.33,0.02119,0.01343,,,,,,
53,4.417,45469.65,0.02133,0.01351,,,,,,
53.1,4.425,45470.5,0.02148,0.01359,,,,,,
53.2,4.434,45468.65,0.02162,0.01368,,,,,,
53.3,4.442,45470.09,0.02177,0.01376,,,,,,
53.4,4.45,45468.26,0.02191,0.01385,,,,,,
53.5,4.458,45465.72,0.02205,0.01393,,,,,,
53.6,4.467,45466.86,0.02219,0.01402,,,,,,
53.7,4.475,45466.77,0.02234,0.0141,,,,,,
53.8,4.483,45460.91,0.02249,0.01419,,,,,,
53.9,4.492,45460.41,0.02264,0.01427,,,,,,
54,4.5,45462.63,0.02279,0.01436,,,,,,
54.1,4.509,45458.84,0.02293,0.01444,,,,,,
54.2,4.517,45455.75,0.02308,0.01453,,,,,,
54.3,4.525,45456.8,0.02323,0.01462,,,,,,
54.4,4.534,45453.86,0.02337,0.0147,,,,,,
54.5,4.542,45449.71,0.02352,0.01479,,,,,,
54.6,4.55,45444.94,0.02367,0.01488,,,,,,
54.7,4.558,45444.13,0.02382,0.01496,,,,,,
54.8,4.567,45446.11,0.02397,0.01505,,,,,,
54.9,4.575,45440.36,0.02412,0.01514,,,,,,
55,4.583,45425.04,0.02427,0.01522,,,,,,
55.1,4.592,45423.04,0.02442,0.01531,,,,,,
55.2,4.6,45427.88,0.02457,0.01539,,,,,,
55.3,4.609,45425.44,0.02472,0.01548,,,,,,
55.4,4.617,45417.53,0.02487,0.01556,,,,,,
55.5,4.625,45417.01,0.02502,0.01565,,,,,,
55.6,4.633,45413.21,0.02517,0.01574,,,,,,
55.7,4.642,45412.58,0.02532,0.01582,,,,,,
55.8,4.65,45409.91,0.02548,0.01592,,,,,,
55.9,4.659,45400.05,0.02563,0.016,,,,,,
56,4.667,45398.42,0.02579,0.01609,,,,,,
56.1,4.675,45391.29,0.02594,0.01618,,,,,,
56.2,4.683,45388.14,0.02609,0.01627,,,,,,
56.3,4.692,45384.64,0.02625,0.01636,,,,,,
56.4,4.7,45382.7,0.0264,0.01644,,,,,,
56.5,4.709,45381.88,0.02656,0.01654,,,,,,
56.6,4.717,45380.15,0.02673,0.01663,,,,,,
56.7,4.725,45377.85,0.02689,0.01672,,,,,,
56.8,4.734,45377.99,0.02705,0.01681,,,,,,
56.9,4.742,45376.78,0.02721,0.0169,,,,,,
57,4.75,45375.4,0.02737,0.01699,,,,,,
57.1,4.759,45373.87,0.02754,0.01708,,,,,,
57.2,4.767,45368.96,0.02769,0.01717,,,,,,
57.3,4.775,45366.9,0.02786,0.01726,,,,,,
57.4,4.784,45365.95,0.02802,0.01735,,,,,,
57.5,4.792,45363.89,0.02818,0.01744,,,,,,
57.6,4.8,45359.65,0.02834,0.01754,,,,,,
57.7,4.808,45353.94,0.0285,0.01763,,,,,,
57.8,4.817,45353.59,0.02867,0.01772,,,,,,
57.9,4.825,45353.06,0.02883,0.01781,,,,,,
58,4.834,45340.81,0.02899,0.01791,,,,,,
58.1,4.842,45342.65,0.02915,0.018,,,,,,
58.2,4.85,45336.17,0.02931,0.01809,,,,,,
58.3,4.858,45328.88,0.02948,0.01819,,,,,,
58.4,4.867,45323.86,0.02964,0.01828,,,,,,
58.5,4.875,45319.9,0.02981,0.01837,,,,,,
58.6,4.884,45316.6,0.02997,0.01847,,,,,,
58.7,4.892,45313.94,0.03014,0.01857,,,,,,
58.8,4.9,45307.67,0.03031,0.01866,,,,,,
58.9,4.908,45299.7,0.03047,0.01876,,,,,,
59,4.917,45295.57,0.03064,0.01886,,,,,,
59.1,4.925,45295.12,0.03081,0.01895,,,,,,
59.2,4.934,45280.39,0.03098,0.01905,,,,,,
59.3,4.942,45268.45,0.03115,0.01915,,,,,,
59.4,4.95,45265.09,0.03131,0.01924,,,,,,
59.5,4.958,45262.05,0.03148,0.01934,,,,,,
59.6,4.967,45262.1,0.03166,0.01944,,,,,,
59.7,4.975,45257.1,0.03183,0.01954,,,,,,
59.8,4.984,45248.55,0.032,0.01964,,,,,,
59.9,4.992,45245.63,0.03217,0.01974,,,,,,
60,5,45236.36,0.03234,0.01984,,,,,,
60.1,5.009,45225.03,0.03251,0.01994,,,,,,
60.2,5.017,45219.18,0.03268,0.02004,,,,,,
60.3,5.025,45209.11,0.03286,0.02014,,,,,,
60.4,5.034,45202.71,0.03303,0.02025,,,,,,
60.5,5.042,45196.19,0.0332,0.02035,,,,,,
60.6,5.05,45190.64,0.03337,0.02045,,,,,,
60.7,5.059,45188.43,0.03355,0.02055,,,,,,
60.8,5.067,45181.3,0.03372,0.02066,,,,,,
60.9,5.075,45181.4,0.0339,0.02076,,,,,,
61,5.083,45177.21,0.03408,0.02087,,,,,,
61.1,5.092,45172.61,0.03426,0.02098,,,,,,
61.2,5.1,45170.95,0.03444,0.02108,,,,,,
61.3,5.109,45168.28,0.03462,0.02118,,,,,,
61.4,5.117,45162.57,0.0348,0.02129,,,,,,
61.5,5.125,45158.91,0.03499,0.0214,,,,,,
61.6,5.133,45157.41,0.03517,0.02151,,,,,,
61.7,5.142,45156.88,0.03535,0.02162,,,,,,
61.8,5.15,45156.04,0.03554,0.02173,,,,,,
61.9,5.159,45150.4,0.03572,0.02184,,,,,,
62,5.167,45145.75,0.0359,0.02195,,,,,,
62.1,5.175,45136.46,0.03609,0.02206,,,,,,
62.2,5.183,45128.35,0.03628,0.02217,,,,,,
62.3,5.192,45119.81,0.03647,0.02228,,,,,,
62.4,5.2,45115.41,0.03666,0.02239,,,,,,
62.5,5.209,45103.47,0.03685,0.02251,,,,,,
62.6,5.217,45086.52,0.03704,0.02262,,,,,,
62.7,5.225,45075.83,0.03723,0.02273,,,,,,
62.8,5.234,45073.93,0.03742,0.02285,,,,,,
62.9,5.242,45067.95,0.03761,0.02296,,,,,,
63,5.25,45066.22,0.03781,0.02307,,,,,,
63.1,5.258,45056.66,0.03801,0.02319,,,,,,
63.2,5.267,45041.11,0.03821,0.0233,,,,,,
63.3,5.275,45029.81,0.03839,0.02342,,,,,,
63.4,5.283,45026.12,0.03859,0.02354,,,,,,
63.5,5.292,45017.84,0.0388,0.02365,,,,,,
63.6,5.3,45006.68,0.039,0.02377,,,,,,
63.7,5.308,44998.13,0.0392,0.02389,,,,,,
63.8,5.317,44991.76,0.0394,0.024,,,,,,
63.9,5.325,44990.31,0.0396,0.02412,,,,,,
64,5.334,44977.22,0.03981,0.02424,,,,,,
64.1,5.342,44965.05,0.04001,0.02436,,,,,,
64.2,5.35,44961.62,0.04022,0.02449,,,,,,
64.3,5.358,44954.26,0.04042,0.02461,,,,,,
64.4,5.367,44953.01,0.04063,0.02473,,,,,,
64.5,5.375,44949.38,0.04084,0.02486,,,,,,
64.6,5.384,44943.2,0.04105,0.02498,,,,,,
64.7,5.392,44933.39,0.04127,0.0251,,,,,,
64.8,5.4,44920.91,0.04147,0.02523,,,,,,
64.9,5.408,44913.9,0.04168,0.02535,,,,,,
65,5.417,44908.37,0.04189,0.02548,,,,,,
65.1,5.425,44901.74,0.04211,0.02561,,,,,,
65.2,5.433,44889.52,0.04233,0.02574,,,,,,
65.3,5.442,44875.29,0.04254,0.02586,,,,,,
65.4,5.45,44864.9,0.04275,0.02599,,,,,,
65.5,5.459,44861.15,0.04297,0.02612,,,,,,
65.6,5.467,44855.39,0.04319,0.02624,,,,,,
65.7,5.475,44844.52,0.04341,0.02637,,,,,,
65.8,5.483,44830.75,0.04363,0.0265,,,,,,
65.9,5.492,44826.96,0.04385,0.02663,,,,,,
66,5.5,44804.31,0.04408,0.02676,,,,,,
66.1,5.509,44794.48,0.0443,0.02689,,,,,,
66.2,5.517,44783.79,0.04452,0.02702,,,,,,
66.3,5.525,44770.43,0.04474,0.02715,,,,,,
66.4,5.533,44758.66,0.04498,0.02728,,,,,,
66.5,5.542,44749.41,0.0452,0.02741,,,,,,
66.6,5.55,44740.79,0.04543,0.02755,,,,,,
66.7,5.559,44738.04,0.04565,0.02768,,,,,,
66.8,5.567,44734.49,0.04589,0.02782,,,,,,
66.9,5.575,44728.16,0.04612,0.02795,,,,,,
67,5.584,44718,0.04635,0.02808,,,,,,
67.1,5.592,44705.25,0.04658,0.02821,,,,,,
67.2,5.6,44692.21,0.04681,0.02835,,,,,,
67.3,5.609,44675.45,0.04705,0.02848,,,,,,
67.4,5.617,44653.65,0.04728,0.02862,,,,,,
67.5,5.625,44646.16,0.04751,0.02875,,,,,,
67.6,5.633,44640.02,0.04775,0.02889,,,,,,
67.7,5.642,44624.02,0.04799,0.02902,,,,,,
67.8,5.65,44600.93,0.04823,0.02916,,,,,,
67.9,5.659,44589.83,0.04846,0.02929,,,,,,
68,5.667,44580.4,0.04869,0.02943,,,,,,
68.1,5.675,44568.46,0.04893,0.02956,,,,,,
68.2,5.683,44555.82,0.04916,0.02969,,,,,,
68.3,5.692,44548.57,0.0494,0.02983,,,,,,
68.4,5.7,44544.89,0.04964,0.02996,,,,,,
68.5,5.708,44540.11,0.04988,0.03009,,,,,,
68.6,5.717,44533.2,0.05012,0.03023,,,,,,
68.7,5.725,44520.96,0.05036,0.03036,,,,,,
68.8,5.734,44507.38,0.05061,0.0305,,,,,,
68.9,5.742,44483.14,0.05085,0.03064,,,,,,
69,5.75,44461.8,0.0511,0.03077,,,,,,
69.1,5.758,44445.55,0.05134,0.0309,,,,,,
69.2,5.767,44438.16,0.05159,0.03104,,,,,,
69.3,5.775,44432.63,0.05183,0.03117,,,,,,
69.4,5.784,44413.93,0.05208,0.03131,,,,,,
69.5,5.792,44399.42,0.05233,0.03144,,,,,,
69.6,5.8,44388.41,0.05258,0.03158,,,,,,
69.7,5.808,44369.14,0.05283,0.03171,,,,,,
69.8,5.817,44346,0.05309,0.03185,,,,,,
69.9,5.825,44340.16,0.05334,0.03198,,,,,,
70,5.834,44330.96,0.05359,0.03211,,,,,,
70.1,5.842,44320.99,0.05383,0.03225,,,,,,
70.2,5.85,44309.18,0.05409,0.03238,,,,,,
70.3,5.858,44294.45,0.05434,0.03251,,,,,,
70.4,5.867,44287.92,0.05459,0.03264,,,,,,
70.5,5.875,44262.06,0.05484,0.03277,,,,,,
70.6,5.884,44242.28,0.0551,0.0329,,,,,,
70.7,5.892,44235.26,0.05535,0.03303,,,,,,
70.8,5.9,44223.46,0.0556,0.03316,,,,,,
70.9,5.909,44195.42,0.05586,0.03329,,,,,,
71,5.917,44173.84,0.05612,0.03342,,,,,,
71.1,5.925,44159.73,0.05637,0.03355,,,,,,
71.2,5.933,44142.93,0.05662,0.03368,,,,,,
71.3,5.942,44130.64,0.05687,0.0338,,,,,,
71.4,5.95,44123.68,0.05713,0.03393,,,,,,
71.5,5.959,44120.65,0.05739,0.03406,,,,,,
71.6,5.967,44117.08,0.05765,0.03419,,,,,,
71.7,5.975,44102.38,0.0579,0.03432,,,,,,
71.8,5.983,44082.31,0.05816,0.03444,,,,,,
71.9,5.992,44064.04,0.05842,0.03457,,,,,,
72,6,44042.19,0.05868,0.03469,,,,,,
72.1,6.009,44022.47,0.05894,0.03482,,,,,,
72.2,6.017,44017.07,0.0592,0.03494,,,,,,
72.3,6.025,43987.73,0.05945,0.03507,,,,,,
72.4,6.033,43970.38,0.0597,0.03519,,,,,,
72.5,6.042,43964.3,0.05996,0.03532,,,,,,
72.6,6.05,43944.64,0.06023,0.03544,,,,,,
72.7,6.059,43936.98,0.06049,0.03557,,,,,,
72.8,6.067,43920.05,0.06075,0.03569,,,,,,
72.9,6.075,43906.55,0.061,0.03581,,,,,,
73,6.084,43898.19,0.06127,0.03593,,,,,,
73.1,6.092,43876.22,0.06153,0.03605,,,,,,
73.2,6.1,43863.88,0.06178,0.03617,,,,,,
73.3,6.109,43832.37,0.06204,0.03629,,,,,,
73.4,6.117,43817.84,0.06229,0.03641,,,,,,
73.5,6.125,43815.52,0.06255,0.03653,,,,,,
73.6,6.134,43799.9,0.06281,0.03665,,,,,,
73.7,6.142,43777.84,0.06306,0.03677,,,,,,
73.8,6.15,43765.36,0.06332,0.03688,,,,,,
73.9,6.158,43741.63,0.06358,0.037,,,,,,
74,6.167,43729.38,0.06384,0.03712,,,,,,
74.1,6.175,43717.29,0.0641,0.03723,,,,,,
74.2,6.184,43707.09,0.06437,0.03735,,,,,,
74.3,6.192,43698.7,0.06463,0.03746,,,,,,
74.4,6.2,43685.52,0.06489,0.03758,,,,,,
74.5,6.208,43669.76,0.06515,0.03769,,,,,,
74.6,6.217,43636.45,0.06541,0.03781,,,,,,
74.7,6.225,43620.27,0.06568,0.03792,,,,,,
74.8,6.234,43610.74,0.06595,0.03803,,,,,,
74.9,6.242,43592.55,0.06621,0.03815,,,,,,
75,6.25,43561.66,0.06647,0.03826,,,,,,
75.1,6.258,43545.32,0.06674,0.03837,,,,,,
75.2,6.267,43531.23,0.06701,0.03848,,,,,,
75.3,6.275,43516.29,0.06728,0.03859,,,,,,
75.4,6.283,43511.13,0.06754,0.0387,,,,,,
75.5,6.292,43506.77,0.06781,0.03881,,,,,,
75.6,6.3,43499.05,0.06808,0.03891,,,,,,
75.7,6.308,43477.73,0.06835,0.03902,,,,,,
75.8,6.317,43462.92,0.06862,0.03913,,,,,,
75.9,6.325,43436.81,0.06889,0.03924,,,,,,
76,6.333,43404.82,0.06916,0.03934,,,,,,
76.1,6.342,43398.77,0.06944,0.03944,,,,,,
76.2,6.35,43383.25,0.06971,0.03955,,,,,,
76.3,6.358,43362.12,0.06998,0.03965,,,,,,
76.4,6.367,43337.97,0.07025,0.03975,,,,,,
76.5,6.375,43316.1,0.07053,0.03986,,,,,,
76.6,6.383,43307.73,0.0708,0.03996,,,,,,
76.7,6.392,43301.13,0.07107,0.04006,,,,,,
76.8,6.4,43289.05,0.07135,0.04016,,,,,,
76.9,6.408,43276.45,0.07161,0.04026,,,,,,
77,6.417,43262.28,0.07188,0.04036,,,,,,
77.1,6.425,43243.62,0.07215,0.04046,,,,,,
77.2,6.433,43221.07,0.07242,0.04056,,,,,,
77.3,6.442,43207.95,0.07269,0.04066,,,,,,
77.4,6.45,43201.16,0.07296,0.04076,,,,,,
77.5,6.458,43178.84,0.07323,0.04085,,,,,,
77.6,6.467,43146.14,0.0735,0.04095,,,,,,
77.7,6.475,43127,0.07376,0.04104,,,,,,
77.8,6.483,43108.77,0.07403,0.04114,,,,,,
77.9,6.492,43099.2,0.0743,0.04123,,,,,,
78,6.5,43088.66,0.07457,0.04133,,,,,,
78.1,6.508,43071.59,0.07483,0.04142,,,,,,
78.2,6.517,43061.18,0.07511,0.04151,,,,,,
78.3,6.525,43042.5,0.07539,0.0416,,,,,,
78.4,6.534,43012.76,0.07567,0.0417,,,,,,
78.5,6.542,42992.69,0.07594,0.04179,,,,,,
78.6,6.55,42986.6,0.07623,0.04188,,,,,,
78.7,6.559,42961.23,0.07652,0.04197,,,,,,
78.8,6.567,42942.77,0.0768,0.04206,,,,,,
78.9,6.575,42929.45,0.07708,0.04215,,,,,,
79,6.584,42912.93,0.07737,0.04223,,,,,,
79.1,6.592,42901.67,0.07766,0.04232,,,,,,
79.2,6.6,42897.94,0.07795,0.04241,,,,,,
79.3,6.608,42885.05,0.07824,0.0425,,,,,,
79.4,6.617,42871.41,0.07853,0.04259,,,,,,
79.5,6.625,42849.78,0.07883,0.04267,,,,,,
79.6,6.634,42819.5,0.07912,0.04276,,,,,,
79.7,6.642,42789.38,0.07941,0.04284,,,,,,
79.8,6.65,42777.45,0.07971,0.04293,,,,,,
79.9,6.658,42765.94,0.08,0.04301,,,,,,
80,6.667,42743.54,0.0803,0.04309,,,,,,
80.1,6.675,42721.7,0.0806,0.04318,,,,,,
80.2,6.684,42702.11,0.0809,0.04326,,,,,,
80.3,6.692,42690.58,0.0812,0.04334,,,,,,
80.4,6.7,42678.89,0.0815,0.04342,,,,,,
80.5,6.709,42670.59,0.0818,0.0435,,,,,,
80.6,6.717,42663.46,0.0821,0.04358,,,,,,
80.7,6.725,42640.7,0.0824,0.04366,,,,,,
80.8,6.734,42622.75,0.0827,0.04374,,,,,,
80.9,6.742,42595.26,0.083,0.04382,,,,,,
81,6.75,42583.44,0.0833,0.0439,,,,,,
81.1,6.759,42576.08,0.0836,0.04398,,,,,,
81.2,6.767,42539.56,0.08391,0.04405,,,,,,
81.3,6.775,42519.98,0.08421,0.04413,,,,,,
81.4,6.784,42488.73,0.08452,0.04421,,,,,,
81.5,6.792,42474.04,0.08482,0.04428,,,,,,
81.6,6.8,42469.39,0.08512,0.04436,,,,,,
81.7,6.809,42464.38,0.08543,0.04443,,,,,,
81.8,6.817,42442.23,0.08574,0.04451,,,,,,
81.9,6.825,42420.66,0.08604,0.04458,,,,,,
82,6.833,42399.94,0.08634,0.04465,,,,,,
82.1,6.842,42378.45,0.08665,0.04472,,,,,,
82.2,6.85,42369.6,0.08695,0.0448,,,,,,
82.3,6.859,42353.28,0.08726,0.04487,,,,,,
82.4,6.867,42331.48,0.08757,0.04494,,,,,,
82.5,6.875,42301.79,0.08789,0.04501,,,,,,
82.6,6.883,42287.06,0.08819,0.04508,,,,,,
82.7,6.892,42283.3,0.08851,0.04515,,,,,,
82.8,6.9,42273.43,0.08882,0.04522,,,,,,
82.9,6.909,42252.2,0.08914,0.04529,,,,,,
83,6.917,42225.13,0.08944,0.04535,,,,,,
83.1,6.925,42197.69,0.08976,0.04542,,,,,,
83.2,6.933,42169.71,0.09007,0.04548,,,,,,
83.3,6.942,42160.62,0.09039,0.04555,,,,,,
83.4,6.95,42145.63,0.0907,0.04562,,,,,,
83.5,6.959,42123.12,0.09102,0.04568,,,,,,
83.6,6.967,42103.53,0.09133,0.04575,,,,,,
83.7,6.975,42078.57,0.09165,0.04581,,,,,,
83.8,6.983,42069.55,0.09197,0.04588,,,,,,
83.9,6.992,42062.37,0.09229,0.04594,,,,,,
84,7,42055.85,0.0926,0.046,,,,,,
84.1,7.008,42022.19,0.09292,0.04606,,,,,,
84.2,7.017,42005.28,0.09324,0.04612,,,,,,
84.3,7.025,41984.47,0.09356,0.04618,,,,,,
84.4,7.033,41972.34,0.09388,0.04624,,,,,,
84.5,7.042,41944.06,0.0942,0.0463,,,,,,
84.6,7.05,41912.07,0.09452,0.04636,,,,,,
84.7,7.058,41888.44,0.09485,0.04642,,,,,,
84.8,7.067,41865.44,0.09518,0.04648,,,,,,
84.9,7.075,41855.23,0.0955,0.04654,,,,,,
85,7.084,41850.59,0.09584,0.04659,,,,,,
85.1,7.092,41835.7,0.09617,0.04665,,,,,,
85.2,7.1,41818.8,0.09649,0.0467,,,,,,
85.3,7.108,41792.53,0.09682,0.04676,,,,,,
85.4,7.117,41765.86,0.09715,0.04681,,,,,,
85.5,7.125,41758.61,0.09748,0.04687,,,,,,
85.6,7.134,41736.15,0.09782,0.04692,,,,,,
85.7,7.142,41706.55,0.09815,0.04698,,,,,,
85.8,7.15,41689.63,0.09848,0.04703,,,,,,
85.9,7.159,41666.87,0.09882,0.04708,,,,,,
86,7.167,41655.7,0.09914,0.04713,,,,,,
86.1,7.175,41640.26,0.09947,0.04719,,,,,,
86.2,7.184,41624.07,0.0998,0.04724,,,,,,
86.3,7.192,41585.07,0.10013,0.04729,,,,,,
86.4,7.2,41561.47,0.10045,0.04734,,,,,,
86.5,7.208,41549.1,0.10078,0.04738,,,,,,
86.6,7.217,41542.12,0.10111,0.04743,,,,,,
86.7,7.225,41513.97,0.10144,0.04748,,,,,,
86.8,7.233,41494.75,0.10176,0.04753,,,,,,
86.9,7.242,41473.06,0.1021,0.04758,,,,,,
87,7.25,41455.27,0.10243,0.04762,,,,,,
87.1,7.259,41443.55,0.10276,0.04767,,,,,,
87.2,7.267,41430.55,0.10309,0.04772,,,,,,
87.3,7.275,41403.95,0.10342,0.04776,,,,,,
87.4,7.284,41379.52,0.10374,0.04781,,,,,,
87.5,7.292,41352.26,0.10408,0.04785,,,,,,
87.6,7.3,41340.14,0.10441,0.0479,,,,,,
87.7,7.308,41305.42,0.10474,0.04794,,,,,,
87.8,7.317,41282.2,0.10507,0.04799,,,,,,
87.9,7.325,41257.18,0.10541,0.04803,,,,,,
88,7.333,41244.84,0.10574,0.04807,,,,,,
88.1,7.342,41240.95,0.10608,0.04811,,,,,,
88.2,7.35,41228.46,0.10641,0.04815,,,,,,
88.3,7.359,41213.18,0.10675,0.0482,,,,,,
88.4,7.367,41177.39,0.10709,0.04824,,,,,,
88.5,7.375,41142.28,0.10742,0.04827,,,,,,
88.6,7.384,41139.18,0.10775,0.04832,,,,,,
88.7,7.392,41117.53,0.10809,0.04836,,,,,,
88.8,7.4,41077.68,0.10843,0.0484,,,,,,
88.9,7.409,41057.32,0.10876,0.04843,,,,,,
89,7.417,41040.69,0.10909,0.04847,,,,,,
89.1,7.425,41022.92,0.10942,0.04851,,,,,,
89.2,7.434,41008.96,0.10976,0.04855,,,,,,
89.3,7.442,40981.95,0.1101,0.04858,,,,,,
89.4,7.45,40958.62,0.11044,0.04862,,,,,,
89.5,7.458,40933.39,0.11077,0.04865,,,,,,
89.6,7.467,40923.14,0.11111,0.04869,,,,,,
89.7,7.475,40899.54,0.11145,0.04872,,,,,,
89.8,7.483,40868.36,0.11178,0.04876,,,,,,
89.9,7.492,40844.77,0.11212,0.0488,,,,,,
90,7.5,40829.43,0.11247,0.04883,,,,,,
90.1,7.508,40813.51,0.11281,0.04887,,,,,,
90.2,7.517,40798.53,0.11315,0.0489,,,,,,
90.3,7.525,40772.67,0.11349,0.04893,,,,,,
90.4,7.534,40737.88,0.11384,0.04896,,,,,,
90.5,7.542,40718.04,0.11417,0.049,,,,,,
90.6,7.55,40684.25,0.11451,0.04903,,,,,,
90.7,7.558,40662.86,0.11484,0.04906,,,,,,
90.8,7.567,40643.26,0.1152,0.04909,,,,,,
90.9,7.575,40631.37,0.11554,0.04912,,,,,,
91,7.583,40613.46,0.11587,0.04915,,,,,,
91.1,7.592,40600.72,0.11622,0.04918,,,,,,
91.2,7.6,40573.55,0.11656,0.04921,,,,,,
91.3,7.609,40531.68,0.1169,0.04924,,,,,,
91.4,7.617,40512.89,0.11724,0.04927,,,,,,
91.5,7.625,40488.76,0.11758,0.04929,,,,,,
91.6,7.634,40459.37,0.11791,0.04932,,,,,,
91.7,7.642,40435.27,0.11826,0.04935,,,,,,
91.8,7.65,40415.18,0.1186,0.04937,,,,,,
91.9,7.659,40406.58,0.11894,0.0494,,,,,,
92,7.667,40385.71,0.11929,0.04943,,,,,,
92.1,7.675,40364.39,0.11963,0.04946,,,,,,
92.2,7.683,40336.22,0.11997,0.04948,,,,,,
92.3,7.692,40308.76,0.12032,0.04951,,,,,,
92.4,7.7,40289.26,0.12065,0.04953,,,,,,
92.5,7.709,40247.41,0.12099,0.04956,,,,,,
92.6,7.717,40225.07,0.12134,0.04958,,,,,,
92.7,7.725,40209.29,0.12168,0.04961,,,,,,
92.8,7.733,40190.62,0.12202,0.04963,,,,,,
92.9,7.742,40182.36,0.12237,0.04965,,,,,,
93,7.75,40155.33,0.12271,0.04968,,,,,,
93.1,7.759,40114.79,0.12305,0.0497,,,,,,
93.2,7.767,40099.21,0.1234,0.04972,,,,,,
93.3,7.775,40068.39,0.12374,0.04974,,,,,,
93.4,7.784,40041.84,0.12408,0.04976,,,,,,
93.5,7.792,40013.11,0.12443,0.04978,,,,,,
93.6,7.8,40001.54,0.12477,0.04981,,,,,,
93.7,7.809,39980.05,0.12511,0.04983,,,,,,
93.8,7.817,39953.18,0.12545,0.04985,,,,,,
93.9,7.825,39920.56,0.12579,0.04987,,,,,,
94,7.834,39891.25,0.12613,0.04989,,,,,,
94.1,7.842,39877.82,0.12647,0.04991,,,,,,
94.2,7.85,39848.37,0.12682,0.04993,,,,,,
94.3,7.859,39818.4,0.12716,0.04994,,,,,,
94.4,7.867,39798.62,0.1275,0.04996,,,,,,
94.5,7.875,39781.54,0.12784,0.04998,,,,,,
94.6,7.884,39763.41,0.1282,0.05,,,,,,
94.7,7.892,39729.97,0.12854,0.05002,,,,,,
94.8,7.9,39686.07,0.12888,0.05003,,,,,,
94.9,7.909,39674.54,0.12922,0.05005,,,,,,
95,7.917,39637.54,0.12957,0.05007,,,,,,
95.1,7.925,39606.67,0.12991,0.05009,,,,,,
95.2,7.934,39591.83,0.13027,0.0501,,,,,,
95.3,7.942,39579.41,0.13062,0.05012,,,,,,
95.4,7.95,39564.38,0.13096,0.05013,,,,,,
95.5,7.958,39535.14,0.13131,0.05015,,,,,,
95.6,7.967,39496.89,0.13166,0.05016,,,,,,
95.7,7.975,39471.22,0.132,0.05018,,,,,,
95.8,7.984,39436.64,0.13235,0.05019,,,,,,
95.9,7.992,39400.16,0.1327,0.05021,,,,,,
96,8,39381.85,0.13305,0.05022,,,,,,
96.1,8.008,39368.9,0.13339,0.05024,,,,,,
96.2,8.017,39340.38,0.13374,0.05025,,,,,,
96.3,8.025,39313.11,0.13409,0.05026,,,,,,
96.4,8.034,39278.22,0.13444,0.05028,,,,,,
96.5,8.042,39258.97,0.13479,0.05029,,,,,,
96.6,8.05,39229.57,0.13514,0.0503,,,,,,
96.7,8.059,39191.98,0.13549,0.05031,,,,,,
96.8,8.067,39169.43,0.13584,0.05032,,,,,,
96.9,8.075,39148.15,0.13619,0.05034,,,,,,
97,8.083,39120.15,0.13653,0.05035,,,,,,
97.1,8.092,39083.15,0.13688,0.05036,,,,,,
97.2,8.1,39062.03,0.13723,0.05037,,,,,,
97.3,8.109,39033.62,0.13758,0.05038,,,,,,
97.4,8.117,38999.53,0.13793,0.05039,,,,,,
97.5,8.125,38978.44,0.13829,0.0504,,,,,,
97.6,8.133,38968.94,0.13864,0.05041,,,,,,
97.7,8.142,38946.77,0.13899,0.05042,,,,,,
97.8,8.15,38906.19,0.13935,0.05043,,,,,,
97.9,8.159,38869.1,0.13971,0.05044,,,,,,
98,8.167,38830.69,0.14006,0.05045,,,,,,
98.1,8.175,38797.62,0.14041,0.05046,,,,,,
98.2,8.183,38765.98,0.14076,0.05047,,,,,,
98.3,8.192,38758,0.14112,0.05048,,,,,,
98.4,8.2,38737.85,0.14148,0.05049,,,,,,
98.5,8.209,38704.36,0.14183,0.0505,,,,,,
98.6,8.217,38668.05,0.14218,0.0505,,,,,,
98.7,8.225,38647.68,0.14253,0.05051,,,,,,
98.8,8.234,38600.93,0.14288,0.05052,,,,,,
98.9,8.242,38556.89,0.14323,0.05053,,,,,,
99,8.25,38542.69,0.14357,0.05054,,,,,,
99.1,8.259,38529.56,0.14393,0.05054,,,,,,
99.2,8.267,38486.38,0.14427,0.05055,,,,,,
99.3,8.275,38451.35,0.14463,0.05056,,,,,,
99.4,8.284,38435.07,0.14498,0.05056,,,,,,
99.5,8.292,38397.65,0.14533,0.05057,,,,,,
99.6,8.3,38369.82,0.14568,0.05057,,,,,,
99.7,8.308,38352.05,0.14603,0.05058,,,,,,
99.8,8.317,38334.82,0.14638,0.05059,,,,,,
99.9,8.325,38285.97,0.14674,0.05059,,,,,,
100,8.334,38242.6,0.14709,0.0506,,,,,,
100.1,8.342,38217.49,0.14744,0.0506,,,,,,
100.2,8.35,38172.82,0.14779,0.05061,,,,,,
100.3,8.358,38150.42,0.14815,0.05061,,,,,,
100.4,8.367,38139.63,0.1485,0.05062,,,,,,
100.5,8.375,38119.28,0.14886,0.05062,,,,,,
100.6,8.384,38068.56,0.14922,0.05063,,,,,,
100.7,8.392,38043.7,0.14957,0.05063,,,,,,
100.8,8.4,37988.11,0.14992,0.05064,,,,,,
100.9,8.409,37953.5,0.15027,0.05064,,,,,,
101,8.417,37925.19,0.15063,0.05064,,,,,,
101.1,8.425,37916.12,0.15098,0.05065,,,,,,
101.2,8.434,37885.18,0.15133,0.05065,,,,,,
101.3,8.442,37845.21,0.15169,0.05065,,,,,,
101.4,8.45,37828.98,0.15204,0.05066,,,,,,
101.5,8.458,37778.84,0.1524,0.05066,,,,,,
101.6,8.467,37747.87,0.15275,0.05067,,,,,,
101.7,8.475,37724.91,0.15311,0.05067,,,,,,
101.8,8.483,37691.67,0.15346,0.05067,,,,,,
101.9,8.492,37640.29,0.15382,0.05067,,,,,,
102,8.5,37616.05,0.15417,0.05068,,,,,,
102.1,8.508,37578.7,0.15452,0.05068,,,,,,
102.2,8.517,37548.66,0.15488,0.05068,,,,,,
102.3,8.525,37523.71,0.15524,0.05068,,,,,,
102.4,8.533,37500.37,0.15558,0.05069,,,,,,
102.5,8.542,37461.89,0.15594,0.05069,,,,,,
102.6,8.55,37424.27,0.15629,0.05069,,,,,,
102.7,8.558,37381.24,0.15665,0.05069,,,,,,
102.8,8.567,37332.68,0.15701,0.0507,,,,,,
102.9,8.575,37314.3,0.15736,0.0507,,,,,,
103,8.583,37298.26,0.15772,0.0507,,,,,,
103.1,8.592,37266.2,0.15807,0.0507,,,,,,
103.2,8.6,37215.66,0.15842,0.0507,,,,,,
103.3,8.608,37179.67,0.15878,0.05071,,,,,,
103.4,8.617,37133.09,0.15913,0.05071,,,,,,
103.5,8.625,37114.6,0.15947,0.05071,,,,,,
103.6,8.633,37080.8,0.15982,0.05071,,,,,,
103.7,8.642,37040.18,0.16017,0.05071,,,,,,
103.8,8.65,37009.39,0.16052,0.05071,,,,,,
103.9,8.658,36973.02,0.16088,0.05071,,,,,,
104,8.667,36925.71,0.16123,0.05071,,,,,,
104.1,8.675,36904.93,0.16159,0.05071,,,,,,
104.2,8.683,36873.68,0.16195,0.05071,,,,,,
104.3,8.692,36833.6,0.16231,0.05072,,,,,,
104.4,8.7,36791.96,0.16266,0.05072,,,,,,
104.5,8.709,36743.72,0.16303,0.05072,,,,,,
104.6,8.717,36708.41,0.16338,0.05072,,,,,,
104.7,8.725,36694.01,0.16374,0.05072,,,,,,
104.8,8.734,36661.55,0.1641,0.05072,,,,,,
104.9,8.742,36606.75,0.16446,0.05072,,,,,,
105,8.75,36581.67,0.16482,0.05072,,,,,,
105.1,8.759,36523.48,0.16518,0.05072,,,,,,
105.2,8.767,36495.4,0.16554,0.05072,,,,,,
105.3,8.775,36473.22,0.1659,0.05072,,,,,,
105.4,8.784,36430.09,0.16627,0.05072,,,,,,
105.5,8.792,36386,0.16663,0.05072,,,,,,
105.6,8.8,36344.89,0.16699,0.05072,,,,,,
105.7,8.809,36291.4,0.16735,0.05072,,,,,,
105.8,8.817,36275.64,0.16771,0.05072,,,,,,
105.9,8.825,36239.91,0.16808,0.05072,,,,,,
106,8.834,36191.92,0.16844,0.05072,,,,,,
106.1,8.842,36153.6,0.1688,0.05072,,,,,,
106.2,8.85,36103.07,0.16917,0.05072,,,,,,
106.3,8.859,36074.48,0.16953,0.05072,,,,,,
106.4,8.867,36045.81,0.16989,0.05072,,,,,,
106.5,8.875,35988.96,0.17025,0.05072,,,,,,
106.6,8.884,35955.66,0.17061,0.05072,,,,,,
106.7,8.892,35907.04,0.17097,0.05072,,,,,,
106.8,8.9,35875.48,0.17133,0.05072,,,,,,
106.9,8.909,35852.16,0.17168,0.05072,,,,,,
107,8.917,35808.39,0.17205,0.05072,,,,,,
107.1,8.925,35754.42,0.17242,0.05072,,,,,,
107.2,8.934,35705.71,0.17278,0.05072,,,,,,
107.3,8.942,35664.8,0.17314,0.05072,,,,,,
107.4,8.95,35644.43,0.1735,0.05072,,,,,,
107.5,8.959,35603.89,0.17386,0.05072,,,,,,
107.6,8.967,35558.84,0.17423,0.05072,,,,,,
107.7,8.975,35499.88,0.1746,0.05072,,,,,,
107.8,8.983,35457.11,0.17495,0.05072,,,,,,
107.9,8.992,35434.13,0.17531,0.05072,,,,,,
108,9,35381.86,0.17568,0.05072,,,,,,
108.1,9.008,35353.37,0.17604,0.05072,,,,,,
108.2,9.017,35305.02,0.17642,0.05072,,,,,,
108.3,9.025,35253.83,0.17678,0.05072,,,,,,
108.4,9.033,35218.87,0.17714,0.05071,,,,,,
108.5,9.042,35164.63,0.17751,0.05071,,,,,,
108.6,9.05,35119,0.17787,0.05071,,,,,,
108.7,9.059,35066.27,0.17824,0.05071,,,,,,
108.8,9.067,35045.27,0.1786,0.05071,,,,,,
108.9,9.075,35015.38,0.17897,0.05071,,,,,,
109,9.083,34947.84,0.17933,0.05071,,,,,,
109.1,9.092,34891.36,0.1797,0.05071,,,,,,
109.2,9.1,34844.32,0.18006,0.05071,,,,,,
109.3,9.109,34822.74,0.18043,0.05071,,,,,,
109.4,9.117,34775.84,0.1808,0.05071,,,,,,
109.5,9.125,34737.17,0.18116,0.05071,,,,,,
109.6,9.134,34671.86,0.18154,0.05071,,,,,,
109.7,9.142,34623.65,0.1819,0.0507,,,,,,
109.8,9.15,34593.41,0.18227,0.0507,,,,,,
109.9,9.158,34527.27,0.18263,0.0507,,,,,,
110,9.167,34484.71,0.183,0.0507,,,,,,
110.1,9.175,34446.06,0.18337,0.0507,,,,,,
110.2,9.183,34415.24,0.18373,0.0507,,,,,,
110.3,9.192,34344.23,0.1841,0.0507,,,,,,
110.4,9.2,34299.8,0.18448,0.0507,,,,,,
110.5,9.208,34232.72,0.18485,0.0507,,,,,,
110.6,9.217,34212,0.18521,0.0507,,,,,,
110.7,9.225,34170.86,0.18559,0.0507,,,,,,
110.8,9.234,34114.3,0.18596,0.0507,,,,,,
110.9,9.242,34034.39,0.18633,0.0507,,,,,,
111,9.25,33995.32,0.1867,0.05069,,,,,,
111.1,9.259,33947.44,0.18707,0.05069,,,,,,
111.2,9.267,33893.11,0.18745,0.05069,,,,,,
111.3,9.275,33826.3,0.18782,0.05069,,,,,,
111.4,9.284,33791.47,0.1882,0.05069,,,,,,
111.5,9.292,33680.99,0.1886,0.05069,,,,,,
111.6,9.3,33582,0.18903,0.05068,,,,,,
111.7,9.309,33281.11,0.1896,0.05068,,,,,,
111.742,9.313,16514.12,0.15307,0.05085,,,,,,