File: TensionLab/experimentalData/1018 Steel Sample 2.csv
Time (s),Extension (mm),Load (N),Axial Strain (mm/mm),Transverse Strain (mm/mm),Thickness(m),Width(m),Final length(m),Axial gauge length(m),Transverse gauge length(m),Crosshead Rate(mm/min)
0,0,-0.02,0,0,0.0063,0.0124,0.05711,0.0254,0.01238,5
0.1,0.004,9.23,0,0,,,,,,
0.2,0.014,194.42,0.00001,-0.00001,,,,,,
0.3,0.024,372.97,0,-0.00001,,,,,,
0.4,0.034,469.24,0,-0.00001,,,,,,
0.5,0.042,549.64,-0.00001,0,,,,,,
0.6,0.05,624.12,-0.00002,0.00001,,,,,,
0.7,0.059,681.12,-0.00003,0.00002,,,,,,
0.8,0.067,748.53,-0.00003,0.00002,,,,,,
0.9,0.075,826.41,-0.00003,0.00002,,,,,,
1,0.084,865.44,-0.00003,0.00003,,,,,,
1.1,0.092,958.05,-0.00002,0.00003,,,,,,
1.2,0.1,1024.36,-0.00002,0.00003,,,,,,
1.3,0.109,1083.7,-0.00001,0.00004,,,,,,
1.4,0.117,1162.07,-0.00001,0.00004,,,,,,
1.5,0.125,1253.79,-0.00001,0.00004,,,,,,
1.6,0.134,1315.22,-0.00001,0.00004,,,,,,
1.7,0.142,1423.1,0,0.00004,,,,,,
1.8,0.15,1485.22,0,0.00005,,,,,,
1.9,0.159,1576.97,0.00001,0.00005,,,,,,
2,0.167,1673.72,0.00001,0.00005,,,,,,
2.1,0.175,1755.02,0.00001,0.00005,,,,,,
2.2,0.184,1845.37,0.00002,0.00006,,,,,,
2.3,0.192,1897.82,0.00002,0.00006,,,,,,
2.4,0.2,1989.46,0.00002,0.00006,,,,,,
2.5,0.209,2066.5,0.00002,0.00006,,,,,,
2.6,0.217,2103.22,0.00003,0.00006,,,,,,
2.7,0.225,2180.37,0.00003,0.00007,,,,,,
2.8,0.234,2266.61,0.00003,0.00007,,,,,,
2.9,0.242,2315.83,0.00004,0.00007,,,,,,
3,0.25,2381.01,0.00004,0.00007,,,,,,
3.1,0.259,2450.22,0.00004,0.00007,,,,,,
3.2,0.267,2507.44,0.00004,0.00007,,,,,,
3.3,0.275,2591.98,0.00005,0.00007,,,,,,
3.4,0.284,2667.17,0.00005,0.00008,,,,,,
3.5,0.292,2700.1,0.00006,0.00008,,,,,,
3.6,0.3,2792.24,0.00006,0.00008,,,,,,
3.7,0.308,2875.93,0.00006,0.00008,,,,,,
3.8,0.317,2933.88,0.00007,0.00008,,,,,,
3.9,0.325,2996.84,0.00007,0.00008,,,,,,
4,0.334,3092.15,0.00007,0.00007,,,,,,
4.1,0.342,3151.09,0.00008,0.00007,,,,,,
4.2,0.35,3241.28,0.00008,0.00007,,,,,,
4.3,0.358,3299.92,0.00009,0.00007,,,,,,
4.4,0.367,3384.44,0.00009,0.00008,,,,,,
4.5,0.375,3486.94,0.00009,0.00007,,,,,,
4.6,0.384,3535.66,0.00009,0.00008,,,,,,
4.7,0.392,3618.12,0.0001,0.00007,,,,,,
4.8,0.4,3719.98,0.0001,0.00007,,,,,,
4.9,0.408,3797.53,0.00011,0.00007,,,,,,
5,0.417,3871.02,0.00011,0.00007,,,,,,
5.1,0.425,3948.33,0.00011,0.00007,,,,,,
5.2,0.433,4052.32,0.00011,0.00007,,,,,,
5.3,0.442,4132.16,0.00012,0.00007,,,,,,
5.4,0.45,4205.26,0.00012,0.00007,,,,,,
5.5,0.459,4311.78,0.00012,0.00007,,,,,,
5.6,0.467,4377.75,0.00012,0.00007,,,,,,
5.7,0.475,4467.24,0.00013,0.00007,,,,,,
5.8,0.484,4555.9,0.00013,0.00007,,,,,,
5.9,0.492,4647.12,0.00013,0.00007,,,,,,
6,0.5,4736.49,0.00013,0.00007,,,,,,
6.1,0.509,4796.65,0.00014,0.00007,,,,,,
6.2,0.517,4904.3,0.00014,0.00007,,,,,,
6.3,0.525,4971.33,0.00014,0.00007,,,,,,
6.4,0.533,5066.98,0.00015,0.00007,,,,,,
6.5,0.542,5161.18,0.00015,0.00007,,,,,,
6.6,0.55,5222.71,0.00015,0.00007,,,,,,
6.7,0.559,5319.51,0.00016,0.00007,,,,,,
6.8,0.567,5389.08,0.00016,0.00007,,,,,,
6.9,0.575,5486.52,0.00017,0.00008,,,,,,
7,0.583,5570.76,0.00017,0.00008,,,,,,
7.1,0.592,5652.99,0.00018,0.00008,,,,,,
7.2,0.6,5746.92,0.00018,0.00009,,,,,,
7.3,0.609,5814.61,0.00018,0.00009,,,,,,
7.4,0.617,5934.76,0.00019,0.00009,,,,,,
7.5,0.625,6011.94,0.00019,0.00009,,,,,,
7.6,0.633,6094.7,0.00019,0.00009,,,,,,
7.7,0.642,6209.48,0.0002,0.0001,,,,,,
7.8,0.65,6301.82,0.00021,0.0001,,,,,,
7.9,0.659,6389.04,0.00021,0.0001,,,,,,
8,0.667,6480.96,0.00021,0.00011,,,,,,
8.1,0.675,6596.28,0.00023,0.00011,,,,,,
8.2,0.684,6656.04,0.00023,0.00011,,,,,,
8.3,0.692,6780.75,0.00024,0.00011,,,,,,
8.4,0.7,6872.08,0.00025,0.00011,,,,,,
8.5,0.708,6963.26,0.00025,0.00012,,,,,,
8.6,0.717,7062.56,0.00025,0.00012,,,,,,
8.7,0.725,7183.99,0.00026,0.00012,,,,,,
8.8,0.733,7257.57,0.00027,0.00012,,,,,,
8.9,0.742,7382.25,0.00027,0.00013,,,,,,
9,0.75,7467.94,0.00028,0.00013,,,,,,
9.1,0.758,7577.99,0.00029,0.00013,,,,,,
9.2,0.767,7681.41,0.00029,0.00013,,,,,,
9.3,0.775,7777.28,0.0003,0.00013,,,,,,
9.4,0.783,7875.18,0.00031,0.00014,,,,,,
9.5,0.792,8005.46,0.00031,0.00014,,,,,,
9.6,0.8,8087.84,0.00032,0.00014,,,,,,
9.7,0.808,8207.92,0.00033,0.00014,,,,,,
9.8,0.817,8308.87,0.00034,0.00014,,,,,,
9.9,0.825,8426.83,0.00034,0.00015,,,,,,
10,0.834,8526.13,0.00035,0.00015,,,,,,
10.1,0.842,8629.58,0.00035,0.00015,,,,,,
10.2,0.85,8727.88,0.00036,0.00015,,,,,,
10.3,0.859,8864.24,0.00037,0.00015,,,,,,
10.4,0.867,8948.12,0.00037,0.00015,,,,,,
10.5,0.875,9072.5,0.00038,0.00016,,,,,,
10.6,0.883,9171.92,0.00039,0.00016,,,,,,
10.7,0.892,9297.48,0.0004,0.00017,,,,,,
10.8,0.9,9400.32,0.00041,0.00017,,,,,,
10.9,0.909,9508.93,0.00041,0.00017,,,,,,
11,0.917,9620.8,0.00042,0.00017,,,,,,
11.1,0.925,9722.24,0.00043,0.00017,,,,,,
11.2,0.933,9852.31,0.00044,0.00018,,,,,,
11.3,0.942,9952.78,0.00044,0.00018,,,,,,
11.4,0.95,10070.83,0.00045,0.00018,,,,,,
11.5,0.958,10175.8,0.00046,0.00018,,,,,,
11.6,0.967,10299.54,0.00047,0.00018,,,,,,
11.7,0.975,10417.94,0.00047,0.00019,,,,,,
11.8,0.983,10541.78,0.00048,0.00019,,,,,,
11.9,0.992,10634.7,0.00049,0.00019,,,,,,
12,1,10769.76,0.0005,0.00019,,,,,,
12.1,1.009,10867.2,0.00051,0.0002,,,,,,
12.2,1.017,10982.17,0.00051,0.0002,,,,,,
12.3,1.025,11118.97,0.00052,0.0002,,,,,,
12.4,1.033,11207.2,0.00053,0.0002,,,,,,
12.5,1.042,11361.52,0.00054,0.00021,,,,,,
12.6,1.05,11447.59,0.00054,0.00021,,,,,,
12.7,1.059,11569.68,0.00055,0.00021,,,,,,
12.8,1.067,11698.85,0.00056,0.00022,,,,,,
12.9,1.075,11799.16,0.00057,0.00022,,,,,,
13,1.084,11947.44,0.00058,0.00022,,,,,,
13.1,1.092,12041.39,0.00058,0.00022,,,,,,
13.2,1.1,12179.25,0.00059,0.00022,,,,,,
13.3,1.109,12286.08,0.0006,0.00023,,,,,,
13.4,1.117,12398.84,0.00061,0.00023,,,,,,
13.5,1.125,12533.5,0.00061,0.00023,,,,,,
13.6,1.134,12643.23,0.00062,0.00023,,,,,,
13.7,1.142,12788.76,0.00063,0.00024,,,,,,
13.8,1.15,12896.66,0.00064,0.00024,,,,,,
13.9,1.158,13019.27,0.00065,0.00024,,,,,,
14,1.167,13132.6,0.00066,0.00025,,,,,,
14.1,1.175,13255.26,0.00067,0.00025,,,,,,
14.2,1.184,13395.28,0.00068,0.00025,,,,,,
14.3,1.192,13515.71,0.00069,0.00026,,,,,,
14.4,1.2,13640.96,0.0007,0.00026,,,,,,
14.5,1.208,13771.94,0.0007,0.00026,,,,,,
14.6,1.217,13889.67,0.00071,0.00026,,,,,,
14.7,1.225,14025.18,0.00072,0.00027,,,,,,
14.8,1.233,14161.75,0.00073,0.00027,,,,,,
14.9,1.242,14267.84,0.00074,0.00028,,,,,,
15,1.25,14432.3,0.00075,0.00028,,,,,,
15.1,1.258,14537.42,0.00076,0.00028,,,,,,
15.2,1.267,14681.13,0.00077,0.00029,,,,,,
15.3,1.275,14809.53,0.00078,0.00029,,,,,,
15.4,1.284,14947.69,0.00079,0.00029,,,,,,
15.5,1.292,15077.99,0.0008,0.0003,,,,,,
15.6,1.3,15195.27,0.00081,0.0003,,,,,,
15.7,1.308,15336.27,0.00082,0.0003,,,,,,
15.8,1.317,15476.42,0.00083,0.00031,,,,,,
15.9,1.325,15606.25,0.00084,0.00031,,,,,,
16,1.333,15719.57,0.00085,0.00032,,,,,,
16.1,1.342,15879.03,0.00086,0.00032,,,,,,
16.2,1.35,15988.29,0.00087,0.00033,,,,,,
16.3,1.359,16135.8,0.00088,0.00033,,,,,,
16.4,1.367,16265.42,0.00089,0.00034,,,,,,
16.5,1.375,16400.38,0.00089,0.00034,,,,,,
16.6,1.384,16529.97,0.00091,0.00034,,,,,,
16.7,1.392,16662.02,0.00092,0.00035,,,,,,
16.8,1.4,16783.55,0.00093,0.00035,,,,,,
16.9,1.408,16934.04,0.00093,0.00035,,,,,,
17,1.417,17070.11,0.00094,0.00035,,,,,,
17.1,1.425,17197.33,0.00095,0.00036,,,,,,
17.2,1.433,17336.95,0.00096,0.00036,,,,,,
17.3,1.442,17470.65,0.00097,0.00036,,,,,,
17.4,1.45,17593.95,0.00098,0.00037,,,,,,
17.5,1.459,17753.98,0.00099,0.00037,,,,,,
17.6,1.467,17867.36,0.001,0.00038,,,,,,
17.7,1.475,17999.03,0.00101,0.00038,,,,,,
17.8,1.483,18153.84,0.00102,0.00038,,,,,,
17.9,1.492,18284,0.00103,0.00039,,,,,,
18,1.5,18415.84,0.00104,0.00039,,,,,,
18.1,1.508,18561.69,0.00105,0.0004,,,,,,
18.2,1.517,18698.45,0.00106,0.0004,,,,,,
18.3,1.525,18823.44,0.00107,0.0004,,,,,,
18.4,1.533,18987.65,0.00108,0.00041,,,,,,
18.5,1.542,19103.98,0.00109,0.00041,,,,,,
18.6,1.55,19248.59,0.0011,0.00042,,,,,,
18.7,1.558,19382.86,0.00111,0.00042,,,,,,
18.8,1.567,19534.16,0.00112,0.00042,,,,,,
18.9,1.575,19646.39,0.00113,0.00043,,,,,,
19,1.583,19821.16,0.00114,0.00044,,,,,,
19.1,1.592,19943.85,0.00115,0.00044,,,,,,
19.2,1.6,20084.69,0.00117,0.00045,,,,,,
19.3,1.608,20225.62,0.00118,0.00045,,,,,,
19.4,1.617,20368.59,0.00119,0.00045,,,,,,
19.5,1.625,20488.14,0.0012,0.00045,,,,,,
19.6,1.634,20650.15,0.00121,0.00046,,,,,,
19.7,1.642,20775.88,0.00122,0.00046,,,,,,
19.8,1.65,20910.18,0.00123,0.00047,,,,,,
19.9,1.658,21064.27,0.00124,0.00047,,,,,,
20,1.667,21210.26,0.00125,0.00048,,,,,,
20.1,1.675,21340.38,0.00126,0.00048,,,,,,
20.2,1.684,21491.26,0.00128,0.00049,,,,,,
20.3,1.692,21635.44,0.00129,0.00049,,,,,,
20.4,1.7,21763.74,0.0013,0.0005,,,,,,
20.5,1.708,21899.9,0.00131,0.0005,,,,,,
20.6,1.717,22069.48,0.00132,0.00051,,,,,,
20.7,1.725,22181.28,0.00133,0.00051,,,,,,
20.8,1.733,22334.12,0.00135,0.00052,,,,,,
20.9,1.742,22477.07,0.00136,0.00052,,,,,,
21,1.75,22617.09,0.00136,0.00053,,,,,,
21.1,1.758,22742.78,0.00137,0.00053,,,,,,
21.2,1.767,22923.41,0.00139,0.00054,,,,,,
21.3,1.775,23040.06,0.0014,0.00054,,,,,,
21.4,1.783,23192.99,0.00141,0.00055,,,,,,
21.5,1.792,23331.51,0.00143,0.00056,,,,,,
21.6,1.8,23491.83,0.00144,0.00056,,,,,,
21.7,1.808,23616.11,0.00145,0.00057,,,,,,
21.8,1.817,23770.5,0.00146,0.00057,,,,,,
21.9,1.825,23909.36,0.00147,0.00058,,,,,,
22,1.833,24055.04,0.00149,0.00058,,,,,,
22.1,1.842,24181.03,0.0015,0.00058,,,,,,
22.2,1.85,24352.5,0.00151,0.00059,,,,,,
22.3,1.858,24481.05,0.00152,0.0006,,,,,,
22.4,1.867,24615.97,0.00153,0.0006,,,,,,
22.5,1.875,24771.54,0.00154,0.00061,,,,,,
22.6,1.883,24913.71,0.00155,0.00061,,,,,,
22.7,1.892,25048.65,0.00157,0.00062,,,,,,
22.8,1.9,25197.21,0.00158,0.00062,,,,,,
22.9,1.909,25347.38,0.00159,0.00063,,,,,,
23,1.917,25472.04,0.0016,0.00064,,,,,,
23.1,1.925,25623.75,0.00162,0.00064,,,,,,
23.2,1.933,25776.95,0.00163,0.00065,,,,,,
23.3,1.942,25911.84,0.00164,0.00065,,,,,,
23.4,1.95,26044.54,0.00165,0.00066,,,,,,
23.5,1.958,26219.58,0.00167,0.00067,,,,,,
23.6,1.967,26338.87,0.00168,0.00067,,,,,,
23.7,1.975,26489.25,0.00169,0.00068,,,,,,
23.8,1.984,26634.12,0.00171,0.00068,,,,,,
23.9,1.992,26791.55,0.00172,0.00069,,,,,,
24,2,26920.73,0.00173,0.00069,,,,,,
24.1,2.009,27074.03,0.00175,0.0007,,,,,,
24.2,2.017,27214.23,0.00176,0.00071,,,,,,
24.3,2.025,27369.53,0.00177,0.00071,,,,,,
24.4,2.034,27493.62,0.00179,0.00072,,,,,,
24.5,2.042,27661.23,0.0018,0.00073,,,,,,
24.6,2.05,27794.38,0.00182,0.00073,,,,,,
24.7,2.058,27938.88,0.00183,0.00074,,,,,,
24.8,2.067,28080.55,0.00185,0.00075,,,,,,
24.9,2.075,28236.5,0.00186,0.00076,,,,,,
25,2.084,28358.16,0.00187,0.00076,,,,,,
25.1,2.092,28512.2,0.00189,0.00077,,,,,,
25.2,2.1,28660.89,0.0019,0.00078,,,,,,
25.3,2.108,28800.41,0.00191,0.00079,,,,,,
25.4,2.117,28933.82,0.00193,0.00079,,,,,,
25.5,2.125,29094.43,0.00194,0.0008,,,,,,
25.6,2.133,29223.46,0.00196,0.00081,,,,,,
25.7,2.142,29367.95,0.00197,0.00082,,,,,,
25.8,2.15,29519.75,0.00198,0.00082,,,,,,
25.9,2.158,29659.41,0.002,0.00083,,,,,,
26,2.167,29797.11,0.00201,0.00084,,,,,,
26.1,2.175,29951.11,0.00203,0.00085,,,,,,
26.2,2.184,30088.18,0.00204,0.00085,,,,,,
26.3,2.192,30231.76,0.00206,0.00086,,,,,,
26.4,2.2,30363.2,0.00208,0.00087,,,,,,
26.5,2.209,30528.48,0.00209,0.00088,,,,,,
26.6,2.217,30655.08,0.00211,0.00089,,,,,,
26.7,2.225,30798.88,0.00212,0.0009,,,,,,
26.8,2.233,30951.09,0.00213,0.00091,,,,,,
26.9,2.242,31093.73,0.00215,0.00092,,,,,,
27,2.25,31210.09,0.00217,0.00092,,,,,,
27.1,2.258,31377.52,0.00218,0.00093,,,,,,
27.2,2.267,31503.43,0.0022,0.00094,,,,,,
27.3,2.275,31641.75,0.00222,0.00095,,,,,,
27.4,2.283,31787.63,0.00223,0.00096,,,,,,
27.5,2.292,31928.67,0.00225,0.00097,,,,,,
27.6,2.3,32057.96,0.00227,0.00098,,,,,,
27.7,2.308,32220.36,0.00228,0.00099,,,,,,
27.8,2.317,32344.39,0.0023,0.001,,,,,,
27.9,2.325,32476.13,0.00231,0.00101,,,,,,
28,2.333,32622.62,0.00233,0.00102,,,,,,
28.1,2.342,32765.3,0.00235,0.00103,,,,,,
28.2,2.35,32892.15,0.00237,0.00104,,,,,,
28.3,2.359,33040.86,0.00238,0.00105,,,,,,
28.4,2.367,33167.06,0.0024,0.00106,,,,,,
28.5,2.375,33299.98,0.00242,0.00107,,,,,,
28.6,2.383,33447.24,0.00244,0.00108,,,,,,
28.7,2.392,33586.61,0.00245,0.00109,,,,,,
28.8,2.4,33707.09,0.00247,0.0011,,,,,,
28.9,2.408,33862.92,0.00249,0.00111,,,,,,
29,2.417,33974.9,0.00251,0.00112,,,,,,
29.1,2.425,34120.5,0.00252,0.00114,,,,,,
29.2,2.433,34259.81,0.00254,0.00115,,,,,,
29.3,2.442,34395.27,0.00256,0.00116,,,,,,
29.4,2.45,34512.7,0.00258,0.00117,,,,,,
29.5,2.458,34671.72,0.0026,0.00118,,,,,,
29.6,2.467,34782.28,0.00262,0.0012,,,,,,
29.7,2.475,34915.43,0.00264,0.00121,,,,,,
29.8,2.484,35063.15,0.00266,0.00122,,,,,,
29.9,2.492,35171.71,0.00268,0.00123,,,,,,
30,2.5,35318.88,0.0027,0.00124,,,,,,
30.1,2.508,35442.64,0.00272,0.00126,,,,,,
30.2,2.517,35572.2,0.00274,0.00127,,,,,,
30.3,2.525,35705.62,0.00276,0.00128,,,,,,
30.4,2.534,35830.67,0.00278,0.00129,,,,,,
30.5,2.542,35945.07,0.0028,0.0013,,,,,,
30.6,2.55,36085.19,0.00282,0.00132,,,,,,
30.7,2.558,36198.61,0.00284,0.00133,,,,,,
30.8,2.567,36342.34,0.00286,0.00134,,,,,,
30.9,2.575,36470.27,0.00289,0.00136,,,,,,
31,2.584,36581,0.00291,0.00137,,,,,,
31.1,2.592,36719.98,0.00293,0.00138,,,,,,
31.2,2.6,36836.31,0.00295,0.0014,,,,,,
31.3,2.608,36968.23,0.00298,0.00141,,,,,,
31.4,2.617,37086.55,0.003,0.00143,,,,,,
31.5,2.625,37201.1,0.00302,0.00144,,,,,,
31.6,2.633,37328.37,0.00304,0.00146,,,,,,
31.7,2.642,37446.2,0.00307,0.00147,,,,,,
31.8,2.65,37577.79,0.00309,0.00149,,,,,,
31.9,2.659,37693.25,0.00312,0.0015,,,,,,
32,2.667,37808.15,0.00314,0.00152,,,,,,
32.1,2.675,37925.66,0.00316,0.00154,,,,,,
32.2,2.683,38043.65,0.00319,0.00156,,,,,,
32.3,2.692,38171.48,0.00322,0.00157,,,,,,
32.4,2.7,38274.05,0.00325,0.00159,,,,,,
32.5,2.709,38405.66,0.00327,0.00161,,,,,,
32.6,2.717,38503.08,0.0033,0.00162,,,,,,
32.7,2.725,38627.55,0.00332,0.00164,,,,,,
32.8,2.733,38725.89,0.00335,0.00166,,,,,,
32.9,2.742,38835.71,0.00337,0.00168,,,,,,
33,2.75,38969.66,0.0034,0.0017,,,,,,
33.1,2.759,39059.68,0.00343,0.00172,,,,,,
33.2,2.767,39197.54,0.00345,0.00174,,,,,,
33.3,2.775,39276.68,0.00348,0.00176,,,,,,
33.4,2.783,39400.89,0.00351,0.00178,,,,,,
33.5,2.792,39507.75,0.00354,0.0018,,,,,,
33.6,2.8,39616.99,0.00357,0.00182,,,,,,
33.7,2.809,39712.19,0.0036,0.00184,,,,,,
33.8,2.817,39837.47,0.00363,0.00186,,,,,,
33.9,2.825,39915.61,0.00366,0.00188,,,,,,
34,2.833,40036.96,0.00369,0.0019,,,,,,
34.1,2.842,40126.12,0.00372,0.00193,,,,,,
34.2,2.85,40242.74,0.00375,0.00195,,,,,,
34.3,2.858,40331.34,0.00379,0.00197,,,,,,
34.4,2.867,40448.94,0.00382,0.00199,,,,,,
34.5,2.875,40533.06,0.00386,0.00202,,,,,,
34.6,2.884,40643.06,0.00389,0.00204,,,,,,
34.7,2.892,40719.82,0.00393,0.00207,,,,,,
34.8,2.9,40832.25,0.00396,0.0021,,,,,,
34.9,2.908,40908.54,0.004,0.00212,,,,,,
35,2.917,41015.88,0.00403,0.00215,,,,,,
35.1,2.925,41097.45,0.00407,0.00218,,,,,,
35.2,2.933,41200.65,0.00411,0.0022,,,,,,
35.3,2.942,41291.83,0.00415,0.00223,,,,,,
35.4,2.95,41377.41,0.00419,0.00226,,,,,,
35.5,2.959,41481.62,0.00423,0.00229,,,,,,
35.6,2.967,41534.01,0.00427,0.00232,,,,,,
35.7,2.975,41645.71,0.00431,0.00235,,,,,,
35.8,2.984,41721.38,0.00435,0.00238,,,,,,
35.9,2.992,41809.22,0.00439,0.00241,,,,,,
36,3,41896.64,0.00443,0.00244,,,,,,
36.1,3.008,41967.78,0.00448,0.00248,,,,,,
36.2,3.017,42061.78,0.00453,0.00251,,,,,,
36.3,3.025,42125.04,0.00457,0.00254,,,,,,
36.4,3.033,42218.46,0.00462,0.00258,,,,,,
36.5,3.042,42309.03,0.00466,0.00261,,,,,,
36.6,3.05,42356.62,0.00471,0.00265,,,,,,
36.7,3.059,42433.85,0.00476,0.00269,,,,,,
36.8,3.067,42532.23,0.00481,0.00272,,,,,,
36.9,3.075,42582.02,0.00486,0.00276,,,,,,
37,3.084,42663.61,0.00491,0.0028,,,,,,
37.1,3.092,42737.02,0.00496,0.00284,,,,,,
37.2,3.1,42794.58,0.00501,0.00288,,,,,,
37.3,3.109,42878.34,0.00507,0.00292,,,,,,
37.4,3.117,42944.52,0.00513,0.00296,,,,,,
37.5,3.125,42994.12,0.00519,0.003,,,,,,
37.6,3.134,43065.02,0.00524,0.00304,,,,,,
37.7,3.142,43142.61,0.0053,0.00309,,,,,,
37.8,3.15,43181.29,0.00536,0.00313,,,,,,
37.9,3.159,43251.7,0.00542,0.00318,,,,,,
38,3.167,43316.44,0.00548,0.00322,,,,,,
38.1,3.175,43367.02,0.00554,0.00327,,,,,,
38.2,3.183,43432.85,0.0056,0.00331,,,,,,
38.3,3.192,43489.16,0.00567,0.00336,,,,,,
38.4,3.2,43550.39,0.00573,0.00341,,,,,,
38.5,3.209,43584.7,0.0058,0.00346,,,,,,
38.6,3.217,43650.15,0.00587,0.00351,,,,,,
38.7,3.225,43707.77,0.00593,0.00356,,,,,,
38.8,3.233,43768.71,0.006,0.00361,,,,,,
38.9,3.242,43786.67,0.00608,0.00365,,,,,,
39,3.25,43848.37,0.00615,0.00371,,,,,,
39.1,3.259,43893.45,0.00622,0.00376,,,,,,
39.2,3.267,43957.9,0.0063,0.00381,,,,,,
39.3,3.275,43987.26,0.00637,0.00386,,,,,,
39.4,3.283,44030.28,0.00644,0.00392,,,,,,
39.5,3.292,44084.4,0.00652,0.00397,,,,,,
39.6,3.3,44127.09,0.0066,0.00403,,,,,,
39.7,3.308,44170.61,0.00668,0.00408,,,,,,
39.8,3.317,44200.48,0.00676,0.00414,,,,,,
39.9,3.325,44233.21,0.00684,0.0042,,,,,,
40,3.334,44285.95,0.00692,0.00426,,,,,,
40.1,3.342,44317.32,0.00701,0.00431,,,,,,
40.2,3.35,44364.56,0.00709,0.00437,,,,,,
40.3,3.358,44391.23,0.00718,0.00443,,,,,,
40.4,3.367,44411.99,0.00727,0.00449,,,,,,
40.5,3.375,44448.07,0.00735,0.00455,,,,,,
40.6,3.383,44503.23,0.00744,0.00461,,,,,,
40.7,3.392,44531.55,0.00753,0.00467,,,,,,
40.8,3.4,44572.29,0.00762,0.00474,,,,,,
40.9,3.408,44590.25,0.00771,0.0048,,,,,,
41,3.417,44610.7,0.00781,0.00486,,,,,,
41.1,3.425,44643.34,0.0079,0.00492,,,,,,
41.2,3.434,44680.57,0.008,0.00499,,,,,,
41.3,3.442,44704.42,0.00809,0.00505,,,,,,
41.4,3.45,44728.84,0.00819,0.00512,,,,,,
41.5,3.458,44766.23,0.00829,0.00518,,,,,,
41.6,3.467,44804.71,0.00839,0.00524,,,,,,
41.7,3.475,44814.37,0.00849,0.00531,,,,,,
41.8,3.484,44829.9,0.00859,0.00538,,,,,,
41.9,3.492,44850.64,0.0087,0.00545,,,,,,
42,3.5,44879.95,0.0088,0.00552,,,,,,
42.1,3.509,44906.43,0.0089,0.00558,,,,,,
42.2,3.517,44921.09,0.00901,0.00565,,,,,,
42.3,3.525,44959.36,0.00911,0.00572,,,,,,
42.4,3.534,44985.22,0.00922,0.00579,,,,,,
42.5,3.542,45001.17,0.00932,0.00586,,,,,,
42.6,3.55,45009.35,0.00943,0.00593,,,,,,
42.7,3.558,45021.11,0.00954,0.006,,,,,,
42.8,3.567,45042.28,0.00965,0.00607,,,,,,
42.9,3.575,45067.79,0.00976,0.00614,,,,,,
43,3.583,45089.14,0.00987,0.00621,,,,,,
43.1,3.592,45113.85,0.00999,0.00628,,,,,,
43.2,3.6,45127.77,0.0101,0.00635,,,,,,
43.3,3.609,45144.04,0.01021,0.00643,,,,,,
43.4,3.617,45164.48,0.01033,0.0065,,,,,,
43.5,3.625,45175.81,0.01044,0.00657,,,,,,
43.6,3.634,45192.76,0.01055,0.00664,,,,,,
43.7,3.642,45210.3,0.01067,0.00671,,,,,,
43.8,3.65,45219.78,0.01079,0.00679,,,,,,
43.9,3.659,45223.46,0.0109,0.00686,,,,,,
44,3.667,45236.31,0.01102,0.00693,,,,,,
44.1,3.675,45252.84,0.01114,0.007,,,,,,
44.2,3.684,45263.61,0.01126,0.00708,,,,,,
44.3,3.692,45276.68,0.01138,0.00716,,,,,,
44.4,3.7,45293.55,0.0115,0.00723,,,,,,
44.5,3.709,45312.01,0.01162,0.0073,,,,,,
44.6,3.717,45325.21,0.01174,0.00738,,,,,,
44.7,3.725,45337.96,0.01186,0.00745,,,,,,
44.8,3.734,45347.87,0.01199,0.00753,,,,,,
44.9,3.742,45366.6,0.01212,0.0076,,,,,,
45,3.75,45378.8,0.01224,0.00768,,,,,,
45.1,3.759,45387.09,0.01237,0.00776,,,,,,
45.2,3.767,45403.69,0.0125,0.00783,,,,,,
45.3,3.775,45419.16,0.01262,0.00791,,,,,,
45.4,3.784,45422.51,0.01275,0.00799,,,,,,
45.5,3.792,45425.62,0.01287,0.00806,,,,,,
45.6,3.8,45427.8,0.013,0.00814,,,,,,
45.7,3.808,45434.12,0.01313,0.00821,,,,,,
45.8,3.817,45438.33,0.01326,0.00829,,,,,,
45.9,3.825,45441.16,0.01339,0.00837,,,,,,
46,3.833,45445.53,0.01352,0.00844,,,,,,
46.1,3.842,45452.25,0.01365,0.00852,,,,,,
46.2,3.85,45456.01,0.01378,0.0086,,,,,,
46.3,3.858,45458.71,0.0139,0.00867,,,,,,
46.4,3.867,45469.01,0.01403,0.00875,,,,,,
46.5,3.875,45485.26,0.01416,0.00883,,,,,,
46.6,3.884,45490.68,0.0143,0.00891,,,,,,
46.7,3.892,45501.68,0.01443,0.00898,,,,,,
46.8,3.9,45510.27,0.01456,0.00906,,,,,,
46.9,3.909,45520.38,0.01469,0.00914,,,,,,
47,3.917,45527.29,0.01483,0.00921,,,,,,
47.1,3.925,45529.94,0.01496,0.0093,,,,,,
47.2,3.933,45535.38,0.01509,0.00937,,,,,,
47.3,3.942,45535.87,0.01523,0.00945,,,,,,
47.4,3.95,45542.98,0.01537,0.00953,,,,,,
47.5,3.959,45558.08,0.0155,0.00961,,,,,,
47.6,3.967,45558.76,0.01564,0.00969,,,,,,
47.7,3.975,45567.13,0.01577,0.00977,,,,,,
47.8,3.984,45578.38,0.01591,0.00986,,,,,,
47.9,3.992,45579.41,0.01604,0.00993,,,,,,
48,4,45584.86,0.01619,0.01002,,,,,,
48.1,4.009,45586.71,0.01633,0.0101,,,,,,
48.2,4.017,45587.78,0.01646,0.01018,,,,,,
48.3,4.025,45592.11,0.0166,0.01026,,,,,,
48.4,4.034,45591.72,0.01673,0.01034,,,,,,
48.5,4.042,45596.21,0.01687,0.01043,,,,,,
48.6,4.05,45610.88,0.01701,0.01051,,,,,,
48.7,4.059,45611.29,0.01715,0.01059,,,,,,
48.8,4.067,45618.39,0.01729,0.01067,,,,,,
48.9,4.075,45621.19,0.01744,0.01075,,,,,,
49,4.083,45622.14,0.01758,0.01084,,,,,,
49.1,4.092,45625.51,0.01772,0.01092,,,,,,
49.2,4.1,45629.54,0.01786,0.011,,,,,,
49.3,4.109,45630.56,0.018,0.01108,,,,,,
49.4,4.117,45629,0.01815,0.01116,,,,,,
49.5,4.125,45630.11,0.01829,0.01124,,,,,,
49.6,4.134,45633.48,0.01843,0.01132,,,,,,
49.7,4.142,45634.21,0.01858,0.0114,,,,,,
49.8,4.15,45632.53,0.01872,0.01149,,,,,,
49.9,4.159,45638.37,0.01886,0.01157,,,,,,
50,4.167,45639.11,0.01902,0.01165,,,,,,
50.1,4.175,45639.54,0.01916,0.01173,,,,,,
50.2,4.184,45638.61,0.01932,0.01182,,,,,,
50.3,4.192,45641.5,0.01946,0.0119,,,,,,
50.4,4.2,45641.84,0.01961,0.01199,,,,,,
50.5,4.209,45641.27,0.01976,0.01207,,,,,,
50.6,4.217,45638.89,0.0199,0.01215,,,,,,
50.7,4.225,45642.4,0.02004,0.01224,,,,,,
50.8,4.234,45642.4,0.0202,0.01232,,,,,,
50.9,4.242,45643.45,0.02035,0.0124,,,,,,
51,4.25,45641.21,0.0205,0.01249,,,,,,
51.1,4.258,45640.74,0.02065,0.01257,,,,,,
51.2,4.267,45643.44,0.02079,0.01266,,,,,,
51.3,4.275,45644.4,0.02095,0.01274,,,,,,
51.4,4.284,45643.05,0.02109,0.01283,,,,,,
51.5,4.292,45643.09,0.02125,0.01291,,,,,,
51.6,4.3,45642.76,0.0214,0.013,,,,,,
51.7,4.308,45641.96,0.02154,0.01308,,,,,,
51.8,4.317,45642.3,0.02169,0.01317,,,,,,
51.9,4.325,45643.66,0.02185,0.01325,,,,,,
52,4.334,45641.98,0.022,0.01334,,,,,,
52.1,4.342,45640.42,0.02216,0.01342,,,,,,
52.2,4.35,45642.64,0.02231,0.01351,,,,,,
52.3,4.359,45642.09,0.02247,0.01359,,,,,,
52.4,4.367,45641.89,0.02263,0.01368,,,,,,
52.5,4.375,45641.84,0.02278,0.01377,,,,,,
52.6,4.384,45639.25,0.02294,0.01385,,,,,,
52.7,4.392,45638.08,0.0231,0.01394,,,,,,
52.8,4.4,45637.23,0.02325,0.01402,,,,,,
52.9,4.409,45636.12,0.02341,0.01411,,,,,,
53,4.417,45637.71,0.02357,0.0142,,,,,,
53.1,4.425,45635,0.02373,0.01429,,,,,,
53.2,4.433,45631.8,0.02389,0.01437,,,,,,
53.3,4.442,45631.37,0.02404,0.01445,,,,,,
53.4,4.45,45632.08,0.02421,0.01454,,,,,,
53.5,4.459,45631.76,0.02436,0.01463,,,,,,
53.6,4.467,45628.91,0.02453,0.01472,,,,,,
53.7,4.475,45625.89,0.02468,0.01481,,,,,,
53.8,4.483,45625.9,0.02484,0.01489,,,,,,
53.9,4.492,45622.99,0.025,0.01498,,,,,,
54,4.5,45622.68,0.02516,0.01507,,,,,,
54.1,4.509,45616.77,0.02533,0.01516,,,,,,
54.2,4.517,45612.65,0.02549,0.01525,,,,,,
54.3,4.525,45615.05,0.02565,0.01533,,,,,,
54.4,4.533,45613.33,0.02581,0.01542,,,,,,
54.5,4.542,45609.45,0.02597,0.01551,,,,,,
54.6,4.55,45607.98,0.02614,0.0156,,,,,,
54.7,4.559,45603.79,0.02631,0.01569,,,,,,
54.8,4.567,45597.14,0.02648,0.01578,,,,,,
54.9,4.575,45594.2,0.02665,0.01588,,,,,,
55,4.584,45594.92,0.02681,0.01597,,,,,,
55.1,4.592,45596.57,0.02698,0.01606,,,,,,
55.2,4.6,45590.43,0.02715,0.01615,,,,,,
55.3,4.608,45585.37,0.02732,0.01624,,,,,,
55.4,4.617,45584.15,0.02748,0.01633,,,,,,
55.5,4.625,45583.3,0.02766,0.01642,,,,,,
55.6,4.634,45580.03,0.02783,0.01652,,,,,,
55.7,4.642,45572.12,0.028,0.01661,,,,,,
55.8,4.65,45560.12,0.02817,0.0167,,,,,,
55.9,4.658,45556.57,0.02834,0.0168,,,,,,
56,4.667,45548.06,0.02851,0.01689,,,,,,
56.1,4.675,45547.34,0.02868,0.01698,,,,,,
56.2,4.683,45540.67,0.02885,0.01708,,,,,,
56.3,4.692,45543.71,0.02903,0.01717,,,,,,
56.4,4.7,45536.75,0.0292,0.01727,,,,,,
56.5,4.708,45532.1,0.02938,0.01736,,,,,,
56.6,4.717,45531.84,0.02955,0.01745,,,,,,
56.7,4.725,45528.98,0.02972,0.01755,,,,,,
56.8,4.733,45526.64,0.0299,0.01764,,,,,,
56.9,4.742,45526.38,0.03007,0.01774,,,,,,
57,4.75,45516.25,0.03025,0.01783,,,,,,
57.1,4.758,45506.42,0.03043,0.01793,,,,,,
57.2,4.767,45511.5,0.0306,0.01803,,,,,,
57.3,4.775,45500.3,0.03078,0.01812,,,,,,
57.4,4.784,45495.12,0.03096,0.01822,,,,,,
57.5,4.792,45493.43,0.03114,0.01832,,,,,,
57.6,4.8,45480.29,0.03132,0.01842,,,,,,
57.7,4.809,45477.11,0.0315,0.01852,,,,,,
57.8,4.817,45475.07,0.03169,0.01862,,,,,,
57.9,4.825,45467.71,0.03186,0.01872,,,,,,
58,4.834,45461.16,0.03204,0.01882,,,,,,
58.1,4.842,45457.93,0.03222,0.01892,,,,,,
58.2,4.85,45450.81,0.03241,0.01902,,,,,,
58.3,4.859,45449.42,0.03259,0.01912,,,,,,
58.4,4.867,45446.95,0.03278,0.01922,,,,,,
58.5,4.875,45444.02,0.03296,0.01932,,,,,,
58.6,4.883,45439.66,0.03315,0.01942,,,,,,
58.7,4.892,45438.75,0.03334,0.01952,,,,,,
58.8,4.9,45440.27,0.03353,0.01962,,,,,,
58.9,4.909,45434.57,0.03373,0.01973,,,,,,
59,4.917,45430.36,0.03393,0.01983,,,,,,
59.1,4.925,45428.79,0.03412,0.01993,,,,,,
59.2,4.934,45427,0.03432,0.02004,,,,,,
59.3,4.942,45425.55,0.03452,0.02014,,,,,,
59.4,4.95,45425.57,0.03472,0.02025,,,,,,
59.5,4.959,45424.82,0.03492,0.02035,,,,,,
59.6,4.967,45422.22,0.03512,0.02046,,,,,,
59.7,4.975,45417.08,0.03532,0.02057,,,,,,
59.8,4.984,45405.37,0.03552,0.02067,,,,,,
59.9,4.992,45398.8,0.03572,0.02078,,,,,,
60,5,45395.86,0.03593,0.02088,,,,,,
60.1,5.009,45391.64,0.03614,0.02099,,,,,,
60.2,5.017,45378.66,0.03634,0.0211,,,,,,
60.3,5.025,45370.3,0.03655,0.02121,,,,,,
60.4,5.034,45365.6,0.03675,0.02132,,,,,,
60.5,5.042,45354.05,0.03696,0.02143,,,,,,
60.6,5.05,45346.89,0.03716,0.02154,,,,,,
60.7,5.058,45337.89,0.03737,0.02165,,,,,,
60.8,5.067,45337.61,0.03758,0.02176,,,,,,
60.9,5.075,45337.06,0.03779,0.02187,,,,,,
61,5.084,45331.11,0.038,0.02198,,,,,,
61.1,5.092,45313.48,0.03821,0.0221,,,,,,
61.2,5.1,45306.89,0.03841,0.02221,,,,,,
61.3,5.109,45300.68,0.03863,0.02232,,,,,,
61.4,5.117,45287.9,0.03884,0.02243,,,,,,
61.5,5.125,45286.18,0.03905,0.02254,,,,,,
61.6,5.134,45281.78,0.03926,0.02266,,,,,,
61.7,5.142,45275.29,0.03947,0.02278,,,,,,
61.8,5.15,45270.82,0.03968,0.02289,,,,,,
61.9,5.158,45263.99,0.0399,0.02301,,,,,,
62,5.167,45256.17,0.04012,0.02312,,,,,,
62.1,5.175,45255.21,0.04033,0.02324,,,,,,
62.2,5.184,45243.45,0.04055,0.02336,,,,,,
62.3,5.192,45230.34,0.04077,0.02348,,,,,,
62.4,5.2,45224.51,0.04098,0.0236,,,,,,
62.5,5.209,45222.3,0.04119,0.02372,,,,,,
62.6,5.217,45221.97,0.04141,0.02383,,,,,,
62.7,5.225,45219.61,0.04164,0.02396,,,,,,
62.8,5.233,45212.96,0.04186,0.02408,,,,,,
62.9,5.242,45210.29,0.04208,0.0242,,,,,,
63,5.25,45204.91,0.0423,0.02432,,,,,,
63.1,5.258,45200.18,0.04252,0.02445,,,,,,
63.2,5.267,45194.95,0.04275,0.02458,,,,,,
63.3,5.275,45181.86,0.04298,0.0247,,,,,,
63.4,5.283,45174.29,0.0432,0.02483,,,,,,
63.5,5.292,45166.46,0.04342,0.02495,,,,,,
63.6,5.3,45155.99,0.04364,0.02508,,,,,,
63.7,5.309,45156.16,0.04387,0.0252,,,,,,
63.8,5.317,45141.54,0.0441,0.02533,,,,,,
63.9,5.325,45137.91,0.04432,0.02546,,,,,,
64,5.334,45130.51,0.04455,0.02559,,,,,,
64.1,5.342,45123.83,0.04479,0.02572,,,,,,
64.2,5.35,45120.94,0.04501,0.02585,,,,,,
64.3,5.358,45112.84,0.04524,0.02599,,,,,,
64.4,5.367,45106.92,0.04547,0.02612,,,,,,
64.5,5.375,45087.34,0.0457,0.02625,,,,,,
64.6,5.383,45072.96,0.04594,0.02638,,,,,,
64.7,5.392,45068.56,0.04617,0.02652,,,,,,
64.8,5.4,45063.65,0.0464,0.02665,,,,,,
64.9,5.409,45050.79,0.04663,0.02679,,,,,,
65,5.417,45037.8,0.04687,0.02692,,,,,,
65.1,5.425,45032.89,0.04711,0.02706,,,,,,
65.2,5.433,45027.25,0.04734,0.0272,,,,,,
65.3,5.442,45017.51,0.04758,0.02734,,,,,,
65.4,5.45,45011.79,0.04782,0.02748,,,,,,
65.5,5.459,45007.71,0.04806,0.02762,,,,,,
65.6,5.467,45003.41,0.0483,0.02776,,,,,,
65.7,5.475,45001.09,0.04853,0.0279,,,,,,
65.8,5.484,44995.96,0.04878,0.02805,,,,,,
65.9,5.492,44988.59,0.04901,0.02819,,,,,,
66,5.5,44981.99,0.04926,0.02834,,,,,,
66.1,5.508,44965.13,0.04948,0.02848,,,,,,
66.2,5.517,44952.51,0.04971,0.02863,,,,,,
66.3,5.525,44945.25,0.04995,0.02877,,,,,,
66.4,5.534,44921.78,0.0502,0.02892,,,,,,
66.5,5.542,44915.95,0.05044,0.02907,,,,,,
66.6,5.55,44911.51,0.05068,0.02922,,,,,,
66.7,5.558,44896.69,0.05093,0.02936,,,,,,
66.8,5.567,44890.34,0.05117,0.02951,,,,,,
66.9,5.575,44878.36,0.05141,0.02967,,,,,,
67,5.584,44864.59,0.05166,0.02982,,,,,,
67.1,5.592,44858.67,0.05191,0.02996,,,,,,
67.2,5.6,44848.41,0.05216,0.03012,,,,,,
67.3,5.608,44840.02,0.0524,0.03027,,,,,,
67.4,5.617,44836.98,0.05265,0.03042,,,,,,
67.5,5.625,44823.55,0.0529,0.03058,,,,,,
67.6,5.634,44816,0.05315,0.03073,,,,,,
67.7,5.642,44813.51,0.05339,0.03089,,,,,,
67.8,5.65,44810,0.05364,0.03104,,,,,,
67.9,5.659,44805.51,0.0539,0.0312,,,,,,
68,5.667,44797.15,0.05415,0.03136,,,,,,
68.1,5.675,44783.03,0.05439,0.03151,,,,,,
68.2,5.684,44773.77,0.05464,0.03167,,,,,,
68.3,5.692,44754.44,0.0549,0.03183,,,,,,
68.4,5.7,44734.96,0.05515,0.03199,,,,,,
68.5,5.709,44724.64,0.05541,0.03215,,,,,,
68.6,5.717,44710.4,0.05566,0.03231,,,,,,
68.7,5.725,44704.72,0.05591,0.03247,,,,,,
68.8,5.734,44697.3,0.05616,0.03264,,,,,,
68.9,5.742,44678.05,0.05641,0.03279,,,,,,
69,5.75,44675.67,0.05667,0.03295,,,,,,
69.1,5.759,44659.17,0.05693,0.03312,,,,,,
69.2,5.767,44647.07,0.05718,0.03328,,,,,,
69.3,5.775,44630.55,0.05743,0.03344,,,,,,
69.4,5.783,44617.72,0.05768,0.0336,,,,,,
69.5,5.792,44612.56,0.05795,0.03377,,,,,,
69.6,5.8,44603.77,0.05821,0.03393,,,,,,
69.7,5.808,44595.27,0.05846,0.03409,,,,,,
69.8,5.817,44589.86,0.05871,0.03426,,,,,,
69.9,5.825,44582.72,0.05898,0.03443,,,,,,
70,5.833,44571.34,0.05923,0.03459,,,,,,
70.1,5.842,44557.62,0.05949,0.03476,,,,,,
70.2,5.85,44547.07,0.05975,0.03492,,,,,,
70.3,5.859,44532.64,0.06001,0.03509,,,,,,
70.4,5.867,44516.78,0.06027,0.03526,,,,,,
70.5,5.875,44505.57,0.06053,0.03543,,,,,,
70.6,5.884,44502.08,0.06079,0.03559,,,,,,
70.7,5.892,44494.64,0.06106,0.03576,,,,,,
70.8,5.9,44455.98,0.06133,0.03594,,,,,,
70.9,5.909,44437.21,0.06158,0.0361,,,,,,
71,5.917,44424.47,0.06184,0.03627,,,,,,
71.1,5.925,44415.48,0.06211,0.03644,,,,,,
71.2,5.934,44406,0.06237,0.03661,,,,,,
71.3,5.942,44398.81,0.06264,0.03678,,,,,,
71.4,5.95,44390.34,0.06289,0.03695,,,,,,
71.5,5.959,44388.76,0.06316,0.03712,,,,,,
71.6,5.967,44383.42,0.06343,0.03729,,,,,,
71.7,5.975,44372.21,0.06369,0.03746,,,,,,
71.8,5.984,44357.11,0.06396,0.03763,,,,,,
71.9,5.992,44333.68,0.06423,0.0378,,,,,,
72,6,44316.07,0.06449,0.03797,,,,,,
72.1,6.008,44296.84,0.06475,0.03814,,,,,,
72.2,6.017,44289.05,0.06502,0.03831,,,,,,
72.3,6.025,44282.66,0.06529,0.03848,,,,,,
72.4,6.034,44264.46,0.06555,0.03865,,,,,,
72.5,6.042,44243.89,0.06582,0.03882,,,,,,
72.6,6.05,44229.35,0.06609,0.03899,,,,,,
72.7,6.059,44215.88,0.06636,0.03915,,,,,,
72.8,6.067,44206.65,0.06663,0.03932,,,,,,
72.9,6.075,44196.38,0.0669,0.03949,,,,,,
73,6.083,44184.11,0.06717,0.03966,,,,,,
73.1,6.092,44177.95,0.06744,0.03983,,,,,,
73.2,6.1,44164.57,0.06771,0.03999,,,,,,
73.3,6.109,44147.97,0.06798,0.04016,,,,,,
73.4,6.117,44138.19,0.06825,0.04033,,,,,,
73.5,6.125,44119.78,0.06852,0.0405,,,,,,
73.6,6.134,44093.64,0.0688,0.04067,,,,,,
73.7,6.142,44086.18,0.06908,0.04083,,,,,,
73.8,6.15,44081.35,0.06935,0.041,,,,,,
73.9,6.159,44070.48,0.06962,0.04117,,,,,,
74,6.167,44049.92,0.0699,0.04134,,,,,,
74.1,6.175,44027.6,0.07017,0.0415,,,,,,
74.2,6.183,44005.5,0.07044,0.04167,,,,,,
74.3,6.192,43998.34,0.07071,0.04183,,,,,,
74.4,6.2,43993.02,0.07099,0.04199,,,,,,
74.5,6.209,43978.4,0.07126,0.04216,,,,,,
74.6,6.217,43970.21,0.07153,0.04232,,,,,,
74.7,6.225,43960.64,0.07181,0.04248,,,,,,
74.8,6.233,43948.3,0.07208,0.04265,,,,,,
74.9,6.242,43930.79,0.07236,0.04281,,,,,,
75,6.25,43899.77,0.07263,0.04297,,,,,,
75.1,6.259,43885.67,0.0729,0.04313,,,,,,
75.2,6.267,43878.58,0.07318,0.04329,,,,,,
75.3,6.275,43865.57,0.07346,0.04345,,,,,,
75.4,6.284,43843.28,0.07373,0.04361,,,,,,
75.5,6.292,43821.05,0.074,0.04377,,,,,,
75.6,6.3,43809.86,0.07427,0.04393,,,,,,
75.7,6.309,43795.8,0.07456,0.04409,,,,,,
75.8,6.317,43783.31,0.07484,0.04425,,,,,,
75.9,6.325,43781.06,0.07511,0.04441,,,,,,
76,6.334,43777,0.07539,0.04456,,,,,,
76.1,6.342,43771.24,0.07567,0.04472,,,,,,
76.2,6.35,43757.46,0.07595,0.04488,,,,,,
76.3,6.359,43728.31,0.07623,0.04503,,,,,,
76.4,6.367,43705.43,0.0765,0.04519,,,,,,
76.5,6.375,43685.45,0.07677,0.04534,,,,,,
76.6,6.384,43671.02,0.07705,0.04549,,,,,,
76.7,6.392,43660.53,0.07734,0.04565,,,,,,
76.8,6.4,43645.49,0.07761,0.0458,,,,,,
76.9,6.408,43617.77,0.07788,0.04595,,,,,,
77,6.417,43604.5,0.07816,0.0461,,,,,,
77.1,6.425,43585.25,0.07843,0.04625,,,,,,
77.2,6.433,43577.84,0.07871,0.0464,,,,,,
77.3,6.442,43574.85,0.07899,0.04655,,,,,,
77.4,6.45,43564.26,0.07928,0.0467,,,,,,
77.5,6.458,43550.86,0.07955,0.04685,,,,,,
77.6,6.467,43540.88,0.07983,0.047,,,,,,
77.7,6.475,43525.45,0.08012,0.04715,,,,,,
77.8,6.484,43503.97,0.0804,0.0473,,,,,,
77.9,6.492,43485.59,0.08068,0.04744,,,,,,
78,6.5,43476.06,0.08096,0.04759,,,,,,
78.1,6.508,43469.42,0.08124,0.04773,,,,,,
78.2,6.517,43454.91,0.08153,0.04788,,,,,,
78.3,6.525,43436.5,0.08181,0.04802,,,,,,
78.4,6.534,43405.24,0.08209,0.04817,,,,,,
78.5,6.542,43382.61,0.08238,0.04832,,,,,,
78.6,6.55,43372.14,0.08266,0.04846,,,,,,
78.7,6.558,43366.81,0.08294,0.0486,,,,,,
78.8,6.567,43357.51,0.08323,0.04875,,,,,,
78.9,6.575,43340.36,0.08351,0.04889,,,,,,
79,6.583,43330.55,0.0838,0.04903,,,,,,
79.1,6.592,43310.9,0.08408,0.04918,,,,,,
79.2,6.6,43292.1,0.08437,0.04932,,,,,,
79.3,6.609,43266.6,0.08465,0.04946,,,,,,
79.4,6.617,43255.97,0.08493,0.0496,,,,,,
79.5,6.625,43244.21,0.08522,0.04974,,,,,,
79.6,6.634,43223.16,0.08551,0.04988,,,,,,
79.7,6.642,43205.58,0.08579,0.05001,,,,,,
79.8,6.65,43183.66,0.08607,0.05015,,,,,,
79.9,6.659,43174.54,0.08636,0.05028,,,,,,
80,6.667,43170.04,0.08664,0.05042,,,,,,
80.1,6.675,43166.59,0.08693,0.05056,,,,,,
80.2,6.683,43158.84,0.08722,0.05069,,,,,,
80.3,6.692,43144.64,0.08751,0.05083,,,,,,
80.4,6.7,43121.51,0.0878,0.05097,,,,,,
80.5,6.709,43102.96,0.08808,0.0511,,,,,,
80.6,6.717,43079.84,0.08838,0.05124,,,,,,
80.7,6.725,43049.46,0.08867,0.05137,,,,,,
80.8,6.733,43044.2,0.08895,0.0515,,,,,,
80.9,6.742,43031.52,0.08924,0.05164,,,,,,
81,6.75,43007.63,0.08954,0.05177,,,,,,
81.1,6.758,42983.4,0.08983,0.0519,,,,,,
81.2,6.767,42969.08,0.09012,0.05203,,,,,,
81.3,6.775,42957.44,0.09041,0.05216,,,,,,
81.4,6.784,42951.93,0.0907,0.05229,,,,,,
81.5,6.792,42943.96,0.09099,0.05242,,,,,,
81.6,6.8,42932.69,0.09128,0.05255,,,,,,
81.7,6.809,42917.98,0.09158,0.05267,,,,,,
81.8,6.817,42893.46,0.09187,0.0528,,,,,,
81.9,6.825,42874.07,0.09215,0.05293,,,,,,
82,6.834,42860.86,0.09245,0.05306,,,,,,
82.1,6.842,42853.37,0.09274,0.05318,,,,,,
82.2,6.85,42831.81,0.09303,0.0533,,,,,,
82.3,6.858,42802.9,0.09332,0.05343,,,,,,
82.4,6.867,42776.69,0.09361,0.05355,,,,,,
82.5,6.875,42755.24,0.09391,0.05368,,,,,,
82.6,6.884,42745.21,0.0942,0.0538,,,,,,
82.7,6.892,42739.6,0.09449,0.05392,,,,,,
82.8,6.9,42732.56,0.09478,0.05404,,,,,,
82.9,6.908,42714.82,0.09507,0.05416,,,,,,
83,6.917,42701.66,0.09536,0.05428,,,,,,
83.1,6.925,42688.82,0.09566,0.0544,,,,,,
83.2,6.934,42660.13,0.09595,0.05452,,,,,,
83.3,6.942,42647.01,0.09625,0.05464,,,,,,
83.4,6.95,42638.79,0.09654,0.05476,,,,,,
83.5,6.959,42622.48,0.09684,0.05488,,,,,,
83.6,6.967,42597.46,0.09714,0.055,,,,,,
83.7,6.975,42578.43,0.09743,0.05511,,,,,,
83.8,6.984,42563.07,0.09773,0.05523,,,,,,
83.9,6.992,42550.84,0.09803,0.05535,,,,,,
84,7,42544.27,0.09832,0.05546,,,,,,
84.1,7.009,42536.36,0.09862,0.05557,,,,,,
84.2,7.017,42510.1,0.09892,0.05569,,,,,,
84.3,7.025,42486.51,0.09921,0.0558,,,,,,
84.4,7.034,42458.44,0.09951,0.05592,,,,,,
84.5,7.042,42434.78,0.09981,0.05603,,,,,,
84.6,7.05,42430.66,0.1001,0.05614,,,,,,
84.7,7.059,42418.86,0.1004,0.05625,,,,,,
84.8,7.067,42388.62,0.1007,0.05636,,,,,,
84.9,7.075,42371.03,0.101,0.05647,,,,,,
85,7.084,42357.47,0.10129,0.05658,,,,,,
85.1,7.092,42344.04,0.10159,0.05669,,,,,,
85.2,7.1,42335.74,0.10189,0.0568,,,,,,
85.3,7.109,42329.67,0.10219,0.05691,,,,,,
85.4,7.117,42319.17,0.10249,0.05701,,,,,,
85.5,7.125,42293.45,0.10279,0.05712,,,,,,
85.6,7.133,42279.91,0.10309,0.05723,,,,,,
85.7,7.142,42254.66,0.10339,0.05734,,,,,,
85.8,7.15,42239.86,0.10369,0.05744,,,,,,
85.9,7.159,42225.29,0.104,0.05755,,,,,,
86,7.167,42188.67,0.10429,0.05765,,,,,,
86.1,7.175,42165.02,0.1046,0.05775,,,,,,
86.2,7.184,42146.77,0.1049,0.05786,,,,,,
86.3,7.192,42126.11,0.1052,0.05796,,,,,,
86.4,7.2,42123.43,0.1055,0.05806,,,,,,
86.5,7.209,42118.85,0.10581,0.05817,,,,,,
86.6,7.217,42103.1,0.10612,0.05827,,,,,,
86.7,7.225,42085.66,0.10642,0.05837,,,,,,
86.8,7.234,42068.39,0.10673,0.05847,,,,,,
86.9,7.242,42033.95,0.10702,0.05857,,,,,,
87,7.25,42025.5,0.10732,0.05867,,,,,,
87.1,7.259,42009.87,0.10763,0.05876,,,,,,
87.2,7.267,41981.13,0.10794,0.05886,,,,,,
87.3,7.275,41961.75,0.10824,0.05896,,,,,,
87.4,7.283,41948.91,0.10854,0.05905,,,,,,
87.5,7.292,41932.82,0.10884,0.05915,,,,,,
87.6,7.3,41920.69,0.10915,0.05924,,,,,,
87.7,7.308,41906.24,0.10945,0.05934,,,,,,
87.8,7.317,41891.54,0.10977,0.05943,,,,,,
87.9,7.325,41862.76,0.11007,0.05953,,,,,,
88,7.333,41838.33,0.11038,0.05962,,,,,,
88.1,7.342,41818.92,0.11069,0.05972,,,,,,
88.2,7.35,41812.33,0.111,0.05981,,,,,,
88.3,7.358,41791.01,0.1113,0.0599,,,,,,
88.4,7.367,41771.99,0.11162,0.05999,,,,,,
88.5,7.375,41748.4,0.11195,0.06008,,,,,,
88.6,7.383,41730.28,0.11226,0.06017,,,,,,
88.7,7.392,41718.45,0.11258,0.06026,,,,,,
88.8,7.4,41711.48,0.11291,0.06035,,,,,,
88.9,7.408,41697.48,0.11323,0.06044,,,,,,
89,7.417,41672.56,0.11354,0.06053,,,,,,
89.1,7.425,41647.67,0.11384,0.06062,,,,,,
89.2,7.434,41619.45,0.11415,0.06071,,,,,,
89.3,7.442,41604.7,0.11446,0.06079,,,,,,
89.4,7.45,41573.02,0.11478,0.06088,,,,,,
89.5,7.459,41552.43,0.1151,0.06096,,,,,,
89.6,7.467,41532.95,0.11542,0.06105,,,,,,
89.7,7.475,41516.39,0.11574,0.06113,,,,,,
89.8,7.483,41511.41,0.11606,0.06122,,,,,,
89.9,7.492,41501.04,0.11638,0.0613,,,,,,
90,7.5,41491.67,0.1167,0.06138,,,,,,
90.1,7.509,41469.72,0.11702,0.06146,,,,,,
90.2,7.517,41440.43,0.11734,0.06154,,,,,,
90.3,7.525,41413.31,0.11766,0.06162,,,,,,
90.4,7.533,41407.32,0.11798,0.06171,,,,,,
90.5,7.542,41377.07,0.1183,0.06178,,,,,,
90.6,7.55,41349.79,0.11862,0.06186,,,,,,
90.7,7.559,41330.34,0.11895,0.06194,,,,,,
90.8,7.567,41317.41,0.11927,0.06202,,,,,,
90.9,7.575,41295.84,0.11959,0.0621,,,,,,
91,7.584,41288.04,0.11992,0.06218,,,,,,
91.1,7.592,41265.62,0.12025,0.06225,,,,,,
91.2,7.6,41240.91,0.12057,0.06233,,,,,,
91.3,7.609,41217.76,0.1209,0.06241,,,,,,
91.4,7.617,41200.8,0.12123,0.06248,,,,,,
91.5,7.625,41183.87,0.12154,0.06256,,,,,,
91.6,7.634,41158.67,0.12187,0.06263,,,,,,
91.7,7.642,41144.19,0.1222,0.0627,,,,,,
91.8,7.65,41118.73,0.12253,0.06278,,,,,,
91.9,7.659,41103.45,0.12286,0.06285,,,,,,
92,7.667,41083.96,0.12319,0.06292,,,,,,
92.1,7.675,41071.64,0.12352,0.06299,,,,,,
92.2,7.684,41053.95,0.12384,0.06306,,,,,,
92.3,7.692,41022.91,0.12418,0.06313,,,,,,
92.4,7.7,40998.34,0.12451,0.0632,,,,,,
92.5,7.708,40982.41,0.12483,0.06327,,,,,,
92.6,7.717,40956.73,0.12516,0.06334,,,,,,
92.7,7.725,40930.38,0.12549,0.06341,,,,,,
92.8,7.734,40910.08,0.12582,0.06348,,,,,,
92.9,7.742,40901.9,0.12615,0.06354,,,,,,
93,7.75,40884.79,0.12648,0.06361,,,,,,
93.1,7.758,40875.2,0.12681,0.06367,,,,,,
93.2,7.767,40852.27,0.12714,0.06374,,,,,,
93.3,7.775,40822.12,0.12748,0.06381,,,,,,
93.4,7.784,40786.79,0.12781,0.06387,,,,,,
93.5,7.792,40778.9,0.12814,0.06394,,,,,,
93.6,7.8,40747.47,0.12847,0.064,,,,,,
93.7,7.809,40721.95,0.1288,0.06406,,,,,,
93.8,7.817,40705.04,0.12914,0.06412,,,,,,
93.9,7.825,40685.77,0.12947,0.06418,,,,,,
94,7.834,40676.13,0.12981,0.06425,,,,,,
94.1,7.842,40654.75,0.13014,0.06431,,,,,,
94.2,7.85,40632.01,0.13047,0.06437,,,,,,
94.3,7.858,40609.96,0.1308,0.06442,,,,,,
94.4,7.867,40583.44,0.13114,0.06448,,,,,,
94.5,7.875,40570.8,0.13148,0.06454,,,,,,
94.6,7.883,40530.27,0.13181,0.0646,,,,,,
94.7,7.892,40501.24,0.13215,0.06466,,,,,,
94.8,7.9,40483.18,0.13248,0.06471,,,,,,
94.9,7.908,40476.71,0.13282,0.06477,,,,,,
95,7.917,40459.73,0.13316,0.06483,,,,,,
95.1,7.925,40440.91,0.13349,0.06488,,,,,,
95.2,7.933,40415.99,0.13383,0.06494,,,,,,
95.3,7.942,40379.28,0.13417,0.06499,,,,,,
95.4,7.95,40367.75,0.1345,0.06504,,,,,,
95.5,7.959,40339.8,0.13483,0.0651,,,,,,
95.6,7.967,40309.77,0.13518,0.06515,,,,,,
95.7,7.975,40286.66,0.13551,0.0652,,,,,,
95.8,7.984,40275.57,0.13585,0.06525,,,,,,
95.9,7.992,40262.43,0.13618,0.0653,,,,,,
96,8,40240.19,0.13652,0.06535,,,,,,
96.1,8.009,40216.25,0.13686,0.0654,,,,,,
96.2,8.017,40177.89,0.1372,0.06545,,,,,,
96.3,8.025,40159.05,0.13754,0.0655,,,,,,
96.4,8.034,40142.12,0.13788,0.06555,,,,,,
96.5,8.042,40113.62,0.13822,0.0656,,,,,,
96.6,8.05,40087.06,0.13857,0.06565,,,,,,
96.7,8.059,40067.84,0.1389,0.06569,,,,,,
96.8,8.067,40048.1,0.13924,0.06574,,,,,,
96.9,8.075,40031.29,0.13958,0.06578,,,,,,
97,8.084,40009.64,0.13992,0.06583,,,,,,
97.1,8.092,39963.2,0.14026,0.06587,,,,,,
97.2,8.1,39951.15,0.1406,0.06592,,,,,,
97.3,8.109,39915.48,0.14094,0.06596,,,,,,
97.4,8.117,39889.64,0.14128,0.06601,,,,,,
97.5,8.125,39865.49,0.14162,0.06605,,,,,,
97.6,8.134,39851.77,0.14195,0.06609,,,,,,
97.7,8.142,39847.74,0.1423,0.06613,,,,,,
97.8,8.15,39825.58,0.14264,0.06617,,,,,,
97.9,8.159,39789.45,0.14298,0.06622,,,,,,
98,8.167,39760.86,0.14332,0.06626,,,,,,
98.1,8.175,39743.42,0.14366,0.0663,,,,,,
98.2,8.184,39707.88,0.14401,0.06634,,,,,,
98.3,8.192,39675.56,0.14435,0.06637,,,,,,
98.4,8.2,39652.25,0.1447,0.06641,,,,,,
98.5,8.208,39643.8,0.14503,0.06645,,,,,,
98.6,8.217,39622.32,0.14538,0.06649,,,,,,
98.7,8.225,39592.3,0.14572,0.06653,,,,,,
98.8,8.234,39554.73,0.14606,0.06656,,,,,,
98.9,8.242,39545.44,0.14641,0.0666,,,,,,
99,8.25,39517.19,0.14676,0.06664,,,,,,
99.1,8.259,39492.07,0.1471,0.06667,,,,,,
99.2,8.267,39454.21,0.14744,0.06671,,,,,,
99.3,8.275,39437.39,0.14779,0.06674,,,,,,
99.4,8.284,39427.96,0.14814,0.06678,,,,,,
99.5,8.292,39389.36,0.14848,0.06681,,,,,,
99.6,8.3,39355.22,0.14883,0.06684,,,,,,
99.7,8.309,39334.79,0.14917,0.06687,,,,,,
99.8,8.317,39310.22,0.14952,0.06691,,,,,,
99.9,8.325,39273.25,0.14986,0.06694,,,,,,
100,8.334,39252.76,0.15021,0.06697,,,,,,
100.1,8.342,39240.46,0.15056,0.067,,,,,,
100.2,8.35,39232.26,0.1509,0.06703,,,,,,
100.3,8.359,39199.33,0.15124,0.06706,,,,,,
100.4,8.367,39159.09,0.15159,0.06709,,,,,,
100.5,8.375,39129.12,0.15194,0.06712,,,,,,
100.6,8.383,39091.18,0.15228,0.06715,,,,,,
100.7,8.392,39066.98,0.15263,0.06718,,,,,,
100.8,8.4,39036.39,0.15298,0.06721,,,,,,
100.9,8.409,39024.08,0.15333,0.06723,,,,,,
101,8.417,39006.2,0.15368,0.06726,,,,,,
101.1,8.425,38981.35,0.15402,0.06729,,,,,,
101.2,8.433,38940.21,0.15437,0.06731,,,,,,
101.3,8.442,38930.19,0.15471,0.06734,,,,,,
101.4,8.45,38895.72,0.15506,0.06736,,,,,,
101.5,8.459,38859.96,0.15541,0.06739,,,,,,
101.6,8.467,38818.31,0.15577,0.06742,,,,,,
101.7,8.475,38808.38,0.15612,0.06744,,,,,,
101.8,8.483,38790.23,0.15646,0.06746,,,,,,
101.9,8.492,38753.36,0.15682,0.06748,,,,,,
102,8.5,38718.1,0.15717,0.06751,,,,,,
102.1,8.509,38697.97,0.15752,0.06753,,,,,,
102.2,8.517,38666.52,0.15787,0.06755,,,,,,
102.3,8.525,38636.21,0.15821,0.06758,,,,,,
102.4,8.534,38621.93,0.15857,0.0676,,,,,,
102.5,8.542,38606.03,0.15892,0.06762,,,,,,
102.6,8.55,38565.3,0.15927,0.06764,,,,,,
102.7,8.559,38518.22,0.15962,0.06766,,,,,,
102.8,8.567,38496.51,0.15998,0.06768,,,,,,
102.9,8.575,38455.76,0.16032,0.0677,,,,,,
103,8.584,38427.14,0.16067,0.06772,,,,,,
103.1,8.592,38415.6,0.16102,0.06774,,,,,,
103.2,8.6,38398.31,0.16138,0.06776,,,,,,
103.3,8.608,38360.91,0.16173,0.06778,,,,,,
103.4,8.617,38319.4,0.16207,0.06779,,,,,,
103.5,8.625,38310.14,0.16242,0.06781,,,,,,
103.6,8.634,38255.26,0.16277,0.06783,,,,,,
103.7,8.642,38217.51,0.16312,0.06785,,,,,,
103.8,8.65,38194.18,0.16347,0.06786,,,,,,
103.9,8.658,38186.05,0.16382,0.06788,,,,,,
104,8.667,38156.79,0.16418,0.0679,,,,,,
104.1,8.675,38123.66,0.16453,0.06791,,,,,,
104.2,8.684,38100.88,0.16489,0.06793,,,,,,
104.3,8.692,38056.36,0.16523,0.06795,,,,,,
104.4,8.7,38019.25,0.16559,0.06796,,,,,,
104.5,8.709,38003.01,0.16594,0.06797,,,,,,
104.6,8.717,37988.61,0.16629,0.06799,,,,,,
104.7,8.725,37938.52,0.16664,0.068,,,,,,
104.8,8.734,37891.28,0.167,0.06801,,,,,,
104.9,8.742,37881.92,0.16735,0.06803,,,,,,
105,8.75,37837.34,0.1677,0.06804,,,,,,
105.1,8.759,37809.18,0.16805,0.06805,,,,,,
105.2,8.767,37793.65,0.16841,0.06806,,,,,,
105.3,8.775,37765.86,0.16876,0.06808,,,,,,
105.4,8.784,37720.77,0.16911,0.06809,,,,,,
105.5,8.792,37692.17,0.16945,0.0681,,,,,,
105.6,8.8,37645.73,0.1698,0.06811,,,,,,
105.7,8.809,37614.54,0.17015,0.06812,,,,,,
105.8,8.817,37584.62,0.1705,0.06814,,,,,,
105.9,8.825,37575.8,0.17085,0.06815,,,,,,
106,8.833,37551.42,0.17121,0.06816,,,,,,
106.1,8.842,37508.76,0.17156,0.06817,,,,,,
106.2,8.85,37474.99,0.17192,0.06818,,,,,,
106.3,8.859,37435.2,0.17228,0.06818,,,,,,
106.4,8.867,37395.92,0.17263,0.0682,,,,,,
106.5,8.875,37371.99,0.17299,0.0682,,,,,,
106.6,8.883,37345.32,0.17334,0.06821,,,,,,
106.7,8.892,37310.51,0.17369,0.06822,,,,,,
106.8,8.9,37277.88,0.17405,0.06823,,,,,,
106.9,8.908,37240.15,0.1744,0.06824,,,,,,
107,8.917,37200.88,0.17476,0.06825,,,,,,
107.1,8.925,37175.75,0.17512,0.06825,,,,,,
107.2,8.933,37149.98,0.17547,0.06826,,,,,,
107.3,8.942,37117.21,0.17582,0.06827,,,,,,
107.4,8.95,37069.6,0.17619,0.06827,,,,,,
107.5,8.959,37030.21,0.17654,0.06828,,,,,,
107.6,8.967,36984.65,0.1769,0.06829,,,,,,
107.7,8.975,36973.32,0.17724,0.0683,,,,,,
107.8,8.983,36953.04,0.1776,0.0683,,,,,,
107.9,8.992,36913.53,0.17796,0.06831,,,,,,
108,9,36864.52,0.17832,0.06831,,,,,,
108.1,9.008,36828.67,0.17867,0.06832,,,,,,
108.2,9.017,36783.34,0.17903,0.06833,,,,,,
108.3,9.025,36764.72,0.17939,0.06833,,,,,,
108.4,9.034,36739.11,0.17974,0.06834,,,,,,
108.5,9.042,36694.59,0.1801,0.06834,,,,,,
108.6,9.05,36657.75,0.18045,0.06835,,,,,,
108.7,9.058,36617.9,0.18081,0.06835,,,,,,
108.8,9.067,36569.71,0.18117,0.06835,,,,,,
108.9,9.075,36551.41,0.18152,0.06836,,,,,,
109,9.084,36522.77,0.18188,0.06837,,,,,,
109.1,9.092,36484.76,0.18224,0.06837,,,,,,
109.2,9.1,36448.21,0.18261,0.06837,,,,,,
109.3,9.109,36401.4,0.18296,0.06838,,,,,,
109.4,9.117,36358.15,0.18333,0.06838,,,,,,
109.5,9.125,36341.32,0.18369,0.06838,,,,,,
109.6,9.134,36298.39,0.18405,0.06838,,,,,,
109.7,9.142,36248,0.1844,0.06839,,,,,,
109.8,9.15,36210.61,0.18476,0.06839,,,,,,
109.9,9.159,36178.79,0.18512,0.06839,,,,,,
110,9.167,36147.83,0.18548,0.0684,,,,,,
110.1,9.175,36123.29,0.18584,0.0684,,,,,,
110.2,9.183,36074.33,0.1862,0.0684,,,,,,
110.3,9.192,36028.68,0.18656,0.0684,,,,,,
110.4,9.2,35986.79,0.18692,0.06841,,,,,,
110.5,9.209,35937.38,0.18728,0.06841,,,,,,
110.6,9.217,35918.74,0.18764,0.06841,,,,,,
110.7,9.225,35889.61,0.188,0.06841,,,,,,
110.8,9.234,35837.68,0.18836,0.06841,,,,,,
110.9,9.242,35786.05,0.18871,0.06842,,,,,,
111,9.25,35750.08,0.18907,0.06842,,,,,,
111.1,9.259,35721.34,0.18943,0.06842,,,,,,
111.2,9.267,35687.04,0.18979,0.06842,,,,,,
111.3,9.275,35638.71,0.19016,0.06842,,,,,,
111.4,9.284,35606.18,0.19052,0.06842,,,,,,
111.5,9.292,35558.2,0.19088,0.06842,,,,,,
111.6,9.3,35518.68,0.19124,0.06842,,,,,,
111.7,9.309,35490.55,0.19161,0.06843,,,,,,
111.8,9.317,35434.1,0.19197,0.06843,,,,,,
111.9,9.325,35385.99,0.19232,0.06843,,,,,,
112,9.334,35342.16,0.19268,0.06843,,,,,,
112.1,9.342,35322.46,0.19305,0.06843,,,,,,
112.2,9.35,35297.26,0.19341,0.06843,,,,,,
112.3,9.358,35229.43,0.19377,0.06843,,,,,,
112.4,9.367,35195.1,0.19413,0.06843,,,,,,
112.5,9.375,35140.38,0.1945,0.06843,,,,,,
112.6,9.383,35099.38,0.19486,0.06843,,,,,,
112.7,9.392,35065.6,0.19523,0.06843,,,,,,
112.8,9.4,35019.61,0.19558,0.06843,,,,,,
112.9,9.408,34983.88,0.19595,0.06843,,,,,,
113,9.417,34926.9,0.19631,0.06843,,,,,,
113.1,9.425,34886.77,0.19667,0.06843,,,,,,
113.2,9.434,34848.8,0.19703,0.06843,,,,,,
113.3,9.442,34798.25,0.19739,0.06843,,,,,,
113.4,9.45,34756.14,0.19776,0.06843,,,,,,
113.5,9.459,34713.37,0.19812,0.06843,,,,,,
113.6,9.467,34686.65,0.19849,0.06843,,,,,,
113.7,9.475,34636.48,0.19886,0.06843,,,,,,
113.8,9.484,34577.11,0.19923,0.06843,,,,,,
113.9,9.492,34512.73,0.19959,0.06843,,,,,,
114,9.5,34486.61,0.19995,0.06843,,,,,,
114.1,9.508,34453.86,0.20032,0.06843,,,,,,
114.2,9.517,34395.17,0.20068,0.06843,,,,,,
114.3,9.525,34350.59,0.20105,0.06843,,,,,,
114.4,9.534,34283.51,0.20142,0.06843,,,,,,
114.5,9.542,34249.81,0.2018,0.06843,,,,,,
114.6,9.55,34195.8,0.20217,0.06843,,,,,,
114.7,9.558,34141.58,0.20254,0.06843,,,,,,
114.8,9.567,34083.78,0.20292,0.06843,,,,,,
114.9,9.575,34042.32,0.2033,0.06843,,,,,,
115,9.583,33959.37,0.20367,0.06843,,,,,,
115.1,9.592,33895.71,0.20405,0.06843,,,,,,
115.2,9.6,33850.54,0.20443,0.06842,,,,,,
115.3,9.609,33753.33,0.20484,0.06842,,,,,,
115.4,9.617,33594.2,0.2053,0.06842,,,,,,
115.5,9.625,33237.83,0.20592,0.06841,,,,,,
115.56,9.631,17640.55,0.19867,0.07143,,,,,,