File: TensionLab/data/experimentalData/1018 Steel Sample 2.csv
Specimen label,"1018_2"
End date,"Monday, January 24, 2022"
Thickness,"6.30000",mm
Width,"12.40000",mm
Final length,"57.11000",mm
Axial gauge length,"25.40000",mm
Transverse gauge length,"12.38000",mm
Crosshead Rate,"5.00",mm/min

Time,Extension,Load,Axial Strain,Transverse Strain
(s),(mm),(N),(mm/mm),(mm/mm)
"0.000","0.000","-0.02","0.00000","0.00000"
"0.200","0.014","194.42","0.00001","-0.00001"
"0.400","0.034","469.24","0.00000","-0.00001"
"0.600","0.050","624.12","-0.00002","0.00001"
"0.800","0.067","748.53","-0.00003","0.00002"
"1.000","0.084","865.44","-0.00003","0.00003"
"1.200","0.100","1024.36","-0.00002","0.00003"
"1.400","0.117","1162.07","-0.00001","0.00004"
"1.600","0.134","1315.22","-0.00001","0.00004"
"1.800","0.150","1485.22","0.00000","0.00005"
"2.000","0.167","1673.72","0.00001","0.00005"
"2.200","0.184","1845.37","0.00002","0.00006"
"2.400","0.200","1989.46","0.00002","0.00006"
"2.600","0.217","2103.22","0.00003","0.00006"
"2.800","0.234","2266.61","0.00003","0.00007"
"3.000","0.250","2381.01","0.00004","0.00007"
"3.200","0.267","2507.44","0.00004","0.00007"
"3.400","0.284","2667.17","0.00005","0.00008"
"3.600","0.300","2792.24","0.00006","0.00008"
"3.800","0.317","2933.88","0.00007","0.00008"
"4.000","0.334","3092.15","0.00007","0.00007"
"4.200","0.350","3241.28","0.00008","0.00007"
"4.400","0.367","3384.44","0.00009","0.00008"
"4.600","0.384","3535.66","0.00009","0.00008"
"4.800","0.400","3719.98","0.00010","0.00007"
"5.000","0.417","3871.02","0.00011","0.00007"
"5.200","0.433","4052.32","0.00011","0.00007"
"5.400","0.450","4205.26","0.00012","0.00007"
"5.600","0.467","4377.75","0.00012","0.00007"
"5.800","0.484","4555.90","0.00013","0.00007"
"6.000","0.500","4736.49","0.00013","0.00007"
"6.200","0.517","4904.30","0.00014","0.00007"
"6.400","0.533","5066.98","0.00015","0.00007"
"6.600","0.550","5222.71","0.00015","0.00007"
"6.800","0.567","5389.08","0.00016","0.00007"
"7.000","0.583","5570.76","0.00017","0.00008"
"7.200","0.600","5746.92","0.00018","0.00009"
"7.400","0.617","5934.76","0.00019","0.00009"
"7.600","0.633","6094.70","0.00019","0.00009"
"7.800","0.650","6301.82","0.00021","0.00010"
"8.000","0.667","6480.96","0.00021","0.00011"
"8.200","0.684","6656.04","0.00023","0.00011"
"8.400","0.700","6872.08","0.00025","0.00011"
"8.600","0.717","7062.56","0.00025","0.00012"
"8.800","0.733","7257.57","0.00027","0.00012"
"9.000","0.750","7467.94","0.00028","0.00013"
"9.200","0.767","7681.41","0.00029","0.00013"
"9.400","0.783","7875.18","0.00031","0.00014"
"9.600","0.800","8087.84","0.00032","0.00014"
"9.800","0.817","8308.87","0.00034","0.00014"
"10.000","0.834","8526.13","0.00035","0.00015"
"10.200","0.850","8727.88","0.00036","0.00015"
"10.400","0.867","8948.12","0.00037","0.00015"
"10.600","0.883","9171.92","0.00039","0.00016"
"10.800","0.900","9400.32","0.00041","0.00017"
"11.000","0.917","9620.80","0.00042","0.00017"
"11.200","0.933","9852.31","0.00044","0.00018"
"11.400","0.950","10070.83","0.00045","0.00018"
"11.600","0.967","10299.54","0.00047","0.00018"
"11.800","0.983","10541.78","0.00048","0.00019"
"12.000","1.000","10769.76","0.00050","0.00019"
"12.200","1.017","10982.17","0.00051","0.00020"
"12.400","1.033","11207.20","0.00053","0.00020"
"12.600","1.050","11447.59","0.00054","0.00021"
"12.800","1.067","11698.85","0.00056","0.00022"
"13.000","1.084","11947.44","0.00058","0.00022"
"13.200","1.100","12179.25","0.00059","0.00022"
"13.400","1.117","12398.84","0.00061","0.00023"
"13.600","1.134","12643.23","0.00062","0.00023"
"13.800","1.150","12896.66","0.00064","0.00024"
"14.000","1.167","13132.60","0.00066","0.00025"
"14.200","1.184","13395.28","0.00068","0.00025"
"14.400","1.200","13640.96","0.00070","0.00026"
"14.600","1.217","13889.67","0.00071","0.00026"
"14.800","1.233","14161.75","0.00073","0.00027"
"15.000","1.250","14432.30","0.00075","0.00028"
"15.200","1.267","14681.13","0.00077","0.00029"
"15.400","1.284","14947.69","0.00079","0.00029"
"15.600","1.300","15195.27","0.00081","0.00030"
"15.800","1.317","15476.42","0.00083","0.00031"
"16.000","1.333","15719.57","0.00085","0.00032"
"16.200","1.350","15988.29","0.00087","0.00033"
"16.400","1.367","16265.42","0.00089","0.00034"
"16.600","1.384","16529.97","0.00091","0.00034"
"16.800","1.400","16783.55","0.00093","0.00035"
"17.000","1.417","17070.11","0.00094","0.00035"
"17.200","1.433","17336.95","0.00096","0.00036"
"17.400","1.450","17593.95","0.00098","0.00037"
"17.600","1.467","17867.36","0.00100","0.00038"
"17.800","1.483","18153.84","0.00102","0.00038"
"18.000","1.500","18415.84","0.00104","0.00039"
"18.200","1.517","18698.45","0.00106","0.00040"
"18.400","1.533","18987.65","0.00108","0.00041"
"18.600","1.550","19248.59","0.00110","0.00042"
"18.800","1.567","19534.16","0.00112","0.00042"
"19.000","1.583","19821.16","0.00114","0.00044"
"19.200","1.600","20084.69","0.00117","0.00045"
"19.400","1.617","20368.59","0.00119","0.00045"
"19.600","1.634","20650.15","0.00121","0.00046"
"19.800","1.650","20910.18","0.00123","0.00047"
"20.000","1.667","21210.26","0.00125","0.00048"
"20.200","1.684","21491.26","0.00128","0.00049"
"20.400","1.700","21763.74","0.00130","0.00050"
"20.600","1.717","22069.48","0.00132","0.00051"
"20.800","1.733","22334.12","0.00135","0.00052"
"21.000","1.750","22617.09","0.00136","0.00053"
"21.200","1.767","22923.41","0.00139","0.00054"
"21.400","1.783","23192.99","0.00141","0.00055"
"21.600","1.800","23491.83","0.00144","0.00056"
"21.800","1.817","23770.50","0.00146","0.00057"
"22.000","1.833","24055.04","0.00149","0.00058"
"22.200","1.850","24352.50","0.00151","0.00059"
"22.400","1.867","24615.97","0.00153","0.00060"
"22.600","1.883","24913.71","0.00155","0.00061"
"22.800","1.900","25197.21","0.00158","0.00062"
"23.000","1.917","25472.04","0.00160","0.00064"
"23.200","1.933","25776.95","0.00163","0.00065"
"23.400","1.950","26044.54","0.00165","0.00066"
"23.600","1.967","26338.87","0.00168","0.00067"
"23.800","1.984","26634.12","0.00171","0.00068"
"24.000","2.000","26920.73","0.00173","0.00069"
"24.200","2.017","27214.23","0.00176","0.00071"
"24.400","2.034","27493.62","0.00179","0.00072"
"24.600","2.050","27794.38","0.00182","0.00073"
"24.800","2.067","28080.55","0.00185","0.00075"
"25.000","2.084","28358.16","0.00187","0.00076"
"25.200","2.100","28660.89","0.00190","0.00078"
"25.400","2.117","28933.82","0.00193","0.00079"
"25.600","2.133","29223.46","0.00196","0.00081"
"25.800","2.150","29519.75","0.00198","0.00082"
"26.000","2.167","29797.11","0.00201","0.00084"
"26.200","2.184","30088.18","0.00204","0.00085"
"26.400","2.200","30363.20","0.00208","0.00087"
"26.600","2.217","30655.08","0.00211","0.00089"
"26.800","2.233","30951.09","0.00213","0.00091"
"27.000","2.250","31210.09","0.00217","0.00092"
"27.200","2.267","31503.43","0.00220","0.00094"
"27.400","2.283","31787.63","0.00223","0.00096"
"27.600","2.300","32057.96","0.00227","0.00098"
"27.800","2.317","32344.39","0.00230","0.00100"
"28.000","2.333","32622.62","0.00233","0.00102"
"28.200","2.350","32892.15","0.00237","0.00104"
"28.400","2.367","33167.06","0.00240","0.00106"
"28.600","2.383","33447.24","0.00244","0.00108"
"28.800","2.400","33707.09","0.00247","0.00110"
"29.000","2.417","33974.90","0.00251","0.00112"
"29.200","2.433","34259.81","0.00254","0.00115"
"29.400","2.450","34512.70","0.00258","0.00117"
"29.600","2.467","34782.28","0.00262","0.00120"
"29.800","2.484","35063.15","0.00266","0.00122"
"30.000","2.500","35318.88","0.00270","0.00124"
"30.200","2.517","35572.20","0.00274","0.00127"
"30.400","2.534","35830.67","0.00278","0.00129"
"30.600","2.550","36085.19","0.00282","0.00132"
"30.800","2.567","36342.34","0.00286","0.00134"
"31.000","2.584","36581.00","0.00291","0.00137"
"31.200","2.600","36836.31","0.00295","0.00140"
"31.400","2.617","37086.55","0.00300","0.00143"
"31.600","2.633","37328.37","0.00304","0.00146"
"31.800","2.650","37577.79","0.00309","0.00149"
"32.000","2.667","37808.15","0.00314","0.00152"
"32.200","2.683","38043.65","0.00319","0.00156"
"32.400","2.700","38274.05","0.00325","0.00159"
"32.600","2.717","38503.08","0.00330","0.00162"
"32.800","2.733","38725.89","0.00335","0.00166"
"33.000","2.750","38969.66","0.00340","0.00170"
"33.200","2.767","39197.54","0.00345","0.00174"
"33.400","2.783","39400.89","0.00351","0.00178"
"33.600","2.800","39616.99","0.00357","0.00182"
"33.800","2.817","39837.47","0.00363","0.00186"
"34.000","2.833","40036.96","0.00369","0.00190"
"34.200","2.850","40242.74","0.00375","0.00195"
"34.400","2.867","40448.94","0.00382","0.00199"
"34.600","2.884","40643.06","0.00389","0.00204"
"34.800","2.900","40832.25","0.00396","0.00210"
"35.000","2.917","41015.88","0.00403","0.00215"
"35.200","2.933","41200.65","0.00411","0.00220"
"35.400","2.950","41377.41","0.00419","0.00226"
"35.600","2.967","41534.01","0.00427","0.00232"
"35.800","2.984","41721.38","0.00435","0.00238"
"36.000","3.000","41896.64","0.00443","0.00244"
"36.200","3.017","42061.78","0.00453","0.00251"
"36.400","3.033","42218.46","0.00462","0.00258"
"36.600","3.050","42356.62","0.00471","0.00265"
"36.800","3.067","42532.23","0.00481","0.00272"
"37.000","3.084","42663.61","0.00491","0.00280"
"37.200","3.100","42794.58","0.00501","0.00288"
"37.400","3.117","42944.52","0.00513","0.00296"
"37.600","3.134","43065.02","0.00524","0.00304"
"37.800","3.150","43181.29","0.00536","0.00313"
"38.000","3.167","43316.44","0.00548","0.00322"
"38.200","3.183","43432.85","0.00560","0.00331"
"38.400","3.200","43550.39","0.00573","0.00341"
"38.600","3.217","43650.15","0.00587","0.00351"
"38.800","3.233","43768.71","0.00600","0.00361"
"39.000","3.250","43848.37","0.00615","0.00371"
"39.200","3.267","43957.90","0.00630","0.00381"
"39.400","3.283","44030.28","0.00644","0.00392"
"39.600","3.300","44127.09","0.00660","0.00403"
"39.800","3.317","44200.48","0.00676","0.00414"
"40.000","3.334","44285.95","0.00692","0.00426"
"40.200","3.350","44364.56","0.00709","0.00437"
"40.400","3.367","44411.99","0.00727","0.00449"
"40.600","3.383","44503.23","0.00744","0.00461"
"40.800","3.400","44572.29","0.00762","0.00474"
"41.000","3.417","44610.70","0.00781","0.00486"
"41.200","3.434","44680.57","0.00800","0.00499"
"41.400","3.450","44728.84","0.00819","0.00512"
"41.600","3.467","44804.71","0.00839","0.00524"
"41.800","3.484","44829.90","0.00859","0.00538"
"42.000","3.500","44879.95","0.00880","0.00552"
"42.200","3.517","44921.09","0.00901","0.00565"
"42.400","3.534","44985.22","0.00922","0.00579"
"42.600","3.550","45009.35","0.00943","0.00593"
"42.800","3.567","45042.28","0.00965","0.00607"
"43.000","3.583","45089.14","0.00987","0.00621"
"43.200","3.600","45127.77","0.01010","0.00635"
"43.400","3.617","45164.48","0.01033","0.00650"
"43.600","3.634","45192.76","0.01055","0.00664"
"43.800","3.650","45219.78","0.01079","0.00679"
"44.000","3.667","45236.31","0.01102","0.00693"
"44.200","3.684","45263.61","0.01126","0.00708"
"44.400","3.700","45293.55","0.01150","0.00723"
"44.600","3.717","45325.21","0.01174","0.00738"
"44.800","3.734","45347.87","0.01199","0.00753"
"45.000","3.750","45378.80","0.01224","0.00768"
"45.200","3.767","45403.69","0.01250","0.00783"
"45.400","3.784","45422.51","0.01275","0.00799"
"45.600","3.800","45427.80","0.01300","0.00814"
"45.800","3.817","45438.33","0.01326","0.00829"
"46.000","3.833","45445.53","0.01352","0.00844"
"46.200","3.850","45456.01","0.01378","0.00860"
"46.400","3.867","45469.01","0.01403","0.00875"
"46.600","3.884","45490.68","0.01430","0.00891"
"46.800","3.900","45510.27","0.01456","0.00906"
"47.000","3.917","45527.29","0.01483","0.00921"
"47.200","3.933","45535.38","0.01509","0.00937"
"47.400","3.950","45542.98","0.01537","0.00953"
"47.600","3.967","45558.76","0.01564","0.00969"
"47.800","3.984","45578.38","0.01591","0.00986"
"48.000","4.000","45584.86","0.01619","0.01002"
"48.200","4.017","45587.78","0.01646","0.01018"
"48.400","4.034","45591.72","0.01673","0.01034"
"48.600","4.050","45610.88","0.01701","0.01051"
"48.800","4.067","45618.39","0.01729","0.01067"
"49.000","4.083","45622.14","0.01758","0.01084"
"49.200","4.100","45629.54","0.01786","0.01100"
"49.400","4.117","45629.00","0.01815","0.01116"
"49.600","4.134","45633.48","0.01843","0.01132"
"49.800","4.150","45632.53","0.01872","0.01149"
"50.000","4.167","45639.11","0.01902","0.01165"
"50.200","4.184","45638.61","0.01932","0.01182"
"50.400","4.200","45641.84","0.01961","0.01199"
"50.600","4.217","45638.89","0.01990","0.01215"
"50.800","4.234","45642.40","0.02020","0.01232"
"51.000","4.250","45641.21","0.02050","0.01249"
"51.200","4.267","45643.44","0.02079","0.01266"
"51.400","4.284","45643.05","0.02109","0.01283"
"51.600","4.300","45642.76","0.02140","0.01300"
"51.800","4.317","45642.30","0.02169","0.01317"
"52.000","4.334","45641.98","0.02200","0.01334"
"52.200","4.350","45642.64","0.02231","0.01351"
"52.400","4.367","45641.89","0.02263","0.01368"
"52.600","4.384","45639.25","0.02294","0.01385"
"52.800","4.400","45637.23","0.02325","0.01402"
"53.000","4.417","45637.71","0.02357","0.01420"
"53.200","4.433","45631.80","0.02389","0.01437"
"53.400","4.450","45632.08","0.02421","0.01454"
"53.600","4.467","45628.91","0.02453","0.01472"
"53.800","4.483","45625.90","0.02484","0.01489"
"54.000","4.500","45622.68","0.02516","0.01507"
"54.200","4.517","45612.65","0.02549","0.01525"
"54.400","4.533","45613.33","0.02581","0.01542"
"54.600","4.550","45607.98","0.02614","0.01560"
"54.800","4.567","45597.14","0.02648","0.01578"
"55.000","4.584","45594.92","0.02681","0.01597"
"55.200","4.600","45590.43","0.02715","0.01615"
"55.400","4.617","45584.15","0.02748","0.01633"
"55.600","4.634","45580.03","0.02783","0.01652"
"55.800","4.650","45560.12","0.02817","0.01670"
"56.000","4.667","45548.06","0.02851","0.01689"
"56.200","4.683","45540.67","0.02885","0.01708"
"56.400","4.700","45536.75","0.02920","0.01727"
"56.600","4.717","45531.84","0.02955","0.01745"
"56.800","4.733","45526.64","0.02990","0.01764"
"57.000","4.750","45516.25","0.03025","0.01783"
"57.200","4.767","45511.50","0.03060","0.01803"
"57.400","4.784","45495.12","0.03096","0.01822"
"57.600","4.800","45480.29","0.03132","0.01842"
"57.800","4.817","45475.07","0.03169","0.01862"
"58.000","4.834","45461.16","0.03204","0.01882"
"58.200","4.850","45450.81","0.03241","0.01902"
"58.400","4.867","45446.95","0.03278","0.01922"
"58.600","4.883","45439.66","0.03315","0.01942"
"58.800","4.900","45440.27","0.03353","0.01962"
"59.000","4.917","45430.36","0.03393","0.01983"
"59.200","4.934","45427.00","0.03432","0.02004"
"59.400","4.950","45425.57","0.03472","0.02025"
"59.600","4.967","45422.22","0.03512","0.02046"
"59.800","4.984","45405.37","0.03552","0.02067"
"60.000","5.000","45395.86","0.03593","0.02088"
"60.200","5.017","45378.66","0.03634","0.02110"
"60.400","5.034","45365.60","0.03675","0.02132"
"60.600","5.050","45346.89","0.03716","0.02154"
"60.800","5.067","45337.61","0.03758","0.02176"
"61.000","5.084","45331.11","0.03800","0.02198"
"61.200","5.100","45306.89","0.03841","0.02221"
"61.400","5.117","45287.90","0.03884","0.02243"
"61.600","5.134","45281.78","0.03926","0.02266"
"61.800","5.150","45270.82","0.03968","0.02289"
"62.000","5.167","45256.17","0.04012","0.02312"
"62.200","5.184","45243.45","0.04055","0.02336"
"62.400","5.200","45224.51","0.04098","0.02360"
"62.600","5.217","45221.97","0.04141","0.02383"
"62.800","5.233","45212.96","0.04186","0.02408"
"63.000","5.250","45204.91","0.04230","0.02432"
"63.200","5.267","45194.95","0.04275","0.02458"
"63.400","5.283","45174.29","0.04320","0.02483"
"63.600","5.300","45155.99","0.04364","0.02508"
"63.800","5.317","45141.54","0.04410","0.02533"
"64.000","5.334","45130.51","0.04455","0.02559"
"64.200","5.350","45120.94","0.04501","0.02585"
"64.400","5.367","45106.92","0.04547","0.02612"
"64.600","5.383","45072.96","0.04594","0.02638"
"64.800","5.400","45063.65","0.04640","0.02665"
"65.000","5.417","45037.80","0.04687","0.02692"
"65.200","5.433","45027.25","0.04734","0.02720"
"65.400","5.450","45011.79","0.04782","0.02748"
"65.600","5.467","45003.41","0.04830","0.02776"
"65.800","5.484","44995.96","0.04878","0.02805"
"66.000","5.500","44981.99","0.04926","0.02834"
"66.200","5.517","44952.51","0.04971","0.02863"
"66.400","5.534","44921.78","0.05020","0.02892"
"66.600","5.550","44911.51","0.05068","0.02922"
"66.800","5.567","44890.34","0.05117","0.02951"
"67.000","5.584","44864.59","0.05166","0.02982"
"67.200","5.600","44848.41","0.05216","0.03012"
"67.400","5.617","44836.98","0.05265","0.03042"
"67.600","5.634","44816.00","0.05315","0.03073"
"67.800","5.650","44810.00","0.05364","0.03104"
"68.000","5.667","44797.15","0.05415","0.03136"
"68.200","5.684","44773.77","0.05464","0.03167"
"68.400","5.700","44734.96","0.05515","0.03199"
"68.600","5.717","44710.40","0.05566","0.03231"
"68.800","5.734","44697.30","0.05616","0.03264"
"69.000","5.750","44675.67","0.05667","0.03295"
"69.200","5.767","44647.07","0.05718","0.03328"
"69.400","5.783","44617.72","0.05768","0.03360"
"69.600","5.800","44603.77","0.05821","0.03393"
"69.800","5.817","44589.86","0.05871","0.03426"
"70.000","5.833","44571.34","0.05923","0.03459"
"70.200","5.850","44547.07","0.05975","0.03492"
"70.400","5.867","44516.78","0.06027","0.03526"
"70.600","5.884","44502.08","0.06079","0.03559"
"70.800","5.900","44455.98","0.06133","0.03594"
"71.000","5.917","44424.47","0.06184","0.03627"
"71.200","5.934","44406.00","0.06237","0.03661"
"71.400","5.950","44390.34","0.06289","0.03695"
"71.600","5.967","44383.42","0.06343","0.03729"
"71.800","5.984","44357.11","0.06396","0.03763"
"72.000","6.000","44316.07","0.06449","0.03797"
"72.200","6.017","44289.05","0.06502","0.03831"
"72.400","6.034","44264.46","0.06555","0.03865"
"72.600","6.050","44229.35","0.06609","0.03899"
"72.800","6.067","44206.65","0.06663","0.03932"
"73.000","6.083","44184.11","0.06717","0.03966"
"73.200","6.100","44164.57","0.06771","0.03999"
"73.400","6.117","44138.19","0.06825","0.04033"
"73.600","6.134","44093.64","0.06880","0.04067"
"73.800","6.150","44081.35","0.06935","0.04100"
"74.000","6.167","44049.92","0.06990","0.04134"
"74.200","6.183","44005.50","0.07044","0.04167"
"74.400","6.200","43993.02","0.07099","0.04199"
"74.600","6.217","43970.21","0.07153","0.04232"
"74.800","6.233","43948.30","0.07208","0.04265"
"75.000","6.250","43899.77","0.07263","0.04297"
"75.200","6.267","43878.58","0.07318","0.04329"
"75.400","6.284","43843.28","0.07373","0.04361"
"75.600","6.300","43809.86","0.07427","0.04393"
"75.800","6.317","43783.31","0.07484","0.04425"
"76.000","6.334","43777.00","0.07539","0.04456"
"76.200","6.350","43757.46","0.07595","0.04488"
"76.400","6.367","43705.43","0.07650","0.04519"
"76.600","6.384","43671.02","0.07705","0.04549"
"76.800","6.400","43645.49","0.07761","0.04580"
"77.000","6.417","43604.50","0.07816","0.04610"
"77.200","6.433","43577.84","0.07871","0.04640"
"77.400","6.450","43564.26","0.07928","0.04670"
"77.600","6.467","43540.88","0.07983","0.04700"
"77.800","6.484","43503.97","0.08040","0.04730"
"78.000","6.500","43476.06","0.08096","0.04759"
"78.200","6.517","43454.91","0.08153","0.04788"
"78.400","6.534","43405.24","0.08209","0.04817"
"78.600","6.550","43372.14","0.08266","0.04846"
"78.800","6.567","43357.51","0.08323","0.04875"
"79.000","6.583","43330.55","0.08380","0.04903"
"79.200","6.600","43292.10","0.08437","0.04932"
"79.400","6.617","43255.97","0.08493","0.04960"
"79.600","6.634","43223.16","0.08551","0.04988"
"79.800","6.650","43183.66","0.08607","0.05015"
"80.000","6.667","43170.04","0.08664","0.05042"
"80.200","6.683","43158.84","0.08722","0.05069"
"80.400","6.700","43121.51","0.08780","0.05097"
"80.600","6.717","43079.84","0.08838","0.05124"
"80.800","6.733","43044.20","0.08895","0.05150"
"81.000","6.750","43007.63","0.08954","0.05177"
"81.200","6.767","42969.08","0.09012","0.05203"
"81.400","6.784","42951.93","0.09070","0.05229"
"81.600","6.800","42932.69","0.09128","0.05255"
"81.800","6.817","42893.46","0.09187","0.05280"
"82.000","6.834","42860.86","0.09245","0.05306"
"82.200","6.850","42831.81","0.09303","0.05330"
"82.400","6.867","42776.69","0.09361","0.05355"
"82.600","6.884","42745.21","0.09420","0.05380"
"82.800","6.900","42732.56","0.09478","0.05404"
"83.000","6.917","42701.66","0.09536","0.05428"
"83.200","6.934","42660.13","0.09595","0.05452"
"83.400","6.950","42638.79","0.09654","0.05476"
"83.600","6.967","42597.46","0.09714","0.05500"
"83.800","6.984","42563.07","0.09773","0.05523"
"84.000","7.000","42544.27","0.09832","0.05546"
"84.200","7.017","42510.10","0.09892","0.05569"
"84.400","7.034","42458.44","0.09951","0.05592"
"84.600","7.050","42430.66","0.10010","0.05614"
"84.800","7.067","42388.62","0.10070","0.05636"
"85.000","7.084","42357.47","0.10129","0.05658"
"85.200","7.100","42335.74","0.10189","0.05680"
"85.400","7.117","42319.17","0.10249","0.05701"
"85.600","7.133","42279.91","0.10309","0.05723"
"85.800","7.150","42239.86","0.10369","0.05744"
"86.000","7.167","42188.67","0.10429","0.05765"
"86.200","7.184","42146.77","0.10490","0.05786"
"86.400","7.200","42123.43","0.10550","0.05806"
"86.600","7.217","42103.10","0.10612","0.05827"
"86.800","7.234","42068.39","0.10673","0.05847"
"87.000","7.250","42025.50","0.10732","0.05867"
"87.200","7.267","41981.13","0.10794","0.05886"
"87.400","7.283","41948.91","0.10854","0.05905"
"87.600","7.300","41920.69","0.10915","0.05924"
"87.800","7.317","41891.54","0.10977","0.05943"
"88.000","7.333","41838.33","0.11038","0.05962"
"88.200","7.350","41812.33","0.11100","0.05981"
"88.400","7.367","41771.99","0.11162","0.05999"
"88.600","7.383","41730.28","0.11226","0.06017"
"88.800","7.400","41711.48","0.11291","0.06035"
"89.000","7.417","41672.56","0.11354","0.06053"
"89.200","7.434","41619.45","0.11415","0.06071"
"89.400","7.450","41573.02","0.11478","0.06088"
"89.600","7.467","41532.95","0.11542","0.06105"
"89.800","7.483","41511.41","0.11606","0.06122"
"90.000","7.500","41491.67","0.11670","0.06138"
"90.200","7.517","41440.43","0.11734","0.06154"
"90.400","7.533","41407.32","0.11798","0.06171"
"90.600","7.550","41349.79","0.11862","0.06186"
"90.800","7.567","41317.41","0.11927","0.06202"
"91.000","7.584","41288.04","0.11992","0.06218"
"91.200","7.600","41240.91","0.12057","0.06233"
"91.400","7.617","41200.80","0.12123","0.06248"
"91.600","7.634","41158.67","0.12187","0.06263"
"91.800","7.650","41118.73","0.12253","0.06278"
"92.000","7.667","41083.96","0.12319","0.06292"
"92.200","7.684","41053.95","0.12384","0.06306"
"92.400","7.700","40998.34","0.12451","0.06320"
"92.600","7.717","40956.73","0.12516","0.06334"
"92.800","7.734","40910.08","0.12582","0.06348"
"93.000","7.750","40884.79","0.12648","0.06361"
"93.200","7.767","40852.27","0.12714","0.06374"
"93.400","7.784","40786.79","0.12781","0.06387"
"93.600","7.800","40747.47","0.12847","0.06400"
"93.800","7.817","40705.04","0.12914","0.06412"
"94.000","7.834","40676.13","0.12981","0.06425"
"94.200","7.850","40632.01","0.13047","0.06437"
"94.400","7.867","40583.44","0.13114","0.06448"
"94.600","7.883","40530.27","0.13181","0.06460"
"94.800","7.900","40483.18","0.13248","0.06471"
"95.000","7.917","40459.73","0.13316","0.06483"
"95.200","7.933","40415.99","0.13383","0.06494"
"95.400","7.950","40367.75","0.13450","0.06504"
"95.600","7.967","40309.77","0.13518","0.06515"
"95.800","7.984","40275.57","0.13585","0.06525"
"96.000","8.000","40240.19","0.13652","0.06535"
"96.200","8.017","40177.89","0.13720","0.06545"
"96.400","8.034","40142.12","0.13788","0.06555"
"96.600","8.050","40087.06","0.13857","0.06565"
"96.800","8.067","40048.10","0.13924","0.06574"
"97.000","8.084","40009.64","0.13992","0.06583"
"97.200","8.100","39951.15","0.14060","0.06592"
"97.400","8.117","39889.64","0.14128","0.06601"
"97.600","8.134","39851.77","0.14195","0.06609"
"97.800","8.150","39825.58","0.14264","0.06617"
"98.000","8.167","39760.86","0.14332","0.06626"
"98.200","8.184","39707.88","0.14401","0.06634"
"98.400","8.200","39652.25","0.14470","0.06641"
"98.600","8.217","39622.32","0.14538","0.06649"
"98.800","8.234","39554.73","0.14606","0.06656"
"99.000","8.250","39517.19","0.14676","0.06664"
"99.200","8.267","39454.21","0.14744","0.06671"
"99.400","8.284","39427.96","0.14814","0.06678"
"99.600","8.300","39355.22","0.14883","0.06684"
"99.800","8.317","39310.22","0.14952","0.06691"
"100.000","8.334","39252.76","0.15021","0.06697"
"100.200","8.350","39232.26","0.15090","0.06703"
"100.400","8.367","39159.09","0.15159","0.06709"
"100.600","8.383","39091.18","0.15228","0.06715"
"100.800","8.400","39036.39","0.15298","0.06721"
"101.000","8.417","39006.20","0.15368","0.06726"
"101.200","8.433","38940.21","0.15437","0.06731"
"101.400","8.450","38895.72","0.15506","0.06736"
"101.600","8.467","38818.31","0.15577","0.06742"
"101.800","8.483","38790.23","0.15646","0.06746"
"102.000","8.500","38718.10","0.15717","0.06751"
"102.200","8.517","38666.52","0.15787","0.06755"
"102.400","8.534","38621.93","0.15857","0.06760"
"102.600","8.550","38565.30","0.15927","0.06764"
"102.800","8.567","38496.51","0.15998","0.06768"
"103.000","8.584","38427.14","0.16067","0.06772"
"103.200","8.600","38398.31","0.16138","0.06776"
"103.400","8.617","38319.40","0.16207","0.06779"
"103.600","8.634","38255.26","0.16277","0.06783"
"103.800","8.650","38194.18","0.16347","0.06786"
"104.000","8.667","38156.79","0.16418","0.06790"
"104.200","8.684","38100.88","0.16489","0.06793"
"104.400","8.700","38019.25","0.16559","0.06796"
"104.600","8.717","37988.61","0.16629","0.06799"
"104.800","8.734","37891.28","0.16700","0.06801"
"105.000","8.750","37837.34","0.16770","0.06804"
"105.200","8.767","37793.65","0.16841","0.06806"
"105.400","8.784","37720.77","0.16911","0.06809"
"105.600","8.800","37645.73","0.16980","0.06811"
"105.800","8.817","37584.62","0.17050","0.06814"
"106.000","8.833","37551.42","0.17121","0.06816"
"106.200","8.850","37474.99","0.17192","0.06818"
"106.400","8.867","37395.92","0.17263","0.06820"
"106.600","8.883","37345.32","0.17334","0.06821"
"106.800","8.900","37277.88","0.17405","0.06823"
"107.000","8.917","37200.88","0.17476","0.06825"
"107.200","8.933","37149.98","0.17547","0.06826"
"107.400","8.950","37069.60","0.17619","0.06827"
"107.600","8.967","36984.65","0.17690","0.06829"
"107.800","8.983","36953.04","0.17760","0.06830"
"108.000","9.000","36864.52","0.17832","0.06831"
"108.200","9.017","36783.34","0.17903","0.06833"
"108.400","9.034","36739.11","0.17974","0.06834"
"108.600","9.050","36657.75","0.18045","0.06835"
"108.800","9.067","36569.71","0.18117","0.06835"
"109.000","9.084","36522.77","0.18188","0.06837"
"109.200","9.100","36448.21","0.18261","0.06837"
"109.400","9.117","36358.15","0.18333","0.06838"
"109.600","9.134","36298.39","0.18405","0.06838"
"109.800","9.150","36210.61","0.18476","0.06839"
"110.000","9.167","36147.83","0.18548","0.06840"
"110.200","9.183","36074.33","0.18620","0.06840"
"110.400","9.200","35986.79","0.18692","0.06841"
"110.600","9.217","35918.74","0.18764","0.06841"
"110.800","9.234","35837.68","0.18836","0.06841"
"111.000","9.250","35750.08","0.18907","0.06842"
"111.200","9.267","35687.04","0.18979","0.06842"
"111.400","9.284","35606.18","0.19052","0.06842"
"111.600","9.300","35518.68","0.19124","0.06842"
"111.800","9.317","35434.10","0.19197","0.06843"
"112.000","9.334","35342.16","0.19268","0.06843"
"112.200","9.350","35297.26","0.19341","0.06843"
"112.400","9.367","35195.10","0.19413","0.06843"
"112.600","9.383","35099.38","0.19486","0.06843"
"112.800","9.400","35019.61","0.19558","0.06843"
"113.000","9.417","34926.90","0.19631","0.06843"
"113.200","9.434","34848.80","0.19703","0.06843"
"113.400","9.450","34756.14","0.19776","0.06843"
"113.600","9.467","34686.65","0.19849","0.06843"
"113.800","9.484","34577.11","0.19923","0.06843"
"114.000","9.500","34486.61","0.19995","0.06843"
"114.200","9.517","34395.17","0.20068","0.06843"
"114.400","9.534","34283.51","0.20142","0.06843"
"114.600","9.550","34195.80","0.20217","0.06843"
"114.800","9.567","34083.78","0.20292","0.06843"
"115.000","9.583","33959.37","0.20367","0.06843"
"115.200","9.600","33850.54","0.20443","0.06842"
"115.400","9.617","33594.20","0.20530","0.06842"
"115.560","9.631","17640.55","0.19867","0.07143"