File: TensionLab/data/experimentalData/1018 Steel Sample 3.csv
Specimen label,"1018_3"
End date,"Monday, January 24, 2022"
Thickness,"6.28000",mm
Width,"12.33000",mm
Final length,"57.08000",mm
Axial gauge length,"25.40000",mm
Transverse gauge length,"12.33000",mm
Crosshead Rate,"5.00",mm/min

Time,Extension,Load,Axial Strain,Transverse Strain
(s),(mm),(N),(mm/mm),(mm/mm)
"0.000","0.000","0.06","0.00000","0.00000"
"0.200","0.014","106.22","0.00000","0.00000"
"0.400","0.033","330.01","0.00003","0.00001"
"0.600","0.050","513.44","0.00005","0.00002"
"0.800","0.067","691.87","0.00008","0.00002"
"1.000","0.084","874.50","0.00009","0.00003"
"1.200","0.100","1078.30","0.00009","0.00003"
"1.400","0.117","1285.31","0.00009","0.00004"
"1.600","0.134","1465.69","0.00008","0.00004"
"1.800","0.150","1672.57","0.00008","0.00005"
"2.000","0.167","1870.46","0.00007","0.00005"
"2.200","0.184","2045.46","0.00006","0.00006"
"2.400","0.200","2222.26","0.00006","0.00006"
"2.600","0.217","2351.00","0.00007","0.00007"
"2.800","0.234","2523.44","0.00007","0.00007"
"3.000","0.250","2676.59","0.00007","0.00007"
"3.200","0.267","2839.79","0.00008","0.00007"
"3.400","0.284","2987.01","0.00009","0.00008"
"3.600","0.300","3140.05","0.00010","0.00008"
"3.800","0.317","3326.53","0.00010","0.00008"
"4.000","0.334","3494.86","0.00011","0.00008"
"4.200","0.350","3682.84","0.00011","0.00008"
"4.400","0.367","3854.19","0.00012","0.00008"
"4.600","0.383","4037.58","0.00012","0.00008"
"4.800","0.400","4228.78","0.00013","0.00008"
"5.000","0.417","4398.63","0.00013","0.00009"
"5.200","0.433","4599.16","0.00013","0.00009"
"5.400","0.450","4799.90","0.00013","0.00009"
"5.600","0.467","4994.86","0.00014","0.00009"
"5.800","0.483","5209.24","0.00014","0.00009"
"6.000","0.500","5402.50","0.00015","0.00010"
"6.200","0.517","5621.60","0.00016","0.00010"
"6.400","0.534","5839.71","0.00017","0.00010"
"6.600","0.550","6052.59","0.00018","0.00011"
"6.800","0.567","6234.87","0.00019","0.00011"
"7.000","0.583","6460.21","0.00020","0.00012"
"7.200","0.600","6652.14","0.00021","0.00012"
"7.400","0.617","6841.19","0.00022","0.00012"
"7.600","0.634","7063.73","0.00023","0.00013"
"7.800","0.650","7273.32","0.00025","0.00013"
"8.000","0.667","7470.09","0.00026","0.00014"
"8.200","0.684","7676.27","0.00027","0.00014"
"8.400","0.700","7901.89","0.00029","0.00015"
"8.600","0.717","8120.29","0.00030","0.00015"
"8.800","0.734","8327.53","0.00031","0.00016"
"9.000","0.750","8551.48","0.00033","0.00016"
"9.200","0.767","8777.87","0.00034","0.00017"
"9.400","0.783","9002.03","0.00036","0.00017"
"9.600","0.800","9225.57","0.00037","0.00017"
"9.800","0.817","9461.29","0.00039","0.00018"
"10.000","0.833","9681.42","0.00040","0.00019"
"10.200","0.850","9906.13","0.00041","0.00019"
"10.400","0.867","10145.52","0.00043","0.00020"
"10.600","0.883","10372.23","0.00045","0.00020"
"10.800","0.900","10600.92","0.00046","0.00021"
"11.000","0.917","10831.98","0.00047","0.00021"
"11.200","0.933","11059.06","0.00049","0.00021"
"11.400","0.950","11312.87","0.00051","0.00022"
"11.600","0.967","11561.89","0.00052","0.00023"
"11.800","0.983","11796.88","0.00053","0.00023"
"12.000","1.000","12016.76","0.00055","0.00024"
"12.200","1.017","12253.47","0.00057","0.00024"
"12.400","1.034","12513.63","0.00059","0.00025"
"12.600","1.050","12755.30","0.00060","0.00025"
"12.800","1.067","13005.31","0.00061","0.00026"
"13.000","1.084","13248.49","0.00063","0.00026"
"13.200","1.100","13501.58","0.00065","0.00027"
"13.400","1.117","13754.86","0.00067","0.00028"
"13.600","1.134","14025.03","0.00069","0.00028"
"13.800","1.150","14261.12","0.00070","0.00029"
"14.000","1.167","14509.52","0.00072","0.00029"
"14.200","1.184","14753.23","0.00073","0.00030"
"14.400","1.200","15010.83","0.00075","0.00031"
"14.600","1.217","15281.77","0.00077","0.00031"
"14.800","1.233","15525.05","0.00079","0.00032"
"15.000","1.250","15800.23","0.00081","0.00033"
"15.200","1.267","16073.27","0.00082","0.00034"
"15.400","1.284","16339.45","0.00084","0.00034"
"15.600","1.300","16598.13","0.00086","0.00035"
"15.800","1.317","16883.25","0.00088","0.00036"
"16.000","1.333","17155.96","0.00090","0.00037"
"16.200","1.350","17412.08","0.00092","0.00037"
"16.400","1.367","17690.55","0.00094","0.00038"
"16.600","1.383","17976.45","0.00096","0.00039"
"16.800","1.400","18234.78","0.00098","0.00040"
"17.000","1.417","18505.87","0.00100","0.00040"
"17.200","1.434","18794.74","0.00102","0.00041"
"17.400","1.450","19041.21","0.00104","0.00042"
"17.600","1.467","19317.28","0.00106","0.00043"
"17.800","1.484","19614.58","0.00108","0.00044"
"18.000","1.500","19872.72","0.00110","0.00045"
"18.200","1.517","20156.72","0.00113","0.00046"
"18.400","1.534","20453.41","0.00115","0.00047"
"18.600","1.550","20712.15","0.00117","0.00048"
"18.800","1.567","21001.58","0.00119","0.00048"
"19.000","1.584","21287.32","0.00121","0.00049"
"19.200","1.600","21556.82","0.00124","0.00050"
"19.400","1.617","21849.46","0.00126","0.00051"
"19.600","1.634","22119.48","0.00128","0.00052"
"19.800","1.650","22403.27","0.00130","0.00053"
"20.000","1.667","22688.56","0.00133","0.00054"
"20.200","1.683","22954.41","0.00135","0.00055"
"20.400","1.700","23252.94","0.00137","0.00056"
"20.600","1.717","23544.13","0.00140","0.00057"
"20.800","1.733","23803.22","0.00142","0.00058"
"21.000","1.750","24114.10","0.00145","0.00059"
"21.200","1.767","24390.54","0.00147","0.00060"
"21.400","1.783","24672.75","0.00149","0.00061"
"21.600","1.800","24969.48","0.00152","0.00062"
"21.800","1.817","25237.07","0.00154","0.00064"
"22.000","1.833","25524.31","0.00157","0.00065"
"22.200","1.850","25823.54","0.00160","0.00066"
"22.400","1.867","26090.98","0.00162","0.00067"
"22.600","1.883","26393.09","0.00165","0.00068"
"22.800","1.900","26665.79","0.00168","0.00069"
"23.000","1.917","26957.11","0.00170","0.00071"
"23.200","1.933","27249.57","0.00173","0.00072"
"23.400","1.950","27522.01","0.00176","0.00073"
"23.600","1.967","27814.57","0.00179","0.00075"
"23.800","1.984","28102.08","0.00182","0.00076"
"24.000","2.000","28376.99","0.00184","0.00077"
"24.200","2.017","28677.00","0.00187","0.00079"
"24.400","2.034","28949.27","0.00190","0.00080"
"24.600","2.050","29239.11","0.00193","0.00082"
"24.800","2.067","29536.57","0.00196","0.00083"
"25.000","2.083","29797.83","0.00199","0.00085"
"25.200","2.100","30094.41","0.00202","0.00086"
"25.400","2.117","30384.92","0.00205","0.00088"
"25.600","2.133","30663.28","0.00209","0.00090"
"25.800","2.150","30963.01","0.00212","0.00091"
"26.000","2.167","31230.15","0.00215","0.00093"
"26.200","2.183","31508.03","0.00218","0.00095"
"26.400","2.200","31801.88","0.00222","0.00097"
"26.600","2.217","32050.54","0.00225","0.00098"
"26.800","2.233","32338.54","0.00229","0.00100"
"27.000","2.250","32625.75","0.00232","0.00102"
"27.200","2.267","32875.05","0.00236","0.00104"
"27.400","2.283","33155.64","0.00239","0.00106"
"27.600","2.300","33442.07","0.00243","0.00108"
"27.800","2.317","33689.19","0.00247","0.00110"
"28.000","2.334","33966.68","0.00250","0.00112"
"28.200","2.350","34225.33","0.00255","0.00115"
"28.400","2.367","34489.72","0.00259","0.00117"
"28.600","2.383","34741.21","0.00263","0.00119"
"28.800","2.400","35014.11","0.00267","0.00122"
"29.000","2.417","35281.30","0.00272","0.00124"
"29.200","2.434","35531.22","0.00276","0.00127"
"29.400","2.450","35775.57","0.00280","0.00129"
"29.600","2.467","36042.39","0.00285","0.00132"
"29.800","2.484","36300.50","0.00290","0.00135"
"30.000","2.500","36551.87","0.00295","0.00138"
"30.200","2.517","36784.30","0.00300","0.00140"
"30.400","2.534","37021.81","0.00305","0.00143"
"30.600","2.550","37276.12","0.00310","0.00146"
"30.800","2.567","37504.44","0.00315","0.00149"
"31.000","2.583","37763.67","0.00321","0.00152"
"31.200","2.600","38007.80","0.00327","0.00156"
"31.400","2.617","38231.85","0.00333","0.00159"
"31.600","2.633","38447.48","0.00339","0.00163"
"31.800","2.650","38674.08","0.00345","0.00166"
"32.000","2.667","38908.50","0.00351","0.00170"
"32.200","2.684","39139.47","0.00357","0.00174"
"32.400","2.700","39356.70","0.00363","0.00178"
"32.600","2.717","39564.16","0.00370","0.00182"
"32.800","2.733","39776.37","0.00377","0.00186"
"33.000","2.750","39992.46","0.00384","0.00190"
"33.200","2.767","40199.07","0.00392","0.00195"
"33.400","2.784","40391.98","0.00399","0.00200"
"33.600","2.800","40599.05","0.00407","0.00204"
"33.800","2.817","40795.04","0.00415","0.00210"
"34.000","2.834","40991.04","0.00424","0.00215"
"34.200","2.850","41160.76","0.00432","0.00220"
"34.400","2.867","41346.00","0.00441","0.00226"
"34.600","2.884","41528.29","0.00450","0.00232"
"34.800","2.900","41712.79","0.00459","0.00238"
"35.000","2.917","41884.54","0.00469","0.00244"
"35.200","2.933","42029.50","0.00479","0.00251"
"35.400","2.950","42190.52","0.00490","0.00257"
"35.600","2.967","42342.44","0.00500","0.00264"
"35.800","2.983","42511.89","0.00511","0.00272"
"36.000","3.000","42640.74","0.00523","0.00279"
"36.200","3.017","42778.34","0.00535","0.00287"
"36.400","3.033","42926.30","0.00546","0.00295"
"36.600","3.050","43060.11","0.00559","0.00303"
"36.800","3.067","43167.79","0.00571","0.00311"
"37.000","3.084","43286.76","0.00585","0.00320"
"37.200","3.100","43389.12","0.00598","0.00329"
"37.400","3.117","43521.90","0.00613","0.00338"
"37.600","3.133","43606.10","0.00627","0.00347"
"37.800","3.150","43714.60","0.00641","0.00357"
"38.000","3.167","43803.62","0.00656","0.00366"
"38.200","3.184","43903.38","0.00671","0.00376"
"38.400","3.200","43990.08","0.00687","0.00387"
"38.600","3.217","44071.28","0.00702","0.00397"
"38.800","3.234","44160.15","0.00719","0.00408"
"39.000","3.250","44215.43","0.00736","0.00419"
"39.200","3.267","44302.12","0.00754","0.00430"
"39.400","3.283","44376.47","0.00772","0.00441"
"39.600","3.300","44422.49","0.00790","0.00452"
"39.800","3.317","44481.29","0.00808","0.00464"
"40.000","3.334","44549.86","0.00826","0.00476"
"40.200","3.350","44604.78","0.00845","0.00487"
"40.400","3.367","44650.89","0.00865","0.00499"
"40.600","3.384","44716.02","0.00884","0.00512"
"40.800","3.400","44758.10","0.00905","0.00524"
"41.000","3.417","44802.47","0.00925","0.00536"
"41.200","3.434","44830.84","0.00946","0.00549"
"41.400","3.450","44879.00","0.00967","0.00561"
"41.600","3.467","44927.60","0.00989","0.00574"
"41.800","3.483","44963.45","0.01012","0.00588"
"42.000","3.500","45011.95","0.01034","0.00601"
"42.200","3.517","45026.70","0.01056","0.00613"
"42.400","3.533","45044.85","0.01079","0.00626"
"42.600","3.550","45071.11","0.01102","0.00640"
"42.800","3.567","45106.43","0.01126","0.00653"
"43.000","3.583","45130.55","0.01149","0.00666"
"43.200","3.600","45169.70","0.01173","0.00679"
"43.400","3.617","45193.70","0.01196","0.00692"
"43.600","3.634","45223.77","0.01221","0.00706"
"43.800","3.650","45241.31","0.01246","0.00719"
"44.000","3.667","45247.38","0.01271","0.00733"
"44.200","3.684","45260.43","0.01296","0.00746"
"44.400","3.700","45288.19","0.01321","0.00760"
"44.600","3.717","45306.44","0.01347","0.00774"
"44.800","3.733","45318.07","0.01372","0.00787"
"45.000","3.750","45336.06","0.01397","0.00801"
"45.200","3.767","45348.81","0.01424","0.00814"
"45.400","3.784","45362.99","0.01450","0.00828"
"45.600","3.800","45372.86","0.01476","0.00842"
"45.800","3.817","45391.32","0.01503","0.00856"
"46.000","3.834","45399.09","0.01530","0.00869"
"46.200","3.850","45418.95","0.01557","0.00883"
"46.400","3.867","45427.34","0.01583","0.00897"
"46.600","3.884","45433.70","0.01611","0.00911"
"46.800","3.900","45436.83","0.01638","0.00925"
"47.000","3.917","45443.62","0.01666","0.00939"
"47.200","3.933","45443.76","0.01694","0.00952"
"47.400","3.950","45451.78","0.01722","0.00966"
"47.600","3.967","45456.19","0.01749","0.00980"
"47.800","3.984","45461.45","0.01777","0.00994"
"48.000","4.000","45467.45","0.01805","0.01008"
"48.200","4.017","45468.91","0.01834","0.01022"
"48.400","4.034","45475.88","0.01862","0.01036"
"48.600","4.050","45479.75","0.01890","0.01050"
"48.800","4.067","45489.96","0.01919","0.01063"
"49.000","4.083","45491.86","0.01948","0.01077"
"49.200","4.100","45493.34","0.01977","0.01091"
"49.400","4.117","45491.66","0.02007","0.01105"
"49.600","4.134","45495.71","0.02036","0.01119"
"49.800","4.150","45493.19","0.02065","0.01132"
"50.000","4.167","45493.61","0.02095","0.01146"
"50.200","4.184","45496.08","0.02125","0.01160"
"50.400","4.200","45489.85","0.02154","0.01174"
"50.600","4.217","45492.91","0.02184","0.01187"
"50.800","4.234","45484.62","0.02213","0.01200"
"51.000","4.250","45490.15","0.02244","0.01214"
"51.200","4.267","45484.04","0.02274","0.01227"
"51.400","4.284","45481.36","0.02304","0.01241"
"51.600","4.300","45473.46","0.02335","0.01254"
"51.800","4.317","45471.02","0.02366","0.01267"
"52.000","4.333","45464.21","0.02396","0.01280"
"52.200","4.350","45464.75","0.02427","0.01293"
"52.400","4.367","45453.60","0.02458","0.01307"
"52.600","4.384","45451.39","0.02489","0.01319"
"52.800","4.400","45446.83","0.02520","0.01332"
"53.000","4.417","45446.49","0.02551","0.01345"
"53.200","4.434","45437.30","0.02582","0.01358"
"53.400","4.450","45436.94","0.02613","0.01370"
"53.600","4.467","45433.54","0.02645","0.01383"
"53.800","4.484","45432.88","0.02676","0.01395"
"54.000","4.500","45426.11","0.02708","0.01408"
"54.200","4.517","45415.75","0.02740","0.01420"
"54.400","4.534","45412.57","0.02772","0.01432"
"54.600","4.550","45393.86","0.02804","0.01444"
"54.800","4.567","45383.67","0.02836","0.01456"
"55.000","4.584","45378.30","0.02869","0.01468"
"55.200","4.600","45362.99","0.02901","0.01480"
"55.400","4.617","45360.33","0.02933","0.01491"
"55.600","4.634","45344.23","0.02965","0.01503"
"55.800","4.650","45340.14","0.02998","0.01514"
"56.000","4.667","45333.29","0.03030","0.01525"
"56.200","4.683","45323.97","0.03063","0.01536"
"56.400","4.700","45309.40","0.03096","0.01547"
"56.600","4.717","45299.38","0.03128","0.01558"
"56.800","4.733","45283.60","0.03162","0.01568"
"57.000","4.750","45266.05","0.03195","0.01578"
"57.200","4.767","45254.08","0.03228","0.01589"
"57.400","4.783","45245.52","0.03261","0.01599"
"57.600","4.800","45244.41","0.03295","0.01608"
"57.800","4.817","45234.67","0.03328","0.01618"
"58.000","4.833","45217.60","0.03361","0.01627"
"58.200","4.850","45214.16","0.03395","0.01636"
"58.400","4.867","45192.28","0.03428","0.01645"
"58.600","4.883","45177.81","0.03462","0.01654"
"58.800","4.900","45161.05","0.03496","0.01663"
"59.000","4.917","45135.20","0.03529","0.01671"
"59.200","4.934","45125.66","0.03562","0.01679"
"59.400","4.950","45109.53","0.03597","0.01687"
"59.600","4.967","45092.48","0.03631","0.01694"
"59.800","4.984","45071.99","0.03666","0.01702"
"60.000","5.000","45047.84","0.03700","0.01709"
"60.200","5.017","45036.75","0.03733","0.01716"
"60.400","5.034","45028.76","0.03768","0.01723"
"60.600","5.050","45026.00","0.03802","0.01729"
"60.800","5.067","45010.68","0.03836","0.01735"
"61.000","5.084","44993.38","0.03870","0.01741"
"61.200","5.100","44957.16","0.03905","0.01747"
"61.400","5.117","44940.12","0.03939","0.01752"
"61.600","5.134","44921.92","0.03973","0.01758"
"61.800","5.150","44898.04","0.04006","0.01762"
"62.000","5.167","44877.08","0.04041","0.01767"
"62.200","5.184","44853.01","0.04076","0.01772"
"62.400","5.200","44828.55","0.04110","0.01776"
"62.600","5.217","44820.62","0.04144","0.01780"
"62.800","5.233","44801.35","0.04178","0.01784"
"63.000","5.250","44779.98","0.04213","0.01788"
"63.200","5.267","44759.59","0.04247","0.01791"
"63.400","5.283","44730.24","0.04281","0.01795"
"63.600","5.300","44716.49","0.04317","0.01798"
"63.800","5.317","44685.63","0.04350","0.01801"
"64.000","5.334","44659.96","0.04386","0.01803"
"64.200","5.350","44625.11","0.04420","0.01806"
"64.400","5.367","44608.64","0.04455","0.01809"
"64.600","5.384","44600.22","0.04489","0.01811"
"64.800","5.400","44582.54","0.04524","0.01813"
"65.000","5.417","44542.35","0.04559","0.01815"
"65.200","5.433","44512.38","0.04593","0.01817"
"65.400","5.450","44484.64","0.04628","0.01819"
"65.600","5.467","44455.07","0.04662","0.01821"
"65.800","5.484","44434.13","0.04697","0.01822"
"66.000","5.500","44414.68","0.04731","0.01824"
"66.200","5.517","44405.19","0.04765","0.01825"
"66.400","5.534","44372.14","0.04799","0.01826"
"66.600","5.550","44336.99","0.04834","0.01827"
"66.800","5.567","44305.96","0.04868","0.01828"
"67.000","5.584","44289.41","0.04903","0.01829"
"67.200","5.600","44254.71","0.04937","0.01830"
"67.400","5.617","44219.03","0.04972","0.01831"
"67.600","5.633","44200.69","0.05008","0.01832"
"67.800","5.650","44183.21","0.05042","0.01832"
"68.000","5.667","44154.93","0.05077","0.01833"
"68.200","5.684","44121.99","0.05112","0.01833"
"68.400","5.700","44101.08","0.05148","0.01834"
"68.600","5.717","44049.89","0.05184","0.01834"
"68.800","5.733","44018.39","0.05219","0.01835"
"69.000","5.750","43997.75","0.05255","0.01835"
"69.200","5.767","43987.51","0.05292","0.01836"
"69.400","5.783","43964.91","0.05329","0.01836"
"69.600","5.800","43921.73","0.05365","0.01836"
"69.800","5.817","43892.33","0.05402","0.01836"
"70.000","5.834","43860.02","0.05439","0.01837"
"70.200","5.850","43829.61","0.05476","0.01837"
"70.400","5.867","43801.74","0.05513","0.01837"
"70.600","5.884","43781.61","0.05550","0.01837"
"70.800","5.900","43744.01","0.05587","0.01838"
"71.000","5.917","43722.72","0.05624","0.01838"
"71.200","5.934","43683.68","0.05660","0.01838"
"71.400","5.950","43658.26","0.05696","0.01838"
"71.600","5.967","43619.72","0.05733","0.01838"
"71.800","5.984","43596.36","0.05768","0.01838"
"72.000","6.000","43573.23","0.05804","0.01838"
"72.200","6.017","43553.60","0.05840","0.01839"
"72.400","6.034","43510.68","0.05876","0.01839"
"72.600","6.050","43479.86","0.05912","0.01839"
"72.800","6.067","43445.62","0.05948","0.01839"
"73.000","6.084","43401.43","0.05983","0.01839"
"73.200","6.100","43381.13","0.06020","0.01839"
"73.400","6.117","43373.15","0.06056","0.01838"
"73.600","6.133","43340.26","0.06091","0.01838"
"73.800","6.150","43291.76","0.06127","0.01838"
"74.000","6.167","43267.77","0.06163","0.01838"
"74.200","6.184","43237.30","0.06198","0.01838"
"74.400","6.200","43188.45","0.06234","0.01838"
"74.600","6.217","43174.36","0.06270","0.01838"
"74.800","6.233","43152.38","0.06307","0.01838"
"75.000","6.250","43123.83","0.06345","0.01838"
"75.200","6.267","43083.30","0.06381","0.01837"
"75.400","6.284","43070.96","0.06419","0.01837"
"75.600","6.300","43017.86","0.06455","0.01837"
"75.800","6.317","42984.74","0.06492","0.01837"
"76.000","6.334","42961.27","0.06529","0.01837"
"76.200","6.350","42938.38","0.06565","0.01837"
"76.400","6.367","42894.75","0.06602","0.01837"
"76.600","6.383","42857.80","0.06639","0.01837"
"76.800","6.400","42833.83","0.06676","0.01836"
"77.000","6.417","42795.99","0.06713","0.01836"
"77.200","6.434","42769.91","0.06751","0.01836"
"77.400","6.450","42757.34","0.06789","0.01836"
"77.600","6.467","42720.59","0.06827","0.01836"
"77.800","6.484","42675.52","0.06865","0.01836"
"78.000","6.500","42644.30","0.06904","0.01836"
"78.200","6.517","42603.85","0.06944","0.01836"
"78.400","6.534","42561.30","0.06981","0.01836"
"78.600","6.550","42547.29","0.07019","0.01835"
"78.800","6.567","42527.35","0.07057","0.01835"
"79.000","6.583","42482.84","0.07095","0.01835"
"79.200","6.600","42455.55","0.07133","0.01835"
"79.400","6.617","42408.55","0.07171","0.01835"
"79.600","6.634","42359.21","0.07209","0.01835"
"79.800","6.650","42339.43","0.07248","0.01835"
"80.000","6.667","42326.12","0.07286","0.01835"
"80.200","6.684","42288.19","0.07325","0.01834"
"80.400","6.700","42248.13","0.07363","0.01834"
"80.600","6.717","42211.14","0.07402","0.01834"
"80.800","6.734","42174.92","0.07441","0.01834"
"81.000","6.750","42150.86","0.07480","0.01834"
"81.200","6.767","42127.44","0.07518","0.01834"
"81.400","6.784","42078.23","0.07557","0.01833"
"81.600","6.800","42032.13","0.07596","0.01833"
"81.800","6.817","42004.82","0.07637","0.01834"
"82.000","6.834","41966.02","0.07677","0.01833"
"82.200","6.850","41939.40","0.07715","0.01833"
"82.400","6.867","41922.07","0.07755","0.01833"
"82.600","6.883","41880.54","0.07794","0.01833"
"82.800","6.900","41845.20","0.07832","0.01833"
"83.000","6.917","41796.86","0.07872","0.01833"
"83.200","6.933","41744.08","0.07912","0.01832"
"83.400","6.950","41723.11","0.07953","0.01832"
"83.600","6.967","41699.43","0.07992","0.01832"
"83.800","6.983","41660.59","0.08031","0.01832"
"84.000","7.000","41623.26","0.08070","0.01832"
"84.200","7.017","41577.83","0.08108","0.01832"
"84.400","7.034","41544.00","0.08149","0.01832"
"84.600","7.050","41515.15","0.08188","0.01832"
"84.800","7.067","41470.66","0.08227","0.01831"
"85.000","7.084","41431.40","0.08267","0.01831"
"85.200","7.100","41401.43","0.08307","0.01831"
"85.400","7.117","41360.21","0.08348","0.01831"
"85.600","7.134","41318.14","0.08387","0.01831"
"85.800","7.150","41297.68","0.08428","0.01831"
"86.000","7.167","41241.31","0.08469","0.01830"
"86.200","7.184","41211.84","0.08509","0.01830"
"86.400","7.200","41148.85","0.08550","0.01830"
"86.600","7.217","41115.32","0.08592","0.01830"
"86.800","7.234","41099.98","0.08633","0.01830"
"87.000","7.250","41057.62","0.08674","0.01829"
"87.200","7.267","41010.52","0.08717","0.01830"
"87.400","7.284","40970.79","0.08760","0.01830"
"87.600","7.300","40923.27","0.08803","0.01829"
"87.800","7.317","40892.03","0.08847","0.01829"
"88.000","7.334","40852.91","0.08890","0.01829"
"88.200","7.350","40804.11","0.08932","0.01829"
"88.400","7.367","40777.20","0.08976","0.01829"
"88.600","7.383","40718.99","0.09019","0.01829"
"88.800","7.400","40687.38","0.09062","0.01829"
"89.000","7.417","40656.54","0.09104","0.01829"
"89.200","7.433","40599.59","0.09146","0.01829"
"89.400","7.450","40559.38","0.09189","0.01828"
"89.600","7.467","40509.74","0.09232","0.01828"
"89.800","7.483","40482.94","0.09276","0.01828"
"90.000","7.500","40450.35","0.09319","0.01828"
"90.200","7.517","40384.26","0.09363","0.01828"
"90.400","7.534","40342.23","0.09407","0.01828"
"90.600","7.550","40298.06","0.09452","0.01828"
"90.800","7.567","40267.81","0.09496","0.01827"
"91.000","7.584","40230.03","0.09541","0.01828"
"91.200","7.600","40177.01","0.09586","0.01827"
"91.400","7.617","40112.79","0.09628","0.01827"
"91.600","7.634","40079.85","0.09671","0.01827"
"91.800","7.650","40047.15","0.09716","0.01827"
"92.000","7.667","39988.96","0.09760","0.01827"
"92.200","7.684","39942.55","0.09805","0.01826"
"92.400","7.700","39891.60","0.09850","0.01826"
"92.600","7.717","39863.63","0.09895","0.01826"
"92.800","7.734","39811.94","0.09940","0.01826"
"93.000","7.750","39759.11","0.09987","0.01826"
"93.200","7.767","39711.73","0.10032","0.01826"
"93.400","7.784","39663.48","0.10078","0.01825"
"93.600","7.800","39624.47","0.10123","0.01825"
"93.800","7.817","39555.97","0.10169","0.01825"
"94.000","7.833","39509.23","0.10215","0.01825"
"94.200","7.850","39459.74","0.10261","0.01825"
"94.400","7.867","39441.75","0.10308","0.01825"
"94.600","7.883","39372.02","0.10354","0.01824"
"94.800","7.900","39322.92","0.10402","0.01824"
"95.000","7.917","39255.60","0.10449","0.01824"
"95.200","7.934","39232.22","0.10496","0.01824"
"95.400","7.950","39161.80","0.10544","0.01824"
"95.600","7.967","39128.07","0.10591","0.01823"
"95.800","7.984","39058.15","0.10639","0.01823"
"96.000","8.000","39029.29","0.10688","0.01823"
"96.200","8.017","38954.98","0.10735","0.01823"
"96.400","8.034","38909.00","0.10784","0.01823"
"96.600","8.050","38851.36","0.10832","0.01823"
"96.800","8.067","38824.78","0.10880","0.01823"
"97.000","8.084","38749.95","0.10929","0.01822"
"97.200","8.100","38686.53","0.10978","0.01822"
"97.400","8.117","38631.76","0.11027","0.01822"
"97.600","8.134","38596.77","0.11076","0.01822"
"97.800","8.150","38535.46","0.11125","0.01822"
"98.000","8.167","38476.35","0.11175","0.01822"
"98.200","8.184","38413.81","0.11225","0.01821"
"98.400","8.200","38360.17","0.11274","0.01821"
"98.600","8.217","38306.42","0.11325","0.01821"
"98.800","8.234","38244.49","0.11374","0.01821"
"99.000","8.250","38212.70","0.11424","0.01821"
"99.200","8.267","38125.19","0.11474","0.01821"
"99.400","8.284","38061.16","0.11525","0.01820"
"99.600","8.300","38013.57","0.11574","0.01820"
"99.800","8.317","37967.20","0.11625","0.01819"
"100.000","8.334","37900.52","0.11674","0.01819"
"100.200","8.350","37815.32","0.11726","0.01819"
"100.400","8.367","37778.36","0.11775","0.01819"
"100.600","8.384","37713.79","0.11826","0.01819"
"100.800","8.400","37646.11","0.11877","0.01819"
"101.000","8.417","37594.52","0.11929","0.01819"
"101.200","8.434","37517.53","0.11979","0.01818"
"101.400","8.450","37455.32","0.12032","0.01818"
"101.600","8.467","37398.26","0.12083","0.01818"
"101.800","8.484","37345.41","0.12135","0.01818"
"102.000","8.500","37265.66","0.12186","0.01818"
"102.200","8.517","37185.70","0.12237","0.01818"
"102.400","8.534","37150.32","0.12288","0.01817"
"102.600","8.550","37081.23","0.12341","0.01817"
"102.800","8.567","36997.67","0.12393","0.01817"
"103.000","8.584","36942.47","0.12446","0.01817"
"103.200","8.600","36877.53","0.12497","0.01817"
"103.400","8.617","36793.56","0.12549","0.01817"
"103.600","8.634","36748.16","0.12601","0.01817"
"103.800","8.650","36663.33","0.12654","0.01816"
"104.000","8.667","36582.43","0.12708","0.01816"
"104.200","8.684","36529.78","0.12761","0.01816"
"104.400","8.700","36456.77","0.12815","0.01816"
"104.600","8.717","36370.88","0.12869","0.01815"
"104.800","8.733","36313.85","0.12923","0.01815"
"105.000","8.750","36234.25","0.12978","0.01815"
"105.200","8.767","36154.05","0.13032","0.01815"
"105.400","8.784","36092.63","0.13087","0.01814"
"105.600","8.800","36006.70","0.13143","0.01814"
"105.800","8.817","35943.01","0.13198","0.01814"
"106.000","8.834","35848.84","0.13255","0.01814"
"106.200","8.850","35771.27","0.13311","0.01814"
"106.400","8.867","35705.64","0.13366","0.01813"
"106.600","8.884","35623.91","0.13422","0.01813"
"106.800","8.900","35532.90","0.13479","0.01813"
"107.000","8.917","35473.01","0.13536","0.01813"
"107.200","8.934","35362.74","0.13593","0.01812"
"107.400","8.950","35299.21","0.13650","0.01812"
"107.600","8.967","35216.90","0.13707","0.01812"
"107.800","8.984","35119.83","0.13765","0.01812"
"108.000","9.000","35019.73","0.13824","0.01812"
"108.200","9.017","34925.48","0.13883","0.01812"
"108.400","9.034","34849.23","0.13942","0.01811"
"108.600","9.050","34717.77","0.14002","0.01811"
"108.800","9.067","34634.11","0.14063","0.01811"
"109.000","9.084","34505.14","0.14125","0.01811"
"109.200","9.100","34365.60","0.14189","0.01810"
"109.400","9.117","34040.96","0.14270","0.01809"
"109.552","9.130","16728.68","0.15167","0.01792"