File: TensionLab/data/experimentalData/1018 Steel Sample 1.csv
Specimen label,"1018_1"
End date,"Monday, January 24, 2022"
Thickness,"6.24000",mm
Width,"12.38000",mm
Final length,"57.02000",mm
Axial gauge length,"25.40000",mm
Transverse gauge length,"12.38000",mm
Crosshead Rate,"5.00",mm/min

Time,Extension,Load,Axial Strain,Transverse Strain
(s),(mm),(N),(mm/mm),(mm/mm)
"0.000","0.000","0.10","0.00000","0.00000"
"0.200","0.014","214.86","0.00001","0.00000"
"0.400","0.033","450.60","0.00003","0.00001"
"0.600","0.050","608.29","0.00005","0.00002"
"0.800","0.067","786.10","0.00006","0.00002"
"1.000","0.084","979.49","0.00008","0.00003"
"1.200","0.100","1157.22","0.00010","0.00004"
"1.400","0.117","1324.88","0.00010","0.00004"
"1.600","0.134","1539.06","0.00011","0.00005"
"1.800","0.150","1770.52","0.00012","0.00005"
"2.000","0.167","1988.62","0.00012","0.00006"
"2.200","0.184","2180.04","0.00013","0.00006"
"2.400","0.200","2395.80","0.00014","0.00006"
"2.600","0.217","2594.92","0.00014","0.00006"
"2.800","0.233","2776.44","0.00015","0.00006"
"3.000","0.250","2978.25","0.00015","0.00006"
"3.200","0.267","3165.77","0.00016","0.00006"
"3.400","0.283","3347.59","0.00016","0.00006"
"3.600","0.300","3558.18","0.00016","0.00006"
"3.800","0.317","3748.07","0.00016","0.00005"
"4.000","0.333","3919.33","0.00016","0.00005"
"4.200","0.350","4102.82","0.00016","0.00005"
"4.400","0.367","4282.89","0.00016","0.00005"
"4.600","0.383","4469.62","0.00016","0.00005"
"4.800","0.400","4621.38","0.00016","0.00005"
"5.000","0.417","4770.72","0.00016","0.00005"
"5.200","0.434","4924.49","0.00016","0.00005"
"5.400","0.450","5100.06","0.00017","0.00005"
"5.600","0.467","5238.78","0.00017","0.00005"
"5.800","0.484","5405.45","0.00017","0.00005"
"6.000","0.500","5555.87","0.00018","0.00005"
"6.200","0.517","5736.38","0.00018","0.00005"
"6.400","0.533","5908.36","0.00019","0.00006"
"6.600","0.550","6066.10","0.00020","0.00006"
"6.800","0.567","6246.46","0.00021","0.00006"
"7.000","0.583","6398.89","0.00021","0.00006"
"7.200","0.600","6595.58","0.00022","0.00006"
"7.400","0.617","6770.64","0.00023","0.00006"
"7.600","0.633","6949.85","0.00024","0.00007"
"7.800","0.650","7156.99","0.00024","0.00007"
"8.000","0.667","7333.13","0.00025","0.00007"
"8.200","0.683","7503.47","0.00026","0.00007"
"8.400","0.700","7703.14","0.00027","0.00007"
"8.600","0.717","7885.17","0.00028","0.00008"
"8.800","0.733","8080.08","0.00029","0.00008"
"9.000","0.750","8280.44","0.00030","0.00008"
"9.200","0.767","8462.40","0.00031","0.00009"
"9.400","0.783","8660.87","0.00032","0.00009"
"9.600","0.800","8863.18","0.00033","0.00009"
"9.800","0.817","9064.37","0.00034","0.00009"
"10.000","0.833","9278.20","0.00035","0.00010"
"10.200","0.850","9472.09","0.00037","0.00010"
"10.400","0.867","9694.21","0.00037","0.00011"
"10.600","0.884","9925.51","0.00039","0.00011"
"10.800","0.900","10137.39","0.00040","0.00011"
"11.000","0.917","10356.82","0.00041","0.00012"
"11.200","0.933","10584.32","0.00042","0.00012"
"11.400","0.950","10817.98","0.00044","0.00013"
"11.600","0.967","11026.72","0.00045","0.00014"
"11.800","0.984","11264.61","0.00046","0.00014"
"12.000","1.000","11477.15","0.00048","0.00015"
"12.200","1.017","11717.21","0.00049","0.00016"
"12.400","1.034","11942.29","0.00050","0.00016"
"12.600","1.050","12156.16","0.00052","0.00017"
"12.800","1.067","12387.84","0.00053","0.00017"
"13.000","1.083","12638.69","0.00054","0.00018"
"13.200","1.100","12862.38","0.00056","0.00019"
"13.400","1.117","13107.78","0.00057","0.00019"
"13.600","1.133","13348.29","0.00059","0.00020"
"13.800","1.150","13581.88","0.00060","0.00020"
"14.000","1.167","13815.96","0.00062","0.00021"
"14.200","1.183","14053.78","0.00063","0.00021"
"14.400","1.200","14296.16","0.00065","0.00022"
"14.600","1.217","14539.03","0.00066","0.00023"
"14.800","1.234","14803.59","0.00068","0.00024"
"15.000","1.250","15043.20","0.00069","0.00024"
"15.200","1.267","15293.09","0.00071","0.00025"
"15.400","1.284","15542.31","0.00073","0.00026"
"15.600","1.300","15792.05","0.00074","0.00027"
"15.800","1.317","16046.47","0.00076","0.00027"
"16.000","1.333","16284.31","0.00077","0.00028"
"16.200","1.350","16549.57","0.00079","0.00028"
"16.400","1.367","16810.62","0.00081","0.00029"
"16.600","1.383","17072.69","0.00082","0.00030"
"16.800","1.400","17315.55","0.00084","0.00031"
"17.000","1.417","17588.79","0.00086","0.00032"
"17.200","1.433","17858.17","0.00088","0.00033"
"17.400","1.450","18124.07","0.00090","0.00033"
"17.600","1.467","18367.68","0.00092","0.00034"
"17.800","1.483","18640.62","0.00093","0.00035"
"18.000","1.500","18905.47","0.00095","0.00036"
"18.200","1.517","19157.71","0.00097","0.00037"
"18.400","1.533","19430.76","0.00099","0.00037"
"18.600","1.550","19700.01","0.00101","0.00038"
"18.800","1.567","19963.95","0.00102","0.00039"
"19.000","1.583","20220.55","0.00105","0.00040"
"19.200","1.600","20503.46","0.00107","0.00041"
"19.400","1.617","20772.68","0.00108","0.00042"
"19.600","1.633","21025.53","0.00111","0.00043"
"19.800","1.650","21303.64","0.00112","0.00044"
"20.000","1.667","21575.95","0.00115","0.00045"
"20.200","1.683","21834.74","0.00117","0.00047"
"20.400","1.700","22118.73","0.00119","0.00048"
"20.600","1.717","22394.25","0.00121","0.00048"
"20.800","1.734","22666.34","0.00123","0.00049"
"21.000","1.750","22928.49","0.00125","0.00051"
"21.200","1.767","23215.51","0.00127","0.00052"
"21.400","1.783","23484.20","0.00130","0.00053"
"21.600","1.800","23750.77","0.00132","0.00054"
"21.800","1.817","24014.46","0.00134","0.00055"
"22.000","1.834","24300.88","0.00136","0.00056"
"22.200","1.850","24541.72","0.00139","0.00058"
"22.400","1.867","24835.94","0.00141","0.00059"
"22.600","1.883","25117.54","0.00144","0.00060"
"22.800","1.900","25376.66","0.00146","0.00062"
"23.000","1.917","25658.90","0.00149","0.00063"
"23.200","1.933","25944.98","0.00151","0.00064"
"23.400","1.950","26201.61","0.00153","0.00065"
"23.600","1.967","26482.72","0.00156","0.00067"
"23.800","1.983","26764.32","0.00158","0.00068"
"24.000","2.000","27024.25","0.00161","0.00069"
"24.200","2.017","27298.08","0.00164","0.00071"
"24.400","2.033","27586.87","0.00166","0.00072"
"24.600","2.050","27847.94","0.00169","0.00074"
"24.800","2.067","28126.71","0.00172","0.00075"
"25.000","2.083","28417.93","0.00174","0.00077"
"25.200","2.100","28670.66","0.00177","0.00078"
"25.400","2.117","28948.97","0.00180","0.00080"
"25.600","2.133","29243.41","0.00183","0.00081"
"25.800","2.150","29488.46","0.00186","0.00083"
"26.000","2.167","29762.23","0.00188","0.00085"
"26.200","2.184","30053.29","0.00192","0.00087"
"26.400","2.200","30300.64","0.00195","0.00088"
"26.600","2.217","30579.85","0.00198","0.00090"
"26.800","2.234","30860.89","0.00201","0.00092"
"27.000","2.250","31125.99","0.00204","0.00094"
"27.200","2.267","31378.99","0.00207","0.00096"
"27.400","2.284","31660.46","0.00210","0.00098"
"27.600","2.300","31928.21","0.00214","0.00100"
"27.800","2.317","32174.96","0.00217","0.00102"
"28.000","2.333","32441.67","0.00221","0.00104"
"28.200","2.350","32707.17","0.00224","0.00106"
"28.400","2.367","32973.30","0.00227","0.00108"
"28.600","2.383","33212.84","0.00231","0.00110"
"28.800","2.400","33480.01","0.00235","0.00112"
"29.000","2.417","33723.27","0.00238","0.00115"
"29.200","2.433","33984.36","0.00242","0.00118"
"29.400","2.450","34225.23","0.00246","0.00120"
"29.600","2.467","34488.14","0.00249","0.00122"
"29.800","2.483","34741.63","0.00253","0.00124"
"30.000","2.500","35005.42","0.00257","0.00127"
"30.200","2.517","35243.72","0.00261","0.00129"
"30.400","2.533","35475.09","0.00265","0.00132"
"30.600","2.550","35720.27","0.00269","0.00134"
"30.800","2.567","35968.27","0.00273","0.00137"
"31.000","2.584","36222.65","0.00278","0.00140"
"31.200","2.600","36470.56","0.00282","0.00142"
"31.400","2.617","36700.92","0.00287","0.00145"
"31.600","2.633","36924.65","0.00291","0.00148"
"31.800","2.650","37162.34","0.00296","0.00151"
"32.000","2.667","37394.70","0.00301","0.00155"
"32.200","2.684","37621.78","0.00306","0.00158"
"32.400","2.700","37860.49","0.00311","0.00162"
"32.600","2.717","38095.36","0.00316","0.00165"
"32.800","2.734","38319.38","0.00321","0.00168"
"33.000","2.750","38532.85","0.00327","0.00172"
"33.200","2.767","38751.57","0.00332","0.00175"
"33.400","2.784","38975.88","0.00338","0.00179"
"33.600","2.800","39178.29","0.00344","0.00182"
"33.800","2.817","39386.29","0.00350","0.00186"
"34.000","2.833","39592.48","0.00357","0.00191"
"34.200","2.850","39802.97","0.00363","0.00196"
"34.400","2.867","40009.15","0.00369","0.00201"
"34.600","2.883","40201.45","0.00376","0.00205"
"34.800","2.900","40402.78","0.00383","0.00209"
"35.000","2.917","40595.68","0.00389","0.00214"
"35.200","2.933","40781.66","0.00397","0.00219"
"35.400","2.950","40951.04","0.00404","0.00224"
"35.600","2.967","41139.83","0.00411","0.00229"
"35.800","2.983","41296.27","0.00419","0.00235"
"36.000","3.000","41480.96","0.00427","0.00241"
"36.200","3.017","41652.02","0.00435","0.00246"
"36.400","3.033","41826.94","0.00444","0.00252"
"36.600","3.050","41978.89","0.00453","0.00258"
"36.800","3.067","42114.24","0.00462","0.00265"
"37.000","3.083","42281.41","0.00471","0.00271"
"37.200","3.100","42431.80","0.00481","0.00278"
"37.400","3.117","42566.57","0.00490","0.00286"
"37.600","3.133","42690.32","0.00500","0.00293"
"37.800","3.150","42844.51","0.00510","0.00300"
"38.000","3.167","42952.20","0.00520","0.00308"
"38.200","3.183","43085.42","0.00531","0.00316"
"38.400","3.200","43207.21","0.00543","0.00325"
"38.600","3.217","43310.11","0.00554","0.00333"
"38.800","3.234","43423.12","0.00566","0.00342"
"39.000","3.250","43516.10","0.00578","0.00351"
"39.200","3.267","43624.52","0.00591","0.00360"
"39.400","3.284","43724.09","0.00604","0.00370"
"39.600","3.300","43817.75","0.00617","0.00380"
"39.800","3.317","43909.52","0.00631","0.00390"
"40.000","3.334","43982.58","0.00645","0.00400"
"40.200","3.350","44078.59","0.00659","0.00411"
"40.400","3.367","44137.50","0.00673","0.00422"
"40.600","3.383","44228.28","0.00688","0.00434"
"40.800","3.400","44303.61","0.00704","0.00445"
"41.000","3.417","44347.62","0.00721","0.00457"
"41.200","3.433","44425.67","0.00738","0.00468"
"41.400","3.450","44483.12","0.00755","0.00480"
"41.600","3.467","44542.37","0.00773","0.00492"
"41.800","3.484","44582.24","0.00791","0.00504"
"42.000","3.500","44638.18","0.00809","0.00517"
"42.200","3.517","44689.22","0.00827","0.00529"
"42.400","3.534","44736.98","0.00846","0.00543"
"42.600","3.550","44768.71","0.00865","0.00556"
"42.800","3.567","44822.10","0.00884","0.00570"
"43.000","3.583","44863.51","0.00903","0.00583"
"43.200","3.600","44904.43","0.00923","0.00596"
"43.400","3.617","44934.30","0.00943","0.00610"
"43.600","3.634","44956.59","0.00963","0.00624"
"43.800","3.650","44999.35","0.00983","0.00638"
"44.000","3.667","45036.16","0.01004","0.00652"
"44.200","3.683","45065.56","0.01025","0.00666"
"44.400","3.700","45085.29","0.01047","0.00680"
"44.600","3.717","45124.82","0.01068","0.00695"
"44.800","3.733","45156.89","0.01090","0.00709"
"45.000","3.750","45162.28","0.01111","0.00723"
"45.200","3.767","45177.09","0.01134","0.00738"
"45.400","3.783","45189.50","0.01156","0.00753"
"45.600","3.800","45214.22","0.01178","0.00768"
"45.800","3.817","45249.02","0.01201","0.00782"
"46.000","3.833","45263.57","0.01223","0.00797"
"46.200","3.850","45282.77","0.01247","0.00812"
"46.400","3.867","45306.02","0.01270","0.00827"
"46.600","3.884","45322.59","0.01293","0.00842"
"46.800","3.900","45338.15","0.01317","0.00858"
"47.000","3.917","45355.65","0.01341","0.00873"
"47.200","3.934","45364.78","0.01366","0.00888"
"47.400","3.950","45370.52","0.01390","0.00904"
"47.600","3.967","45374.03","0.01414","0.00919"
"47.800","3.984","45378.73","0.01438","0.00935"
"48.000","4.000","45386.93","0.01463","0.00950"
"48.200","4.017","45397.29","0.01488","0.00965"
"48.400","4.034","45408.15","0.01513","0.00981"
"48.600","4.050","45418.05","0.01538","0.00997"
"48.800","4.067","45426.91","0.01564","0.01012"
"49.000","4.084","45436.86","0.01590","0.01028"
"49.200","4.100","45446.00","0.01616","0.01044"
"49.400","4.117","45445.52","0.01642","0.01059"
"49.600","4.134","45457.52","0.01669","0.01076"
"49.800","4.150","45455.27","0.01695","0.01092"
"50.000","4.167","45462.51","0.01721","0.01107"
"50.200","4.183","45465.92","0.01748","0.01123"
"50.400","4.200","45469.54","0.01774","0.01140"
"50.600","4.217","45468.62","0.01801","0.01155"
"50.800","4.233","45472.34","0.01827","0.01172"
"51.000","4.250","45470.79","0.01854","0.01188"
"51.200","4.267","45473.87","0.01881","0.01204"
"51.400","4.284","45474.53","0.01908","0.01220"
"51.600","4.300","45476.57","0.01936","0.01236"
"51.800","4.317","45472.97","0.01963","0.01252"
"52.000","4.333","45474.70","0.01991","0.01268"
"52.200","4.350","45474.71","0.02019","0.01285"
"52.400","4.367","45475.75","0.02048","0.01301"
"52.600","4.384","45474.02","0.02076","0.01318"
"52.800","4.400","45471.29","0.02105","0.01335"
"53.000","4.417","45469.65","0.02133","0.01351"
"53.200","4.434","45468.65","0.02162","0.01368"
"53.400","4.450","45468.26","0.02191","0.01385"
"53.600","4.467","45466.86","0.02219","0.01402"
"53.800","4.483","45460.91","0.02249","0.01419"
"54.000","4.500","45462.63","0.02279","0.01436"
"54.200","4.517","45455.75","0.02308","0.01453"
"54.400","4.534","45453.86","0.02337","0.01470"
"54.600","4.550","45444.94","0.02367","0.01488"
"54.800","4.567","45446.11","0.02397","0.01505"
"55.000","4.583","45425.04","0.02427","0.01522"
"55.200","4.600","45427.88","0.02457","0.01539"
"55.400","4.617","45417.53","0.02487","0.01556"
"55.600","4.633","45413.21","0.02517","0.01574"
"55.800","4.650","45409.91","0.02548","0.01592"
"56.000","4.667","45398.42","0.02579","0.01609"
"56.200","4.683","45388.14","0.02609","0.01627"
"56.400","4.700","45382.70","0.02640","0.01644"
"56.600","4.717","45380.15","0.02673","0.01663"
"56.800","4.734","45377.99","0.02705","0.01681"
"57.000","4.750","45375.40","0.02737","0.01699"
"57.200","4.767","45368.96","0.02769","0.01717"
"57.400","4.784","45365.95","0.02802","0.01735"
"57.600","4.800","45359.65","0.02834","0.01754"
"57.800","4.817","45353.59","0.02867","0.01772"
"58.000","4.834","45340.81","0.02899","0.01791"
"58.200","4.850","45336.17","0.02931","0.01809"
"58.400","4.867","45323.86","0.02964","0.01828"
"58.600","4.884","45316.60","0.02997","0.01847"
"58.800","4.900","45307.67","0.03031","0.01866"
"59.000","4.917","45295.57","0.03064","0.01886"
"59.200","4.934","45280.39","0.03098","0.01905"
"59.400","4.950","45265.09","0.03131","0.01924"
"59.600","4.967","45262.10","0.03166","0.01944"
"59.800","4.984","45248.55","0.03200","0.01964"
"60.000","5.000","45236.36","0.03234","0.01984"
"60.200","5.017","45219.18","0.03268","0.02004"
"60.400","5.034","45202.71","0.03303","0.02025"
"60.600","5.050","45190.64","0.03337","0.02045"
"60.800","5.067","45181.30","0.03372","0.02066"
"61.000","5.083","45177.21","0.03408","0.02087"
"61.200","5.100","45170.95","0.03444","0.02108"
"61.400","5.117","45162.57","0.03480","0.02129"
"61.600","5.133","45157.41","0.03517","0.02151"
"61.800","5.150","45156.04","0.03554","0.02173"
"62.000","5.167","45145.75","0.03590","0.02195"
"62.200","5.183","45128.35","0.03628","0.02217"
"62.400","5.200","45115.41","0.03666","0.02239"
"62.600","5.217","45086.52","0.03704","0.02262"
"62.800","5.234","45073.93","0.03742","0.02285"
"63.000","5.250","45066.22","0.03781","0.02307"
"63.200","5.267","45041.11","0.03821","0.02330"
"63.400","5.283","45026.12","0.03859","0.02354"
"63.600","5.300","45006.68","0.03900","0.02377"
"63.800","5.317","44991.76","0.03940","0.02400"
"64.000","5.334","44977.22","0.03981","0.02424"
"64.200","5.350","44961.62","0.04022","0.02449"
"64.400","5.367","44953.01","0.04063","0.02473"
"64.600","5.384","44943.20","0.04105","0.02498"
"64.800","5.400","44920.91","0.04147","0.02523"
"65.000","5.417","44908.37","0.04189","0.02548"
"65.200","5.433","44889.52","0.04233","0.02574"
"65.400","5.450","44864.90","0.04275","0.02599"
"65.600","5.467","44855.39","0.04319","0.02624"
"65.800","5.483","44830.75","0.04363","0.02650"
"66.000","5.500","44804.31","0.04408","0.02676"
"66.200","5.517","44783.79","0.04452","0.02702"
"66.400","5.533","44758.66","0.04498","0.02728"
"66.600","5.550","44740.79","0.04543","0.02755"
"66.800","5.567","44734.49","0.04589","0.02782"
"67.000","5.584","44718.00","0.04635","0.02808"
"67.200","5.600","44692.21","0.04681","0.02835"
"67.400","5.617","44653.65","0.04728","0.02862"
"67.600","5.633","44640.02","0.04775","0.02889"
"67.800","5.650","44600.93","0.04823","0.02916"
"68.000","5.667","44580.40","0.04869","0.02943"
"68.200","5.683","44555.82","0.04916","0.02969"
"68.400","5.700","44544.89","0.04964","0.02996"
"68.600","5.717","44533.20","0.05012","0.03023"
"68.800","5.734","44507.38","0.05061","0.03050"
"69.000","5.750","44461.80","0.05110","0.03077"
"69.200","5.767","44438.16","0.05159","0.03104"
"69.400","5.784","44413.93","0.05208","0.03131"
"69.600","5.800","44388.41","0.05258","0.03158"
"69.800","5.817","44346.00","0.05309","0.03185"
"70.000","5.834","44330.96","0.05359","0.03211"
"70.200","5.850","44309.18","0.05409","0.03238"
"70.400","5.867","44287.92","0.05459","0.03264"
"70.600","5.884","44242.28","0.05510","0.03290"
"70.800","5.900","44223.46","0.05560","0.03316"
"71.000","5.917","44173.84","0.05612","0.03342"
"71.200","5.933","44142.93","0.05662","0.03368"
"71.400","5.950","44123.68","0.05713","0.03393"
"71.600","5.967","44117.08","0.05765","0.03419"
"71.800","5.983","44082.31","0.05816","0.03444"
"72.000","6.000","44042.19","0.05868","0.03469"
"72.200","6.017","44017.07","0.05920","0.03494"
"72.400","6.033","43970.38","0.05970","0.03519"
"72.600","6.050","43944.64","0.06023","0.03544"
"72.800","6.067","43920.05","0.06075","0.03569"
"73.000","6.084","43898.19","0.06127","0.03593"
"73.200","6.100","43863.88","0.06178","0.03617"
"73.400","6.117","43817.84","0.06229","0.03641"
"73.600","6.134","43799.90","0.06281","0.03665"
"73.800","6.150","43765.36","0.06332","0.03688"
"74.000","6.167","43729.38","0.06384","0.03712"
"74.200","6.184","43707.09","0.06437","0.03735"
"74.400","6.200","43685.52","0.06489","0.03758"
"74.600","6.217","43636.45","0.06541","0.03781"
"74.800","6.234","43610.74","0.06595","0.03803"
"75.000","6.250","43561.66","0.06647","0.03826"
"75.200","6.267","43531.23","0.06701","0.03848"
"75.400","6.283","43511.13","0.06754","0.03870"
"75.600","6.300","43499.05","0.06808","0.03891"
"75.800","6.317","43462.92","0.06862","0.03913"
"76.000","6.333","43404.82","0.06916","0.03934"
"76.200","6.350","43383.25","0.06971","0.03955"
"76.400","6.367","43337.97","0.07025","0.03975"
"76.600","6.383","43307.73","0.07080","0.03996"
"76.800","6.400","43289.05","0.07135","0.04016"
"77.000","6.417","43262.28","0.07188","0.04036"
"77.200","6.433","43221.07","0.07242","0.04056"
"77.400","6.450","43201.16","0.07296","0.04076"
"77.600","6.467","43146.14","0.07350","0.04095"
"77.800","6.483","43108.77","0.07403","0.04114"
"78.000","6.500","43088.66","0.07457","0.04133"
"78.200","6.517","43061.18","0.07511","0.04151"
"78.400","6.534","43012.76","0.07567","0.04170"
"78.600","6.550","42986.60","0.07623","0.04188"
"78.800","6.567","42942.77","0.07680","0.04206"
"79.000","6.584","42912.93","0.07737","0.04223"
"79.200","6.600","42897.94","0.07795","0.04241"
"79.400","6.617","42871.41","0.07853","0.04259"
"79.600","6.634","42819.50","0.07912","0.04276"
"79.800","6.650","42777.45","0.07971","0.04293"
"80.000","6.667","42743.54","0.08030","0.04309"
"80.200","6.684","42702.11","0.08090","0.04326"
"80.400","6.700","42678.89","0.08150","0.04342"
"80.600","6.717","42663.46","0.08210","0.04358"
"80.800","6.734","42622.75","0.08270","0.04374"
"81.000","6.750","42583.44","0.08330","0.04390"
"81.200","6.767","42539.56","0.08391","0.04405"
"81.400","6.784","42488.73","0.08452","0.04421"
"81.600","6.800","42469.39","0.08512","0.04436"
"81.800","6.817","42442.23","0.08574","0.04451"
"82.000","6.833","42399.94","0.08634","0.04465"
"82.200","6.850","42369.60","0.08695","0.04480"
"82.400","6.867","42331.48","0.08757","0.04494"
"82.600","6.883","42287.06","0.08819","0.04508"
"82.800","6.900","42273.43","0.08882","0.04522"
"83.000","6.917","42225.13","0.08944","0.04535"
"83.200","6.933","42169.71","0.09007","0.04548"
"83.400","6.950","42145.63","0.09070","0.04562"
"83.600","6.967","42103.53","0.09133","0.04575"
"83.800","6.983","42069.55","0.09197","0.04588"
"84.000","7.000","42055.85","0.09260","0.04600"
"84.200","7.017","42005.28","0.09324","0.04612"
"84.400","7.033","41972.34","0.09388","0.04624"
"84.600","7.050","41912.07","0.09452","0.04636"
"84.800","7.067","41865.44","0.09518","0.04648"
"85.000","7.084","41850.59","0.09584","0.04659"
"85.200","7.100","41818.80","0.09649","0.04670"
"85.400","7.117","41765.86","0.09715","0.04681"
"85.600","7.134","41736.15","0.09782","0.04692"
"85.800","7.150","41689.63","0.09848","0.04703"
"86.000","7.167","41655.70","0.09914","0.04713"
"86.200","7.184","41624.07","0.09980","0.04724"
"86.400","7.200","41561.47","0.10045","0.04734"
"86.600","7.217","41542.12","0.10111","0.04743"
"86.800","7.233","41494.75","0.10176","0.04753"
"87.000","7.250","41455.27","0.10243","0.04762"
"87.200","7.267","41430.55","0.10309","0.04772"
"87.400","7.284","41379.52","0.10374","0.04781"
"87.600","7.300","41340.14","0.10441","0.04790"
"87.800","7.317","41282.20","0.10507","0.04799"
"88.000","7.333","41244.84","0.10574","0.04807"
"88.200","7.350","41228.46","0.10641","0.04815"
"88.400","7.367","41177.39","0.10709","0.04824"
"88.600","7.384","41139.18","0.10775","0.04832"
"88.800","7.400","41077.68","0.10843","0.04840"
"89.000","7.417","41040.69","0.10909","0.04847"
"89.200","7.434","41008.96","0.10976","0.04855"
"89.400","7.450","40958.62","0.11044","0.04862"
"89.600","7.467","40923.14","0.11111","0.04869"
"89.800","7.483","40868.36","0.11178","0.04876"
"90.000","7.500","40829.43","0.11247","0.04883"
"90.200","7.517","40798.53","0.11315","0.04890"
"90.400","7.534","40737.88","0.11384","0.04896"
"90.600","7.550","40684.25","0.11451","0.04903"
"90.800","7.567","40643.26","0.11520","0.04909"
"91.000","7.583","40613.46","0.11587","0.04915"
"91.200","7.600","40573.55","0.11656","0.04921"
"91.400","7.617","40512.89","0.11724","0.04927"
"91.600","7.634","40459.37","0.11791","0.04932"
"91.800","7.650","40415.18","0.11860","0.04937"
"92.000","7.667","40385.71","0.11929","0.04943"
"92.200","7.683","40336.22","0.11997","0.04948"
"92.400","7.700","40289.26","0.12065","0.04953"
"92.600","7.717","40225.07","0.12134","0.04958"
"92.800","7.733","40190.62","0.12202","0.04963"
"93.000","7.750","40155.33","0.12271","0.04968"
"93.200","7.767","40099.21","0.12340","0.04972"
"93.400","7.784","40041.84","0.12408","0.04976"
"93.600","7.800","40001.54","0.12477","0.04981"
"93.800","7.817","39953.18","0.12545","0.04985"
"94.000","7.834","39891.25","0.12613","0.04989"
"94.200","7.850","39848.37","0.12682","0.04993"
"94.400","7.867","39798.62","0.12750","0.04996"
"94.600","7.884","39763.41","0.12820","0.05000"
"94.800","7.900","39686.07","0.12888","0.05003"
"95.000","7.917","39637.54","0.12957","0.05007"
"95.200","7.934","39591.83","0.13027","0.05010"
"95.400","7.950","39564.38","0.13096","0.05013"
"95.600","7.967","39496.89","0.13166","0.05016"
"95.800","7.984","39436.64","0.13235","0.05019"
"96.000","8.000","39381.85","0.13305","0.05022"
"96.200","8.017","39340.38","0.13374","0.05025"
"96.400","8.034","39278.22","0.13444","0.05028"
"96.600","8.050","39229.57","0.13514","0.05030"
"96.800","8.067","39169.43","0.13584","0.05032"
"97.000","8.083","39120.15","0.13653","0.05035"
"97.200","8.100","39062.03","0.13723","0.05037"
"97.400","8.117","38999.53","0.13793","0.05039"
"97.600","8.133","38968.94","0.13864","0.05041"
"97.800","8.150","38906.19","0.13935","0.05043"
"98.000","8.167","38830.69","0.14006","0.05045"
"98.200","8.183","38765.98","0.14076","0.05047"
"98.400","8.200","38737.85","0.14148","0.05049"
"98.600","8.217","38668.05","0.14218","0.05050"
"98.800","8.234","38600.93","0.14288","0.05052"
"99.000","8.250","38542.69","0.14357","0.05054"
"99.200","8.267","38486.38","0.14427","0.05055"
"99.400","8.284","38435.07","0.14498","0.05056"
"99.600","8.300","38369.82","0.14568","0.05057"
"99.800","8.317","38334.82","0.14638","0.05059"
"100.000","8.334","38242.60","0.14709","0.05060"
"100.200","8.350","38172.82","0.14779","0.05061"
"100.400","8.367","38139.63","0.14850","0.05062"
"100.600","8.384","38068.56","0.14922","0.05063"
"100.800","8.400","37988.11","0.14992","0.05064"
"101.000","8.417","37925.19","0.15063","0.05064"
"101.200","8.434","37885.18","0.15133","0.05065"
"101.400","8.450","37828.98","0.15204","0.05066"
"101.600","8.467","37747.87","0.15275","0.05067"
"101.800","8.483","37691.67","0.15346","0.05067"
"102.000","8.500","37616.05","0.15417","0.05068"
"102.200","8.517","37548.66","0.15488","0.05068"
"102.400","8.533","37500.37","0.15558","0.05069"
"102.600","8.550","37424.27","0.15629","0.05069"
"102.800","8.567","37332.68","0.15701","0.05070"
"103.000","8.583","37298.26","0.15772","0.05070"
"103.200","8.600","37215.66","0.15842","0.05070"
"103.400","8.617","37133.09","0.15913","0.05071"
"103.600","8.633","37080.80","0.15982","0.05071"
"103.800","8.650","37009.39","0.16052","0.05071"
"104.000","8.667","36925.71","0.16123","0.05071"
"104.200","8.683","36873.68","0.16195","0.05071"
"104.400","8.700","36791.96","0.16266","0.05072"
"104.600","8.717","36708.41","0.16338","0.05072"
"104.800","8.734","36661.55","0.16410","0.05072"
"105.000","8.750","36581.67","0.16482","0.05072"
"105.200","8.767","36495.40","0.16554","0.05072"
"105.400","8.784","36430.09","0.16627","0.05072"
"105.600","8.800","36344.89","0.16699","0.05072"
"105.800","8.817","36275.64","0.16771","0.05072"
"106.000","8.834","36191.92","0.16844","0.05072"
"106.200","8.850","36103.07","0.16917","0.05072"
"106.400","8.867","36045.81","0.16989","0.05072"
"106.600","8.884","35955.66","0.17061","0.05072"
"106.800","8.900","35875.48","0.17133","0.05072"
"107.000","8.917","35808.39","0.17205","0.05072"
"107.200","8.934","35705.71","0.17278","0.05072"
"107.400","8.950","35644.43","0.17350","0.05072"
"107.600","8.967","35558.84","0.17423","0.05072"
"107.800","8.983","35457.11","0.17495","0.05072"
"108.000","9.000","35381.86","0.17568","0.05072"
"108.200","9.017","35305.02","0.17642","0.05072"
"108.400","9.033","35218.87","0.17714","0.05071"
"108.600","9.050","35119.00","0.17787","0.05071"
"108.800","9.067","35045.27","0.17860","0.05071"
"109.000","9.083","34947.84","0.17933","0.05071"
"109.200","9.100","34844.32","0.18006","0.05071"
"109.400","9.117","34775.84","0.18080","0.05071"
"109.600","9.134","34671.86","0.18154","0.05071"
"109.800","9.150","34593.41","0.18227","0.05070"
"110.000","9.167","34484.71","0.18300","0.05070"
"110.200","9.183","34415.24","0.18373","0.05070"
"110.400","9.200","34299.80","0.18448","0.05070"
"110.600","9.217","34212.00","0.18521","0.05070"
"110.800","9.234","34114.30","0.18596","0.05070"
"111.000","9.250","33995.32","0.18670","0.05069"
"111.200","9.267","33893.11","0.18745","0.05069"
"111.400","9.284","33791.47","0.18820","0.05069"
"111.600","9.300","33582.00","0.18903","0.05068"
"111.742","9.313","16514.12","0.15307","0.05085"