File: TorsionLab/StrainHardening/1018 Steel Sample 3.csv
Time (s),Extension (mm),Load (N),Axial Strain (mm/mm),Transverse Strain (mm/mm),Thickness(m),Width(m),Final length(m),Axial gauge length(m),Transverse gauge length(m),Crosshead Rate(mm/min)
0,0,0.06,0,0,0.00628,0.01233,0.05708,0.0254,0.01233,5
0.1,0.004,7.4,0,0,,,,,,
0.2,0.014,106.22,0,0,,,,,,
0.3,0.024,233.88,0.00002,0.00001,,,,,,
0.4,0.033,330.01,0.00003,0.00001,,,,,,
0.5,0.042,432.85,0.00004,0.00002,,,,,,
0.6,0.05,513.44,0.00005,0.00002,,,,,,
0.7,0.059,613.98,0.00007,0.00002,,,,,,
0.8,0.067,691.87,0.00008,0.00002,,,,,,
0.9,0.075,790.28,0.00009,0.00002,,,,,,
1,0.084,874.5,0.00009,0.00003,,,,,,
1.1,0.092,1000.58,0.0001,0.00003,,,,,,
1.2,0.1,1078.3,0.00009,0.00003,,,,,,
1.3,0.109,1180.38,0.00009,0.00004,,,,,,
1.4,0.117,1285.31,0.00009,0.00004,,,,,,
1.5,0.125,1382.77,0.00008,0.00004,,,,,,
1.6,0.134,1465.69,0.00008,0.00004,,,,,,
1.7,0.142,1574.15,0.00008,0.00005,,,,,,
1.8,0.15,1672.57,0.00008,0.00005,,,,,,
1.9,0.159,1752.64,0.00007,0.00005,,,,,,
2,0.167,1870.46,0.00007,0.00005,,,,,,
2.1,0.175,1953.24,0.00007,0.00006,,,,,,
2.2,0.184,2045.46,0.00006,0.00006,,,,,,
2.3,0.192,2123.41,0.00007,0.00006,,,,,,
2.4,0.2,2222.26,0.00006,0.00006,,,,,,
2.5,0.209,2286.25,0.00006,0.00006,,,,,,
2.6,0.217,2351,0.00007,0.00007,,,,,,
2.7,0.225,2442.55,0.00007,0.00007,,,,,,
2.8,0.234,2523.44,0.00007,0.00007,,,,,,
2.9,0.242,2583.34,0.00007,0.00007,,,,,,
3,0.25,2676.59,0.00007,0.00007,,,,,,
3.1,0.258,2742.19,0.00008,0.00007,,,,,,
3.2,0.267,2839.79,0.00008,0.00007,,,,,,
3.3,0.275,2900.76,0.00009,0.00007,,,,,,
3.4,0.284,2987.01,0.00009,0.00008,,,,,,
3.5,0.292,3092.17,0.00009,0.00008,,,,,,
3.6,0.3,3140.05,0.0001,0.00008,,,,,,
3.7,0.309,3231.43,0.0001,0.00008,,,,,,
3.8,0.317,3326.53,0.0001,0.00008,,,,,,
3.9,0.325,3411.37,0.00011,0.00008,,,,,,
4,0.334,3494.86,0.00011,0.00008,,,,,,
4.1,0.342,3570.21,0.00011,0.00008,,,,,,
4.2,0.35,3682.84,0.00011,0.00008,,,,,,
4.3,0.358,3752.81,0.00012,0.00008,,,,,,
4.4,0.367,3854.19,0.00012,0.00008,,,,,,
4.5,0.375,3956.98,0.00012,0.00008,,,,,,
4.6,0.383,4037.58,0.00012,0.00008,,,,,,
4.7,0.392,4130.75,0.00012,0.00008,,,,,,
4.8,0.4,4228.78,0.00013,0.00008,,,,,,
4.9,0.409,4329.48,0.00013,0.00008,,,,,,
5,0.417,4398.63,0.00013,0.00009,,,,,,
5.1,0.425,4518,0.00013,0.00009,,,,,,
5.2,0.433,4599.16,0.00013,0.00009,,,,,,
5.3,0.442,4703.48,0.00013,0.00009,,,,,,
5.4,0.45,4799.9,0.00013,0.00009,,,,,,
5.5,0.459,4914.69,0.00014,0.00009,,,,,,
5.6,0.467,4994.86,0.00014,0.00009,,,,,,
5.7,0.475,5107.2,0.00014,0.00009,,,,,,
5.8,0.483,5209.24,0.00014,0.00009,,,,,,
5.9,0.492,5312.2,0.00015,0.0001,,,,,,
6,0.5,5402.5,0.00015,0.0001,,,,,,
6.1,0.509,5531.21,0.00015,0.0001,,,,,,
6.2,0.517,5621.6,0.00016,0.0001,,,,,,
6.3,0.525,5728.13,0.00016,0.0001,,,,,,
6.4,0.534,5839.71,0.00017,0.0001,,,,,,
6.5,0.542,5945.49,0.00017,0.0001,,,,,,
6.6,0.55,6052.59,0.00018,0.00011,,,,,,
6.7,0.559,6172.17,0.00019,0.00011,,,,,,
6.8,0.567,6234.87,0.00019,0.00011,,,,,,
6.9,0.575,6364.93,0.0002,0.00011,,,,,,
7,0.583,6460.21,0.0002,0.00012,,,,,,
7.1,0.592,6544.87,0.00021,0.00012,,,,,,
7.2,0.6,6652.14,0.00021,0.00012,,,,,,
7.3,0.608,6767.08,0.00022,0.00012,,,,,,
7.4,0.617,6841.19,0.00022,0.00012,,,,,,
7.5,0.625,6967.07,0.00023,0.00013,,,,,,
7.6,0.634,7063.73,0.00023,0.00013,,,,,,
7.7,0.642,7167.34,0.00024,0.00013,,,,,,
7.8,0.65,7273.32,0.00025,0.00013,,,,,,
7.9,0.658,7372.97,0.00025,0.00013,,,,,,
8,0.667,7470.09,0.00026,0.00014,,,,,,
8.1,0.675,7593.05,0.00027,0.00014,,,,,,
8.2,0.684,7676.27,0.00027,0.00014,,,,,,
8.3,0.692,7803.81,0.00028,0.00014,,,,,,
8.4,0.7,7901.89,0.00029,0.00015,,,,,,
8.5,0.708,8009.96,0.00029,0.00015,,,,,,
8.6,0.717,8120.29,0.0003,0.00015,,,,,,
8.7,0.725,8241.27,0.00031,0.00015,,,,,,
8.8,0.734,8327.53,0.00031,0.00016,,,,,,
8.9,0.742,8463.75,0.00032,0.00016,,,,,,
9,0.75,8551.48,0.00033,0.00016,,,,,,
9.1,0.758,8676.29,0.00033,0.00016,,,,,,
9.2,0.767,8777.87,0.00034,0.00017,,,,,,
9.3,0.775,8899.25,0.00035,0.00017,,,,,,
9.4,0.783,9002.03,0.00036,0.00017,,,,,,
9.5,0.792,9112.5,0.00036,0.00017,,,,,,
9.6,0.8,9225.57,0.00037,0.00017,,,,,,
9.7,0.808,9325.35,0.00038,0.00018,,,,,,
9.8,0.817,9461.29,0.00039,0.00018,,,,,,
9.9,0.825,9559.45,0.00039,0.00018,,,,,,
10,0.833,9681.42,0.0004,0.00019,,,,,,
10.1,0.842,9787.63,0.0004,0.00019,,,,,,
10.2,0.85,9906.13,0.00041,0.00019,,,,,,
10.3,0.859,10026.67,0.00042,0.00019,,,,,,
10.4,0.867,10145.52,0.00043,0.0002,,,,,,
10.5,0.875,10247.66,0.00044,0.0002,,,,,,
10.6,0.883,10372.23,0.00045,0.0002,,,,,,
10.7,0.892,10475.18,0.00045,0.0002,,,,,,
10.8,0.9,10600.92,0.00046,0.00021,,,,,,
10.9,0.909,10733.88,0.00046,0.00021,,,,,,
11,0.917,10831.98,0.00047,0.00021,,,,,,
11.1,0.925,10972.34,0.00048,0.00021,,,,,,
11.2,0.933,11059.06,0.00049,0.00021,,,,,,
11.3,0.942,11184.41,0.00049,0.00022,,,,,,
11.4,0.95,11312.87,0.00051,0.00022,,,,,,
11.5,0.958,11417.22,0.00051,0.00022,,,,,,
11.6,0.967,11561.89,0.00052,0.00023,,,,,,
11.7,0.975,11662.88,0.00053,0.00023,,,,,,
11.8,0.983,11796.88,0.00053,0.00023,,,,,,
11.9,0.992,11900.97,0.00054,0.00023,,,,,,
12,1,12016.76,0.00055,0.00024,,,,,,
12.1,1.009,12153.64,0.00056,0.00024,,,,,,
12.2,1.017,12253.47,0.00057,0.00024,,,,,,
12.3,1.025,12399.17,0.00057,0.00024,,,,,,
12.4,1.034,12513.63,0.00059,0.00025,,,,,,
12.5,1.042,12629.38,0.00059,0.00025,,,,,,
12.6,1.05,12755.3,0.0006,0.00025,,,,,,
12.7,1.058,12869.4,0.0006,0.00026,,,,,,
12.8,1.067,13005.31,0.00061,0.00026,,,,,,
12.9,1.075,13129,0.00062,0.00026,,,,,,
13,1.084,13248.49,0.00063,0.00026,,,,,,
13.1,1.092,13391.01,0.00064,0.00027,,,,,,
13.2,1.1,13501.58,0.00065,0.00027,,,,,,
13.3,1.108,13631.56,0.00065,0.00027,,,,,,
13.4,1.117,13754.86,0.00067,0.00028,,,,,,
13.5,1.125,13861.42,0.00067,0.00028,,,,,,
13.6,1.134,14025.03,0.00069,0.00028,,,,,,
13.7,1.142,14119.26,0.00069,0.00028,,,,,,
13.8,1.15,14261.12,0.0007,0.00029,,,,,,
13.9,1.158,14381.55,0.00071,0.00029,,,,,,
14,1.167,14509.52,0.00072,0.00029,,,,,,
14.1,1.175,14660.17,0.00073,0.0003,,,,,,
14.2,1.184,14753.23,0.00073,0.0003,,,,,,
14.3,1.192,14903.27,0.00074,0.0003,,,,,,
14.4,1.2,15010.83,0.00075,0.00031,,,,,,
14.5,1.209,15146.14,0.00076,0.00031,,,,,,
14.6,1.217,15281.77,0.00077,0.00031,,,,,,
14.7,1.225,15403.53,0.00078,0.00032,,,,,,
14.8,1.233,15525.05,0.00079,0.00032,,,,,,
14.9,1.242,15675.09,0.0008,0.00032,,,,,,
15,1.25,15800.23,0.00081,0.00033,,,,,,
15.1,1.259,15922.98,0.00081,0.00033,,,,,,
15.2,1.267,16073.27,0.00082,0.00034,,,,,,
15.3,1.275,16192.77,0.00083,0.00034,,,,,,
15.4,1.284,16339.45,0.00084,0.00034,,,,,,
15.5,1.292,16467.99,0.00085,0.00035,,,,,,
15.6,1.3,16598.13,0.00086,0.00035,,,,,,
15.7,1.308,16749.75,0.00088,0.00035,,,,,,
15.8,1.317,16883.25,0.00088,0.00036,,,,,,
15.9,1.325,17003.9,0.00089,0.00036,,,,,,
16,1.333,17155.96,0.0009,0.00037,,,,,,
16.1,1.342,17277.03,0.00091,0.00037,,,,,,
16.2,1.35,17412.08,0.00092,0.00037,,,,,,
16.3,1.359,17555.17,0.00093,0.00038,,,,,,
16.4,1.367,17690.55,0.00094,0.00038,,,,,,
16.5,1.375,17800.93,0.00095,0.00038,,,,,,
16.6,1.383,17976.45,0.00096,0.00039,,,,,,
16.7,1.392,18085.3,0.00097,0.00039,,,,,,
16.8,1.4,18234.78,0.00098,0.0004,,,,,,
16.9,1.408,18368.21,0.00099,0.0004,,,,,,
17,1.417,18505.87,0.001,0.0004,,,,,,
17.1,1.425,18623.4,0.00101,0.00041,,,,,,
17.2,1.434,18794.74,0.00102,0.00041,,,,,,
17.3,1.442,18907.44,0.00103,0.00041,,,,,,
17.4,1.45,19041.21,0.00104,0.00042,,,,,,
17.5,1.459,19198.98,0.00105,0.00042,,,,,,
17.6,1.467,19317.28,0.00106,0.00043,,,,,,
17.7,1.475,19456.41,0.00107,0.00043,,,,,,
17.8,1.484,19614.58,0.00108,0.00044,,,,,,
17.9,1.492,19742.04,0.0011,0.00044,,,,,,
18,1.5,19872.72,0.0011,0.00045,,,,,,
18.1,1.508,20034.12,0.00112,0.00045,,,,,,
18.2,1.517,20156.72,0.00113,0.00046,,,,,,
18.3,1.525,20297.59,0.00114,0.00046,,,,,,
18.4,1.534,20453.41,0.00115,0.00047,,,,,,
18.5,1.542,20578.52,0.00116,0.00047,,,,,,
18.6,1.55,20712.15,0.00117,0.00048,,,,,,
18.7,1.558,20862.72,0.00118,0.00048,,,,,,
18.8,1.567,21001.58,0.00119,0.00048,,,,,,
18.9,1.575,21133.73,0.0012,0.00049,,,,,,
19,1.584,21287.32,0.00121,0.00049,,,,,,
19.1,1.592,21415.5,0.00122,0.0005,,,,,,
19.2,1.6,21556.82,0.00124,0.0005,,,,,,
19.3,1.608,21700.9,0.00125,0.00051,,,,,,
19.4,1.617,21849.46,0.00126,0.00051,,,,,,
19.5,1.625,21977.65,0.00127,0.00052,,,,,,
19.6,1.634,22119.48,0.00128,0.00052,,,,,,
19.7,1.642,22264.32,0.00129,0.00053,,,,,,
19.8,1.65,22403.27,0.0013,0.00053,,,,,,
19.9,1.658,22538.89,0.00132,0.00053,,,,,,
20,1.667,22688.56,0.00133,0.00054,,,,,,
20.1,1.675,22832.23,0.00134,0.00054,,,,,,
20.2,1.683,22954.41,0.00135,0.00055,,,,,,
20.3,1.692,23120.36,0.00136,0.00055,,,,,,
20.4,1.7,23252.94,0.00137,0.00056,,,,,,
20.5,1.709,23387.18,0.00138,0.00056,,,,,,
20.6,1.717,23544.13,0.0014,0.00057,,,,,,
20.7,1.725,23687.06,0.00141,0.00057,,,,,,
20.8,1.733,23803.22,0.00142,0.00058,,,,,,
20.9,1.742,23969.33,0.00143,0.00059,,,,,,
21,1.75,24114.1,0.00145,0.00059,,,,,,
21.1,1.758,24242.98,0.00146,0.0006,,,,,,
21.2,1.767,24390.54,0.00147,0.0006,,,,,,
21.3,1.775,24542.62,0.00148,0.00061,,,,,,
21.4,1.783,24672.75,0.00149,0.00061,,,,,,
21.5,1.792,24811.29,0.00151,0.00062,,,,,,
21.6,1.8,24969.48,0.00152,0.00062,,,,,,
21.7,1.809,25088.04,0.00153,0.00063,,,,,,
21.8,1.817,25237.07,0.00154,0.00064,,,,,,
21.9,1.825,25388.58,0.00156,0.00064,,,,,,
22,1.833,25524.31,0.00157,0.00065,,,,,,
22.1,1.842,25652.02,0.00158,0.00065,,,,,,
22.2,1.85,25823.54,0.0016,0.00066,,,,,,
22.3,1.858,25950.86,0.00161,0.00066,,,,,,
22.4,1.867,26090.98,0.00162,0.00067,,,,,,
22.5,1.875,26231.07,0.00163,0.00067,,,,,,
22.6,1.883,26393.09,0.00165,0.00068,,,,,,
22.7,1.892,26519.71,0.00166,0.00069,,,,,,
22.8,1.9,26665.79,0.00168,0.00069,,,,,,
22.9,1.908,26806.49,0.00169,0.0007,,,,,,
23,1.917,26957.11,0.0017,0.00071,,,,,,
23.1,1.925,27082.71,0.00172,0.00071,,,,,,
23.2,1.933,27249.57,0.00173,0.00072,,,,,,
23.3,1.942,27376.59,0.00174,0.00072,,,,,,
23.4,1.95,27522.01,0.00176,0.00073,,,,,,
23.5,1.958,27674.84,0.00177,0.00074,,,,,,
23.6,1.967,27814.57,0.00179,0.00075,,,,,,
23.7,1.975,27939.68,0.0018,0.00075,,,,,,
23.8,1.984,28102.08,0.00182,0.00076,,,,,,
23.9,1.992,28241.92,0.00183,0.00077,,,,,,
24,2,28376.99,0.00184,0.00077,,,,,,
24.1,2.008,28515.47,0.00186,0.00078,,,,,,
24.2,2.017,28677,0.00187,0.00079,,,,,,
24.3,2.025,28812.63,0.00189,0.00079,,,,,,
24.4,2.034,28949.27,0.0019,0.0008,,,,,,
24.5,2.042,29097.16,0.00191,0.00081,,,,,,
24.6,2.05,29239.11,0.00193,0.00082,,,,,,
24.7,2.058,29368.79,0.00194,0.00082,,,,,,
24.8,2.067,29536.57,0.00196,0.00083,,,,,,
24.9,2.075,29654.28,0.00197,0.00084,,,,,,
25,2.083,29797.83,0.00199,0.00085,,,,,,
25.1,2.092,29941.05,0.00201,0.00085,,,,,,
25.2,2.1,30094.41,0.00202,0.00086,,,,,,
25.3,2.108,30216.56,0.00204,0.00087,,,,,,
25.4,2.117,30384.92,0.00205,0.00088,,,,,,
25.5,2.125,30512.91,0.00207,0.00089,,,,,,
25.6,2.133,30663.28,0.00209,0.0009,,,,,,
25.7,2.142,30791.62,0.0021,0.0009,,,,,,
25.8,2.15,30963.01,0.00212,0.00091,,,,,,
25.9,2.159,31078.86,0.00214,0.00092,,,,,,
26,2.167,31230.15,0.00215,0.00093,,,,,,
26.1,2.175,31371.66,0.00217,0.00094,,,,,,
26.2,2.183,31508.03,0.00218,0.00095,,,,,,
26.3,2.192,31632.88,0.0022,0.00096,,,,,,
26.4,2.2,31801.88,0.00222,0.00097,,,,,,
26.5,2.209,31920.52,0.00224,0.00098,,,,,,
26.6,2.217,32050.54,0.00225,0.00098,,,,,,
26.7,2.225,32207.34,0.00227,0.00099,,,,,,
26.8,2.233,32338.54,0.00229,0.001,,,,,,
26.9,2.242,32461.12,0.00231,0.00101,,,,,,
27,2.25,32625.75,0.00232,0.00102,,,,,,
27.1,2.259,32745.34,0.00234,0.00103,,,,,,
27.2,2.267,32875.05,0.00236,0.00104,,,,,,
27.3,2.275,33018.89,0.00238,0.00105,,,,,,
27.4,2.283,33155.64,0.00239,0.00106,,,,,,
27.5,2.292,33275.48,0.00241,0.00107,,,,,,
27.6,2.3,33442.07,0.00243,0.00108,,,,,,
27.7,2.309,33549.5,0.00245,0.00109,,,,,,
27.8,2.317,33689.19,0.00247,0.0011,,,,,,
27.9,2.325,33827.39,0.00249,0.00112,,,,,,
28,2.334,33966.68,0.0025,0.00112,,,,,,
28.1,2.342,34089.8,0.00253,0.00114,,,,,,
28.2,2.35,34225.33,0.00255,0.00115,,,,,,
28.3,2.358,34353.85,0.00256,0.00116,,,,,,
28.4,2.367,34489.72,0.00259,0.00117,,,,,,
28.5,2.375,34629.74,0.00261,0.00118,,,,,,
28.6,2.383,34741.21,0.00263,0.00119,,,,,,
28.7,2.392,34904.41,0.00265,0.00121,,,,,,
28.8,2.4,35014.11,0.00267,0.00122,,,,,,
28.9,2.408,35148.18,0.0027,0.00123,,,,,,
29,2.417,35281.3,0.00272,0.00124,,,,,,
29.1,2.425,35402.46,0.00274,0.00126,,,,,,
29.2,2.434,35531.22,0.00276,0.00127,,,,,,
29.3,2.442,35658.81,0.00278,0.00128,,,,,,
29.4,2.45,35775.57,0.0028,0.00129,,,,,,
29.5,2.458,35924.67,0.00283,0.00131,,,,,,
29.6,2.467,36042.39,0.00285,0.00132,,,,,,
29.7,2.475,36158,0.00288,0.00133,,,,,,
29.8,2.484,36300.5,0.0029,0.00135,,,,,,
29.9,2.492,36405.65,0.00293,0.00136,,,,,,
30,2.5,36551.87,0.00295,0.00138,,,,,,
30.1,2.508,36659.05,0.00297,0.00139,,,,,,
30.2,2.517,36784.3,0.003,0.0014,,,,,,
30.3,2.525,36907.79,0.00302,0.00141,,,,,,
30.4,2.534,37021.81,0.00305,0.00143,,,,,,
30.5,2.542,37161.76,0.00307,0.00145,,,,,,
30.6,2.55,37276.12,0.0031,0.00146,,,,,,
30.7,2.559,37398.11,0.00313,0.00148,,,,,,
30.8,2.567,37504.44,0.00315,0.00149,,,,,,
30.9,2.575,37633.98,0.00318,0.00151,,,,,,
31,2.583,37763.67,0.00321,0.00152,,,,,,
31.1,2.592,37873.85,0.00324,0.00154,,,,,,
31.2,2.6,38007.8,0.00327,0.00156,,,,,,
31.3,2.609,38106.94,0.0033,0.00157,,,,,,
31.4,2.617,38231.85,0.00333,0.00159,,,,,,
31.5,2.625,38333.03,0.00336,0.00161,,,,,,
31.6,2.633,38447.48,0.00339,0.00163,,,,,,
31.7,2.642,38578,0.00341,0.00164,,,,,,
31.8,2.65,38674.08,0.00345,0.00166,,,,,,
31.9,2.659,38823.1,0.00348,0.00168,,,,,,
32,2.667,38908.5,0.00351,0.0017,,,,,,
32.1,2.675,39025.5,0.00354,0.00172,,,,,,
32.2,2.684,39139.47,0.00357,0.00174,,,,,,
32.3,2.692,39247.17,0.0036,0.00176,,,,,,
32.4,2.7,39356.7,0.00363,0.00178,,,,,,
32.5,2.709,39456.37,0.00367,0.0018,,,,,,
32.6,2.717,39564.16,0.0037,0.00182,,,,,,
32.7,2.725,39671.75,0.00374,0.00184,,,,,,
32.8,2.733,39776.37,0.00377,0.00186,,,,,,
32.9,2.742,39883.28,0.00381,0.00188,,,,,,
33,2.75,39992.46,0.00384,0.0019,,,,,,
33.1,2.758,40084.34,0.00388,0.00193,,,,,,
33.2,2.767,40199.07,0.00392,0.00195,,,,,,
33.3,2.775,40291.16,0.00395,0.00197,,,,,,
33.4,2.784,40391.98,0.00399,0.002,,,,,,
33.5,2.792,40497.49,0.00403,0.00202,,,,,,
33.6,2.8,40599.05,0.00407,0.00204,,,,,,
33.7,2.809,40694.43,0.00411,0.00207,,,,,,
33.8,2.817,40795.04,0.00415,0.0021,,,,,,
33.9,2.825,40892.45,0.00419,0.00212,,,,,,
34,2.834,40991.04,0.00424,0.00215,,,,,,
34.1,2.842,41093.08,0.00428,0.00218,,,,,,
34.2,2.85,41160.76,0.00432,0.0022,,,,,,
34.3,2.858,41265.48,0.00436,0.00223,,,,,,
34.4,2.867,41346,0.00441,0.00226,,,,,,
34.5,2.875,41435.42,0.00445,0.00229,,,,,,
34.6,2.884,41528.29,0.0045,0.00232,,,,,,
34.7,2.892,41619.89,0.00455,0.00235,,,,,,
34.8,2.9,41712.79,0.00459,0.00238,,,,,,
34.9,2.908,41776.66,0.00464,0.00241,,,,,,
35,2.917,41884.54,0.00469,0.00244,,,,,,
35.1,2.925,41949.16,0.00474,0.00247,,,,,,
35.2,2.933,42029.5,0.00479,0.00251,,,,,,
35.3,2.942,42133.45,0.00485,0.00254,,,,,,
35.4,2.95,42190.52,0.0049,0.00257,,,,,,
35.5,2.959,42273.14,0.00495,0.00261,,,,,,
35.6,2.967,42342.44,0.005,0.00264,,,,,,
35.7,2.975,42432.97,0.00506,0.00268,,,,,,
35.8,2.983,42511.89,0.00511,0.00272,,,,,,
35.9,2.992,42561.56,0.00517,0.00275,,,,,,
36,3,42640.74,0.00523,0.00279,,,,,,
36.1,3.008,42733.21,0.00528,0.00283,,,,,,
36.2,3.017,42778.34,0.00535,0.00287,,,,,,
36.3,3.025,42853.05,0.0054,0.00291,,,,,,
36.4,3.033,42926.3,0.00546,0.00295,,,,,,
36.5,3.042,42972.11,0.00552,0.00299,,,,,,
36.6,3.05,43060.11,0.00559,0.00303,,,,,,
36.7,3.059,43118.85,0.00565,0.00307,,,,,,
36.8,3.067,43167.79,0.00571,0.00311,,,,,,
36.9,3.075,43220.97,0.00578,0.00315,,,,,,
37,3.084,43286.76,0.00585,0.0032,,,,,,
37.1,3.092,43365.43,0.00591,0.00324,,,,,,
37.2,3.1,43389.12,0.00598,0.00329,,,,,,
37.3,3.108,43459.23,0.00605,0.00333,,,,,,
37.4,3.117,43521.9,0.00613,0.00338,,,,,,
37.5,3.125,43571.1,0.0062,0.00342,,,,,,
37.6,3.133,43606.1,0.00627,0.00347,,,,,,
37.7,3.142,43669.27,0.00634,0.00352,,,,,,
37.8,3.15,43714.6,0.00641,0.00357,,,,,,
37.9,3.159,43773.37,0.00649,0.00361,,,,,,
38,3.167,43803.62,0.00656,0.00366,,,,,,
38.1,3.175,43847.86,0.00664,0.00371,,,,,,
38.2,3.184,43903.38,0.00671,0.00376,,,,,,
38.3,3.192,43962.12,0.00679,0.00382,,,,,,
38.4,3.2,43990.08,0.00687,0.00387,,,,,,
38.5,3.208,44016.48,0.00694,0.00392,,,,,,
38.6,3.217,44071.28,0.00702,0.00397,,,,,,
38.7,3.225,44109.54,0.00711,0.00402,,,,,,
38.8,3.234,44160.15,0.00719,0.00408,,,,,,
38.9,3.242,44194.27,0.00728,0.00413,,,,,,
39,3.25,44215.43,0.00736,0.00419,,,,,,
39.1,3.258,44256.98,0.00745,0.00424,,,,,,
39.2,3.267,44302.12,0.00754,0.0043,,,,,,
39.3,3.275,44329.39,0.00762,0.00435,,,,,,
39.4,3.283,44376.47,0.00772,0.00441,,,,,,
39.5,3.292,44410.82,0.0078,0.00446,,,,,,
39.6,3.3,44422.49,0.0079,0.00452,,,,,,
39.7,3.308,44447.9,0.00798,0.00458,,,,,,
39.8,3.317,44481.29,0.00808,0.00464,,,,,,
39.9,3.325,44514.47,0.00817,0.0047,,,,,,
40,3.334,44549.86,0.00826,0.00476,,,,,,
40.1,3.342,44588.16,0.00836,0.00481,,,,,,
40.2,3.35,44604.78,0.00845,0.00487,,,,,,
40.3,3.358,44618.6,0.00855,0.00493,,,,,,
40.4,3.367,44650.89,0.00865,0.00499,,,,,,
40.5,3.375,44681.73,0.00874,0.00505,,,,,,
40.6,3.384,44716.02,0.00884,0.00512,,,,,,
40.7,3.392,44731.84,0.00895,0.00518,,,,,,
40.8,3.4,44758.1,0.00905,0.00524,,,,,,
40.9,3.409,44778.67,0.00915,0.0053,,,,,,
41,3.417,44802.47,0.00925,0.00536,,,,,,
41.1,3.425,44821.32,0.00935,0.00542,,,,,,
41.2,3.434,44830.84,0.00946,0.00549,,,,,,
41.3,3.442,44856.6,0.00957,0.00555,,,,,,
41.4,3.45,44879,0.00967,0.00561,,,,,,
41.5,3.459,44903.81,0.00978,0.00568,,,,,,
41.6,3.467,44927.6,0.00989,0.00574,,,,,,
41.7,3.475,44940.11,0.01,0.00581,,,,,,
41.8,3.483,44963.45,0.01012,0.00588,,,,,,
41.9,3.492,44989.52,0.01023,0.00594,,,,,,
42,3.5,45011.95,0.01034,0.00601,,,,,,
42.1,3.508,45022.33,0.01045,0.00607,,,,,,
42.2,3.517,45026.7,0.01056,0.00613,,,,,,
42.3,3.525,45039.65,0.01067,0.0062,,,,,,
42.4,3.533,45044.85,0.01079,0.00626,,,,,,
42.5,3.542,45053.8,0.0109,0.00633,,,,,,
42.6,3.55,45071.11,0.01102,0.0064,,,,,,
42.7,3.559,45088.56,0.01114,0.00646,,,,,,
42.8,3.567,45106.43,0.01126,0.00653,,,,,,
42.9,3.575,45121.29,0.01137,0.00659,,,,,,
43,3.583,45130.55,0.01149,0.00666,,,,,,
43.1,3.592,45149.39,0.0116,0.00672,,,,,,
43.2,3.6,45169.7,0.01173,0.00679,,,,,,
43.3,3.609,45186.2,0.01185,0.00685,,,,,,
43.4,3.617,45193.7,0.01196,0.00692,,,,,,
43.5,3.625,45205.89,0.01209,0.00699,,,,,,
43.6,3.634,45223.77,0.01221,0.00706,,,,,,
43.7,3.642,45233.02,0.01233,0.00712,,,,,,
43.8,3.65,45241.31,0.01246,0.00719,,,,,,
43.9,3.658,45244.61,0.01259,0.00726,,,,,,
44,3.667,45247.38,0.01271,0.00733,,,,,,
44.1,3.675,45253.33,0.01283,0.0074,,,,,,
44.2,3.684,45260.43,0.01296,0.00746,,,,,,
44.3,3.692,45271.38,0.01308,0.00753,,,,,,
44.4,3.7,45288.19,0.01321,0.0076,,,,,,
44.5,3.708,45292.9,0.01334,0.00767,,,,,,
44.6,3.717,45306.44,0.01347,0.00774,,,,,,
44.7,3.725,45313.8,0.01359,0.0078,,,,,,
44.8,3.733,45318.07,0.01372,0.00787,,,,,,
44.9,3.742,45331.23,0.01385,0.00794,,,,,,
45,3.75,45336.06,0.01397,0.00801,,,,,,
45.1,3.758,45339.03,0.01411,0.00807,,,,,,
45.2,3.767,45348.81,0.01424,0.00814,,,,,,
45.3,3.775,45355.54,0.01437,0.00821,,,,,,
45.4,3.784,45362.99,0.0145,0.00828,,,,,,
45.5,3.792,45371.56,0.01463,0.00835,,,,,,
45.6,3.8,45372.86,0.01476,0.00842,,,,,,
45.7,3.808,45385.37,0.0149,0.00849,,,,,,
45.8,3.817,45391.32,0.01503,0.00856,,,,,,
45.9,3.825,45394.97,0.01516,0.00863,,,,,,
46,3.834,45399.09,0.0153,0.00869,,,,,,
46.1,3.842,45405.06,0.01543,0.00876,,,,,,
46.2,3.85,45418.95,0.01557,0.00883,,,,,,
46.3,3.859,45424.26,0.01571,0.0089,,,,,,
46.4,3.867,45427.34,0.01583,0.00897,,,,,,
46.5,3.875,45433.03,0.01597,0.00904,,,,,,
46.6,3.884,45433.7,0.01611,0.00911,,,,,,
46.7,3.892,45436.19,0.01625,0.00918,,,,,,
46.8,3.9,45436.83,0.01638,0.00925,,,,,,
46.9,3.909,45439.55,0.01652,0.00932,,,,,,
47,3.917,45443.62,0.01666,0.00939,,,,,,
47.1,3.925,45446.64,0.0168,0.00946,,,,,,
47.2,3.933,45443.76,0.01694,0.00952,,,,,,
47.3,3.942,45446.56,0.01708,0.00959,,,,,,
47.4,3.95,45451.78,0.01722,0.00966,,,,,,
47.5,3.959,45456.52,0.01736,0.00973,,,,,,
47.6,3.967,45456.19,0.01749,0.0098,,,,,,
47.7,3.975,45456.41,0.01763,0.00987,,,,,,
47.8,3.984,45461.45,0.01777,0.00994,,,,,,
47.9,3.992,45462.98,0.01791,0.01001,,,,,,
48,4,45467.45,0.01805,0.01008,,,,,,
48.1,4.009,45471.02,0.01819,0.01015,,,,,,
48.2,4.017,45468.91,0.01834,0.01022,,,,,,
48.3,4.025,45470.93,0.01848,0.01029,,,,,,
48.4,4.034,45475.88,0.01862,0.01036,,,,,,
48.5,4.042,45482.44,0.01876,0.01043,,,,,,
48.6,4.05,45479.75,0.0189,0.0105,,,,,,
48.7,4.059,45484.79,0.01905,0.01057,,,,,,
48.8,4.067,45489.96,0.01919,0.01063,,,,,,
48.9,4.075,45489.46,0.01934,0.0107,,,,,,
49,4.083,45491.86,0.01948,0.01077,,,,,,
49.1,4.092,45495.74,0.01963,0.01084,,,,,,
49.2,4.1,45493.34,0.01977,0.01091,,,,,,
49.3,4.108,45492.11,0.01992,0.01098,,,,,,
49.4,4.117,45491.66,0.02007,0.01105,,,,,,
49.5,4.125,45495.7,0.02021,0.01112,,,,,,
49.6,4.134,45495.71,0.02036,0.01119,,,,,,
49.7,4.142,45495.96,0.02051,0.01126,,,,,,
49.8,4.15,45493.19,0.02065,0.01132,,,,,,
49.9,4.158,45495.52,0.0208,0.0114,,,,,,
50,4.167,45493.61,0.02095,0.01146,,,,,,
50.1,4.175,45494.32,0.0211,0.01153,,,,,,
50.2,4.184,45496.08,0.02125,0.0116,,,,,,
50.3,4.192,45492.33,0.0214,0.01167,,,,,,
50.4,4.2,45489.85,0.02154,0.01174,,,,,,
50.5,4.208,45490.68,0.02169,0.0118,,,,,,
50.6,4.217,45492.91,0.02184,0.01187,,,,,,
50.7,4.225,45486.72,0.02198,0.01194,,,,,,
50.8,4.234,45484.62,0.02213,0.012,,,,,,
50.9,4.242,45486.51,0.02228,0.01207,,,,,,
51,4.25,45490.15,0.02244,0.01214,,,,,,
51.1,4.259,45484.57,0.02259,0.01221,,,,,,
51.2,4.267,45484.04,0.02274,0.01227,,,,,,
51.3,4.275,45483.86,0.02289,0.01234,,,,,,
51.4,4.284,45481.36,0.02304,0.01241,,,,,,
51.5,4.292,45474.53,0.02319,0.01247,,,,,,
51.6,4.3,45473.46,0.02335,0.01254,,,,,,
51.7,4.309,45478.8,0.0235,0.01261,,,,,,
51.8,4.317,45471.02,0.02366,0.01267,,,,,,
51.9,4.325,45465.48,0.02381,0.01274,,,,,,
52,4.333,45464.21,0.02396,0.0128,,,,,,
52.1,4.342,45465.36,0.02412,0.01287,,,,,,
52.2,4.35,45464.75,0.02427,0.01293,,,,,,
52.3,4.359,45461.72,0.02443,0.013,,,,,,
52.4,4.367,45453.6,0.02458,0.01307,,,,,,
52.5,4.375,45452.66,0.02473,0.01313,,,,,,
52.6,4.384,45451.39,0.02489,0.01319,,,,,,
52.7,4.392,45449.4,0.02504,0.01326,,,,,,
52.8,4.4,45446.83,0.0252,0.01332,,,,,,
52.9,4.409,45445.82,0.02535,0.01339,,,,,,
53,4.417,45446.49,0.02551,0.01345,,,,,,
53.1,4.425,45439,0.02567,0.01352,,,,,,
53.2,4.434,45437.3,0.02582,0.01358,,,,,,
53.3,4.442,45437.97,0.02598,0.01364,,,,,,
53.4,4.45,45436.94,0.02613,0.0137,,,,,,
53.5,4.459,45436.23,0.02629,0.01377,,,,,,
53.6,4.467,45433.54,0.02645,0.01383,,,,,,
53.7,4.475,45430.88,0.02661,0.01389,,,,,,
53.8,4.484,45432.88,0.02676,0.01395,,,,,,
53.9,4.492,45429.56,0.02692,0.01402,,,,,,
54,4.5,45426.11,0.02708,0.01408,,,,,,
54.1,4.509,45426.16,0.02724,0.01414,,,,,,
54.2,4.517,45415.75,0.0274,0.0142,,,,,,
54.3,4.525,45413.02,0.02756,0.01426,,,,,,
54.4,4.534,45412.57,0.02772,0.01432,,,,,,
54.5,4.542,45400.42,0.02788,0.01438,,,,,,
54.6,4.55,45393.86,0.02804,0.01444,,,,,,
54.7,4.559,45391.62,0.0282,0.0145,,,,,,
54.8,4.567,45383.67,0.02836,0.01456,,,,,,
54.9,4.575,45381.45,0.02852,0.01462,,,,,,
55,4.584,45378.3,0.02869,0.01468,,,,,,
55.1,4.592,45373.52,0.02885,0.01474,,,,,,
55.2,4.6,45362.99,0.02901,0.0148,,,,,,
55.3,4.608,45357.64,0.02917,0.01486,,,,,,
55.4,4.617,45360.33,0.02933,0.01491,,,,,,
55.5,4.625,45353.26,0.02949,0.01497,,,,,,
55.6,4.634,45344.23,0.02965,0.01503,,,,,,
55.7,4.642,45342.88,0.02982,0.01508,,,,,,
55.8,4.65,45340.14,0.02998,0.01514,,,,,,
55.9,4.659,45336.01,0.03014,0.0152,,,,,,
56,4.667,45333.29,0.0303,0.01525,,,,,,
56.1,4.675,45328.71,0.03046,0.0153,,,,,,
56.2,4.683,45323.97,0.03063,0.01536,,,,,,
56.3,4.692,45321.27,0.0308,0.01541,,,,,,
56.4,4.7,45309.4,0.03096,0.01547,,,,,,
56.5,4.708,45299.9,0.03112,0.01552,,,,,,
56.6,4.717,45299.38,0.03128,0.01558,,,,,,
56.7,4.725,45295.41,0.03145,0.01563,,,,,,
56.8,4.733,45283.6,0.03162,0.01568,,,,,,
56.9,4.742,45274.23,0.03178,0.01573,,,,,,
57,4.75,45266.05,0.03195,0.01578,,,,,,
57.1,4.759,45259.19,0.03212,0.01584,,,,,,
57.2,4.767,45254.08,0.03228,0.01589,,,,,,
57.3,4.775,45247.75,0.03245,0.01594,,,,,,
57.4,4.783,45245.52,0.03261,0.01599,,,,,,
57.5,4.792,45246.55,0.03278,0.01604,,,,,,
57.6,4.8,45244.41,0.03295,0.01608,,,,,,
57.7,4.808,45238.27,0.03311,0.01613,,,,,,
57.8,4.817,45234.67,0.03328,0.01618,,,,,,
57.9,4.825,45230,0.03345,0.01623,,,,,,
58,4.833,45217.6,0.03361,0.01627,,,,,,
58.1,4.842,45216.08,0.03378,0.01632,,,,,,
58.2,4.85,45214.16,0.03395,0.01636,,,,,,
58.3,4.858,45197.49,0.03411,0.01641,,,,,,
58.4,4.867,45192.28,0.03428,0.01645,,,,,,
58.5,4.875,45187.4,0.03445,0.0165,,,,,,
58.6,4.883,45177.81,0.03462,0.01654,,,,,,
58.7,4.892,45175.85,0.03479,0.01658,,,,,,
58.8,4.9,45161.05,0.03496,0.01663,,,,,,
58.9,4.909,45148.37,0.03513,0.01667,,,,,,
59,4.917,45135.2,0.03529,0.01671,,,,,,
59.1,4.925,45127.75,0.03546,0.01675,,,,,,
59.2,4.934,45125.66,0.03562,0.01679,,,,,,
59.3,4.942,45123.5,0.0358,0.01683,,,,,,
59.4,4.95,45109.53,0.03597,0.01687,,,,,,
59.5,4.959,45096.95,0.03614,0.01691,,,,,,
59.6,4.967,45092.48,0.03631,0.01694,,,,,,
59.7,4.975,45077.59,0.03648,0.01698,,,,,,
59.8,4.984,45071.99,0.03666,0.01702,,,,,,
59.9,4.992,45058.67,0.03683,0.01706,,,,,,
60,5,45047.84,0.037,0.01709,,,,,,
60.1,5.009,45043.16,0.03717,0.01712,,,,,,
60.2,5.017,45036.75,0.03733,0.01716,,,,,,
60.3,5.025,45036.02,0.0375,0.01719,,,,,,
60.4,5.034,45028.76,0.03768,0.01723,,,,,,
60.5,5.042,45026.4,0.03785,0.01726,,,,,,
60.6,5.05,45026,0.03802,0.01729,,,,,,
60.7,5.058,45021.67,0.03819,0.01732,,,,,,
60.8,5.067,45010.68,0.03836,0.01735,,,,,,
60.9,5.075,45003.38,0.03853,0.01738,,,,,,
61,5.084,44993.38,0.0387,0.01741,,,,,,
61.1,5.092,44973.76,0.03888,0.01744,,,,,,
61.2,5.1,44957.16,0.03905,0.01747,,,,,,
61.3,5.109,44949.93,0.03922,0.0175,,,,,,
61.4,5.117,44940.12,0.03939,0.01752,,,,,,
61.5,5.125,44933.71,0.03956,0.01755,,,,,,
61.6,5.134,44921.92,0.03973,0.01758,,,,,,
61.7,5.142,44909.46,0.0399,0.0176,,,,,,
61.8,5.15,44898.04,0.04006,0.01762,,,,,,
61.9,5.159,44890,0.04024,0.01765,,,,,,
62,5.167,44877.08,0.04041,0.01767,,,,,,
62.1,5.175,44867.15,0.04058,0.0177,,,,,,
62.2,5.184,44853.01,0.04076,0.01772,,,,,,
62.3,5.192,44841.15,0.04093,0.01774,,,,,,
62.4,5.2,44828.55,0.0411,0.01776,,,,,,
62.5,5.209,44822.87,0.04127,0.01778,,,,,,
62.6,5.217,44820.62,0.04144,0.0178,,,,,,
62.7,5.225,44814.39,0.04161,0.01782,,,,,,
62.8,5.233,44801.35,0.04178,0.01784,,,,,,
62.9,5.242,44794.39,0.04196,0.01786,,,,,,
63,5.25,44779.98,0.04213,0.01788,,,,,,
63.1,5.259,44771.04,0.0423,0.0179,,,,,,
63.2,5.267,44759.59,0.04247,0.01791,,,,,,
63.3,5.275,44743.77,0.04264,0.01793,,,,,,
63.4,5.283,44730.24,0.04281,0.01795,,,,,,
63.5,5.292,44725.04,0.04299,0.01796,,,,,,
63.6,5.3,44716.49,0.04317,0.01798,,,,,,
63.7,5.309,44704.09,0.04333,0.01799,,,,,,
63.8,5.317,44685.63,0.0435,0.01801,,,,,,
63.9,5.325,44667.62,0.04368,0.01802,,,,,,
64,5.334,44659.96,0.04386,0.01803,,,,,,
64.1,5.342,44641.99,0.04403,0.01805,,,,,,
64.2,5.35,44625.11,0.0442,0.01806,,,,,,
64.3,5.359,44617.22,0.04437,0.01807,,,,,,
64.4,5.367,44608.64,0.04455,0.01809,,,,,,
64.5,5.375,44604.44,0.04472,0.0181,,,,,,
64.6,5.384,44600.22,0.04489,0.01811,,,,,,
64.7,5.392,44590.91,0.04507,0.01812,,,,,,
64.8,5.4,44582.54,0.04524,0.01813,,,,,,
64.9,5.409,44562.3,0.04541,0.01814,,,,,,
65,5.417,44542.35,0.04559,0.01815,,,,,,
65.1,5.425,44523.01,0.04576,0.01816,,,,,,
65.2,5.433,44512.38,0.04593,0.01817,,,,,,
65.3,5.442,44504.03,0.04611,0.01818,,,,,,
65.4,5.45,44484.64,0.04628,0.01819,,,,,,
65.5,5.458,44459.71,0.04644,0.0182,,,,,,
65.6,5.467,44455.07,0.04662,0.01821,,,,,,
65.7,5.475,44448.27,0.0468,0.01821,,,,,,
65.8,5.484,44434.13,0.04697,0.01822,,,,,,
65.9,5.492,44421.66,0.04714,0.01823,,,,,,
66,5.5,44414.68,0.04731,0.01824,,,,,,
66.1,5.509,44411.72,0.04748,0.01824,,,,,,
66.2,5.517,44405.19,0.04765,0.01825,,,,,,
66.3,5.525,44393.47,0.04782,0.01825,,,,,,
66.4,5.534,44372.14,0.04799,0.01826,,,,,,
66.5,5.542,44356.05,0.04817,0.01826,,,,,,
66.6,5.55,44336.99,0.04834,0.01827,,,,,,
66.7,5.559,44314.3,0.0485,0.01827,,,,,,
66.8,5.567,44305.96,0.04868,0.01828,,,,,,
66.9,5.575,44302.33,0.04885,0.01829,,,,,,
67,5.584,44289.41,0.04903,0.01829,,,,,,
67.1,5.592,44267.76,0.0492,0.01829,,,,,,
67.2,5.6,44254.71,0.04937,0.0183,,,,,,
67.3,5.609,44245.39,0.04955,0.0183,,,,,,
67.4,5.617,44219.03,0.04972,0.01831,,,,,,
67.5,5.625,44209.74,0.0499,0.01831,,,,,,
67.6,5.633,44200.69,0.05008,0.01832,,,,,,
67.7,5.642,44191.52,0.05025,0.01832,,,,,,
67.8,5.65,44183.21,0.05042,0.01832,,,,,,
67.9,5.659,44176.18,0.05059,0.01832,,,,,,
68,5.667,44154.93,0.05077,0.01833,,,,,,
68.1,5.675,44133.64,0.05095,0.01833,,,,,,
68.2,5.684,44121.99,0.05112,0.01833,,,,,,
68.3,5.692,44105.62,0.0513,0.01834,,,,,,
68.4,5.7,44101.08,0.05148,0.01834,,,,,,
68.5,5.709,44079.48,0.05166,0.01834,,,,,,
68.6,5.717,44049.89,0.05184,0.01834,,,,,,
68.7,5.725,44031.11,0.05201,0.01835,,,,,,
68.8,5.733,44018.39,0.05219,0.01835,,,,,,
68.9,5.742,44008.84,0.05237,0.01835,,,,,,
69,5.75,43997.75,0.05255,0.01835,,,,,,
69.1,5.759,43990.39,0.05274,0.01835,,,,,,
69.2,5.767,43987.51,0.05292,0.01836,,,,,,
69.3,5.775,43977.4,0.0531,0.01836,,,,,,
69.4,5.783,43964.91,0.05329,0.01836,,,,,,
69.5,5.792,43949.21,0.05347,0.01836,,,,,,
69.6,5.8,43921.73,0.05365,0.01836,,,,,,
69.7,5.808,43903.64,0.05383,0.01836,,,,,,
69.8,5.817,43892.33,0.05402,0.01836,,,,,,
69.9,5.825,43882.52,0.05421,0.01837,,,,,,
70,5.834,43860.02,0.05439,0.01837,,,,,,
70.1,5.842,43842.64,0.05457,0.01837,,,,,,
70.2,5.85,43829.61,0.05476,0.01837,,,,,,
70.3,5.858,43812.38,0.05494,0.01837,,,,,,
70.4,5.867,43801.74,0.05513,0.01837,,,,,,
70.5,5.875,43791.19,0.05531,0.01837,,,,,,
70.6,5.884,43781.61,0.0555,0.01837,,,,,,
70.7,5.892,43770.17,0.05569,0.01838,,,,,,
70.8,5.9,43744.01,0.05587,0.01838,,,,,,
70.9,5.908,43728.17,0.05605,0.01838,,,,,,
71,5.917,43722.72,0.05624,0.01838,,,,,,
71.1,5.925,43692.97,0.05642,0.01838,,,,,,
71.2,5.934,43683.68,0.0566,0.01838,,,,,,
71.3,5.942,43676.33,0.05678,0.01838,,,,,,
71.4,5.95,43658.26,0.05696,0.01838,,,,,,
71.5,5.959,43642.14,0.05715,0.01838,,,,,,
71.6,5.967,43619.72,0.05733,0.01838,,,,,,
71.7,5.975,43604.01,0.0575,0.01838,,,,,,
71.8,5.984,43596.36,0.05768,0.01838,,,,,,
71.9,5.992,43580.79,0.05786,0.01838,,,,,,
72,6,43573.23,0.05804,0.01838,,,,,,
72.1,6.009,43565.16,0.05822,0.01838,,,,,,
72.2,6.017,43553.6,0.0584,0.01839,,,,,,
72.3,6.025,43542.03,0.05857,0.01838,,,,,,
72.4,6.034,43510.68,0.05876,0.01839,,,,,,
72.5,6.042,43488.81,0.05893,0.01839,,,,,,
72.6,6.05,43479.86,0.05912,0.01839,,,,,,
72.7,6.059,43470.84,0.0593,0.01839,,,,,,
72.8,6.067,43445.62,0.05948,0.01839,,,,,,
72.9,6.075,43417.79,0.05966,0.01839,,,,,,
73,6.084,43401.43,0.05983,0.01839,,,,,,
73.1,6.092,43389.8,0.06001,0.01839,,,,,,
73.2,6.1,43381.13,0.0602,0.01839,,,,,,
73.3,6.109,43378.18,0.06038,0.01838,,,,,,
73.4,6.117,43373.15,0.06056,0.01838,,,,,,
73.5,6.125,43355.77,0.06073,0.01838,,,,,,
73.6,6.133,43340.26,0.06091,0.01838,,,,,,
73.7,6.142,43323.5,0.0611,0.01838,,,,,,
73.8,6.15,43291.76,0.06127,0.01838,,,,,,
73.9,6.159,43278.03,0.06145,0.01838,,,,,,
74,6.167,43267.77,0.06163,0.01838,,,,,,
74.1,6.175,43253.62,0.0618,0.01838,,,,,,
74.2,6.184,43237.3,0.06198,0.01838,,,,,,
74.3,6.192,43211.88,0.06217,0.01838,,,,,,
74.4,6.2,43188.45,0.06234,0.01838,,,,,,
74.5,6.209,43181.22,0.06252,0.01838,,,,,,
74.6,6.217,43174.36,0.0627,0.01838,,,,,,
74.7,6.225,43162.31,0.06288,0.01838,,,,,,
74.8,6.233,43152.38,0.06307,0.01838,,,,,,
74.9,6.242,43144.35,0.06326,0.01838,,,,,,
75,6.25,43123.83,0.06345,0.01838,,,,,,
75.1,6.258,43099.51,0.06363,0.01838,,,,,,
75.2,6.267,43083.3,0.06381,0.01837,,,,,,
75.3,6.275,43075.15,0.06399,0.01837,,,,,,
75.4,6.284,43070.96,0.06419,0.01837,,,,,,
75.5,6.292,43047.29,0.06437,0.01837,,,,,,
75.6,6.3,43017.86,0.06455,0.01837,,,,,,
75.7,6.309,42999.34,0.06473,0.01837,,,,,,
75.8,6.317,42984.74,0.06492,0.01837,,,,,,
75.9,6.325,42968.17,0.06511,0.01837,,,,,,
76,6.334,42961.27,0.06529,0.01837,,,,,,
76.1,6.342,42946.11,0.06547,0.01837,,,,,,
76.2,6.35,42938.38,0.06565,0.01837,,,,,,
76.3,6.358,42914.04,0.06583,0.01837,,,,,,
76.4,6.367,42894.75,0.06602,0.01837,,,,,,
76.5,6.375,42877.13,0.0662,0.01837,,,,,,
76.6,6.383,42857.8,0.06639,0.01837,,,,,,
76.7,6.392,42849.65,0.06657,0.01837,,,,,,
76.8,6.4,42833.83,0.06676,0.01836,,,,,,
76.9,6.408,42811.91,0.06694,0.01836,,,,,,
77,6.417,42795.99,0.06713,0.01836,,,,,,
77.1,6.425,42777.16,0.06731,0.01836,,,,,,
77.2,6.434,42769.91,0.06751,0.01836,,,,,,
77.3,6.442,42765.82,0.06769,0.01836,,,,,,
77.4,6.45,42757.34,0.06789,0.01836,,,,,,
77.5,6.459,42742.63,0.06808,0.01836,,,,,,
77.6,6.467,42720.59,0.06827,0.01836,,,,,,
77.7,6.475,42699.82,0.06846,0.01836,,,,,,
77.8,6.484,42675.52,0.06865,0.01836,,,,,,
77.9,6.492,42647.63,0.06885,0.01836,,,,,,
78,6.5,42644.3,0.06904,0.01836,,,,,,
78.1,6.509,42627.23,0.06924,0.01836,,,,,,
78.2,6.517,42603.85,0.06944,0.01836,,,,,,
78.3,6.525,42581.32,0.06963,0.01836,,,,,,
78.4,6.534,42561.3,0.06981,0.01836,,,,,,
78.5,6.542,42552.23,0.07,0.01836,,,,,,
78.6,6.55,42547.29,0.07019,0.01835,,,,,,
78.7,6.559,42539.16,0.07038,0.01835,,,,,,
78.8,6.567,42527.35,0.07057,0.01835,,,,,,
78.9,6.575,42508.68,0.07076,0.01835,,,,,,
79,6.583,42482.84,0.07095,0.01835,,,,,,
79.1,6.592,42464.24,0.07114,0.01835,,,,,,
79.2,6.6,42455.55,0.07133,0.01835,,,,,,
79.3,6.609,42444.8,0.07152,0.01835,,,,,,
79.4,6.617,42408.55,0.07171,0.01835,,,,,,
79.5,6.625,42385.33,0.0719,0.01835,,,,,,
79.6,6.634,42359.21,0.07209,0.01835,,,,,,
79.7,6.642,42347.89,0.07229,0.01835,,,,,,
79.8,6.65,42339.43,0.07248,0.01835,,,,,,
79.9,6.659,42335.93,0.07267,0.01834,,,,,,
80,6.667,42326.12,0.07286,0.01835,,,,,,
80.1,6.675,42304.93,0.07305,0.01834,,,,,,
80.2,6.684,42288.19,0.07325,0.01834,,,,,,
80.3,6.692,42267.14,0.07344,0.01834,,,,,,
80.4,6.7,42248.13,0.07363,0.01834,,,,,,
80.5,6.709,42236.16,0.07383,0.01834,,,,,,
80.6,6.717,42211.14,0.07402,0.01834,,,,,,
80.7,6.725,42195.41,0.07422,0.01834,,,,,,
80.8,6.734,42174.92,0.07441,0.01834,,,,,,
80.9,6.742,42158.61,0.0746,0.01834,,,,,,
81,6.75,42150.86,0.0748,0.01834,,,,,,
81.1,6.758,42141.46,0.07498,0.01834,,,,,,
81.2,6.767,42127.44,0.07518,0.01834,,,,,,
81.3,6.775,42103.54,0.07538,0.01833,,,,,,
81.4,6.784,42078.23,0.07557,0.01833,,,,,,
81.5,6.792,42046.15,0.07577,0.01833,,,,,,
81.6,6.8,42032.13,0.07596,0.01833,,,,,,
81.7,6.809,42024.89,0.07617,0.01833,,,,,,
81.8,6.817,42004.82,0.07637,0.01834,,,,,,
81.9,6.825,41981.26,0.07656,0.01834,,,,,,
82,6.834,41966.02,0.07677,0.01833,,,,,,
82.1,6.842,41948.91,0.07696,0.01833,,,,,,
82.2,6.85,41939.4,0.07715,0.01833,,,,,,
82.3,6.858,41930.24,0.07735,0.01833,,,,,,
82.4,6.867,41922.07,0.07755,0.01833,,,,,,
82.5,6.875,41904.54,0.07774,0.01833,,,,,,
82.6,6.883,41880.54,0.07794,0.01833,,,,,,
82.7,6.892,41860.13,0.07813,0.01833,,,,,,
82.8,6.9,41845.2,0.07832,0.01833,,,,,,
82.9,6.908,41823.29,0.07852,0.01833,,,,,,
83,6.917,41796.86,0.07872,0.01833,,,,,,
83.1,6.925,41773.07,0.07892,0.01833,,,,,,
83.2,6.933,41744.08,0.07912,0.01832,,,,,,
83.3,6.942,41725.7,0.07932,0.01832,,,,,,
83.4,6.95,41723.11,0.07953,0.01832,,,,,,
83.5,6.958,41716.29,0.07972,0.01832,,,,,,
83.6,6.967,41699.43,0.07992,0.01832,,,,,,
83.7,6.975,41681.95,0.08011,0.01832,,,,,,
83.8,6.983,41660.59,0.08031,0.01832,,,,,,
83.9,6.992,41632.15,0.0805,0.01832,,,,,,
84,7,41623.26,0.0807,0.01832,,,,,,
84.1,7.009,41610.21,0.08089,0.01832,,,,,,
84.2,7.017,41577.83,0.08108,0.01832,,,,,,
84.3,7.025,41559,0.08129,0.01832,,,,,,
84.4,7.034,41544,0.08149,0.01832,,,,,,
84.5,7.042,41526.58,0.08169,0.01832,,,,,,
84.6,7.05,41515.15,0.08188,0.01832,,,,,,
84.7,7.059,41502.45,0.08207,0.01832,,,,,,
84.8,7.067,41470.66,0.08227,0.01831,,,,,,
84.9,7.075,41448.32,0.08247,0.01831,,,,,,
85,7.084,41431.4,0.08267,0.01831,,,,,,
85.1,7.092,41415.81,0.08287,0.01831,,,,,,
85.2,7.1,41401.43,0.08307,0.01831,,,,,,
85.3,7.108,41378.85,0.08327,0.01831,,,,,,
85.4,7.117,41360.21,0.08348,0.01831,,,,,,
85.5,7.125,41337.48,0.08368,0.01831,,,,,,
85.6,7.134,41318.14,0.08387,0.01831,,,,,,
85.7,7.142,41310.68,0.08408,0.01831,,,,,,
85.8,7.15,41297.68,0.08428,0.01831,,,,,,
85.9,7.159,41270.12,0.08448,0.0183,,,,,,
86,7.167,41241.31,0.08469,0.0183,,,,,,
86.1,7.175,41219.58,0.08488,0.0183,,,,,,
86.2,7.184,41211.84,0.08509,0.0183,,,,,,
86.3,7.192,41182.55,0.08529,0.0183,,,,,,
86.4,7.2,41148.85,0.0855,0.0183,,,,,,
86.5,7.208,41127.63,0.08571,0.0183,,,,,,
86.6,7.217,41115.32,0.08592,0.0183,,,,,,
86.7,7.225,41111.39,0.08612,0.0183,,,,,,
86.8,7.234,41099.98,0.08633,0.0183,,,,,,
86.9,7.242,41088.34,0.08654,0.0183,,,,,,
87,7.25,41057.62,0.08674,0.01829,,,,,,
87.1,7.259,41032.68,0.08695,0.0183,,,,,,
87.2,7.267,41010.52,0.08717,0.0183,,,,,,
87.3,7.275,41004.43,0.08738,0.01829,,,,,,
87.4,7.284,40970.79,0.0876,0.0183,,,,,,
87.5,7.292,40942.98,0.08781,0.01829,,,,,,
87.6,7.3,40923.27,0.08803,0.01829,,,,,,
87.7,7.309,40909.28,0.08824,0.01829,,,,,,
87.8,7.317,40892.03,0.08847,0.01829,,,,,,
87.9,7.325,40878.16,0.08869,0.01829,,,,,,
88,7.334,40852.91,0.0889,0.01829,,,,,,
88.1,7.342,40824.07,0.08911,0.01829,,,,,,
88.2,7.35,40804.11,0.08932,0.01829,,,,,,
88.3,7.359,40798.63,0.08955,0.01829,,,,,,
88.4,7.367,40777.2,0.08976,0.01829,,,,,,
88.5,7.375,40751.62,0.08998,0.01829,,,,,,
88.6,7.383,40718.99,0.09019,0.01829,,,,,,
88.7,7.392,40700.07,0.09041,0.01829,,,,,,
88.8,7.4,40687.38,0.09062,0.01829,,,,,,
88.9,7.408,40672.13,0.09083,0.01829,,,,,,
89,7.417,40656.54,0.09104,0.01829,,,,,,
89.1,7.425,40624.15,0.09125,0.01829,,,,,,
89.2,7.433,40599.59,0.09146,0.01829,,,,,,
89.3,7.442,40585.96,0.09168,0.01828,,,,,,
89.4,7.45,40559.38,0.09189,0.01828,,,,,,
89.5,7.459,40530.21,0.09211,0.01828,,,,,,
89.6,7.467,40509.74,0.09232,0.01828,,,,,,
89.7,7.475,40500.98,0.09254,0.01828,,,,,,
89.8,7.483,40482.94,0.09276,0.01828,,,,,,
89.9,7.492,40472.73,0.09298,0.01828,,,,,,
90,7.5,40450.35,0.09319,0.01828,,,,,,
90.1,7.509,40414.91,0.09341,0.01828,,,,,,
90.2,7.517,40384.26,0.09363,0.01828,,,,,,
90.3,7.525,40370.82,0.09385,0.01828,,,,,,
90.4,7.534,40342.23,0.09407,0.01828,,,,,,
90.5,7.542,40320.95,0.09429,0.01828,,,,,,
90.6,7.55,40298.06,0.09452,0.01828,,,,,,
90.7,7.559,40280.78,0.09474,0.01828,,,,,,
90.8,7.567,40267.81,0.09496,0.01827,,,,,,
90.9,7.575,40247.39,0.09518,0.01827,,,,,,
91,7.584,40230.03,0.09541,0.01828,,,,,,
91.1,7.592,40192.8,0.09564,0.01827,,,,,,
91.2,7.6,40177.01,0.09586,0.01827,,,,,,
91.3,7.609,40151.91,0.09607,0.01827,,,,,,
91.4,7.617,40112.79,0.09628,0.01827,,,,,,
91.5,7.625,40089.86,0.09649,0.01827,,,,,,
91.6,7.634,40079.85,0.09671,0.01827,,,,,,
91.7,7.642,40061.14,0.09694,0.01827,,,,,,
91.8,7.65,40047.15,0.09716,0.01827,,,,,,
91.9,7.658,40023.81,0.09738,0.01827,,,,,,
92,7.667,39988.96,0.0976,0.01827,,,,,,
92.1,7.675,39973.17,0.09783,0.01827,,,,,,
92.2,7.684,39942.55,0.09805,0.01826,,,,,,
92.3,7.692,39914.45,0.09828,0.01826,,,,,,
92.4,7.7,39891.6,0.0985,0.01826,,,,,,
92.5,7.708,39875.54,0.09873,0.01826,,,,,,
92.6,7.717,39863.63,0.09895,0.01826,,,,,,
92.7,7.725,39843.38,0.09918,0.01826,,,,,,
92.8,7.734,39811.94,0.0994,0.01826,,,,,,
92.9,7.742,39778.14,0.09964,0.01826,,,,,,
93,7.75,39759.11,0.09987,0.01826,,,,,,
93.1,7.759,39738.68,0.1001,0.01826,,,,,,
93.2,7.767,39711.73,0.10032,0.01826,,,,,,
93.3,7.775,39678.58,0.10055,0.01826,,,,,,
93.4,7.784,39663.48,0.10078,0.01825,,,,,,
93.5,7.792,39649.08,0.10101,0.01825,,,,,,
93.6,7.8,39624.47,0.10123,0.01825,,,,,,
93.7,7.809,39601.34,0.10146,0.01825,,,,,,
93.8,7.817,39555.97,0.10169,0.01825,,,,,,
93.9,7.825,39540.88,0.10192,0.01825,,,,,,
94,7.833,39509.23,0.10215,0.01825,,,,,,
94.1,7.842,39478.02,0.10238,0.01825,,,,,,
94.2,7.85,39459.74,0.10261,0.01825,,,,,,
94.3,7.859,39449.72,0.10285,0.01825,,,,,,
94.4,7.867,39441.75,0.10308,0.01825,,,,,,
94.5,7.875,39409.53,0.10331,0.01824,,,,,,
94.6,7.883,39372.02,0.10354,0.01824,,,,,,
94.7,7.892,39350.89,0.10378,0.01824,,,,,,
94.8,7.9,39322.92,0.10402,0.01824,,,,,,
94.9,7.909,39291.04,0.10425,0.01824,,,,,,
95,7.917,39255.6,0.10449,0.01824,,,,,,
95.1,7.925,39246.36,0.10472,0.01824,,,,,,
95.2,7.934,39232.22,0.10496,0.01824,,,,,,
95.3,7.942,39202.41,0.1052,0.01823,,,,,,
95.4,7.95,39161.8,0.10544,0.01824,,,,,,
95.5,7.958,39145.38,0.10567,0.01823,,,,,,
95.6,7.967,39128.07,0.10591,0.01823,,,,,,
95.7,7.975,39096.91,0.10615,0.01823,,,,,,
95.8,7.984,39058.15,0.10639,0.01823,,,,,,
95.9,7.992,39039.4,0.10663,0.01823,,,,,,
96,8,39029.29,0.10688,0.01823,,,,,,
96.1,8.009,38992.9,0.10712,0.01823,,,,,,
96.2,8.017,38954.98,0.10735,0.01823,,,,,,
96.3,8.025,38932.38,0.10759,0.01823,,,,,,
96.4,8.034,38909,0.10784,0.01823,,,,,,
96.5,8.042,38868.84,0.10808,0.01823,,,,,,
96.6,8.05,38851.36,0.10832,0.01823,,,,,,
96.7,8.058,38838.42,0.10856,0.01823,,,,,,
96.8,8.067,38824.78,0.1088,0.01823,,,,,,
96.9,8.075,38796.09,0.10904,0.01823,,,,,,
97,8.084,38749.95,0.10929,0.01822,,,,,,
97.1,8.092,38720.51,0.10954,0.01822,,,,,,
97.2,8.1,38686.53,0.10978,0.01822,,,,,,
97.3,8.108,38653.28,0.11003,0.01822,,,,,,
97.4,8.117,38631.76,0.11027,0.01822,,,,,,
97.5,8.125,38619.82,0.11051,0.01822,,,,,,
97.6,8.134,38596.77,0.11076,0.01822,,,,,,
97.7,8.142,38564.76,0.11101,0.01822,,,,,,
97.8,8.15,38535.46,0.11125,0.01822,,,,,,
97.9,8.159,38514.68,0.11149,0.01822,,,,,,
98,8.167,38476.35,0.11175,0.01822,,,,,,
98.1,8.175,38436.6,0.112,0.01822,,,,,,
98.2,8.184,38413.81,0.11225,0.01821,,,,,,
98.3,8.192,38395.94,0.11249,0.01821,,,,,,
98.4,8.2,38360.17,0.11274,0.01821,,,,,,
98.5,8.209,38326.84,0.11299,0.01821,,,,,,
98.6,8.217,38306.42,0.11325,0.01821,,,,,,
98.7,8.225,38271.24,0.11349,0.01821,,,,,,
98.8,8.234,38244.49,0.11374,0.01821,,,,,,
98.9,8.242,38223.33,0.11399,0.01821,,,,,,
99,8.25,38212.7,0.11424,0.01821,,,,,,
99.1,8.259,38166.37,0.11449,0.0182,,,,,,
99.2,8.267,38125.19,0.11474,0.01821,,,,,,
99.3,8.275,38105.14,0.115,0.01821,,,,,,
99.4,8.284,38061.16,0.11525,0.0182,,,,,,
99.5,8.292,38025.93,0.1155,0.0182,,,,,,
99.6,8.3,38013.57,0.11574,0.0182,,,,,,
99.7,8.309,38000.43,0.116,0.0182,,,,,,
99.8,8.317,37967.2,0.11625,0.01819,,,,,,
99.9,8.325,37916.45,0.1165,0.01819,,,,,,
100,8.334,37900.52,0.11674,0.01819,,,,,,
100.1,8.342,37853.29,0.117,0.01819,,,,,,
100.2,8.35,37815.32,0.11726,0.01819,,,,,,
100.3,8.359,37792.09,0.1175,0.01819,,,,,,
100.4,8.367,37778.36,0.11775,0.01819,,,,,,
100.5,8.375,37748.39,0.118,0.01819,,,,,,
100.6,8.384,37713.79,0.11826,0.01819,,,,,,
100.7,8.392,37697.51,0.11852,0.01819,,,,,,
100.8,8.4,37646.11,0.11877,0.01819,,,,,,
100.9,8.409,37614.14,0.11903,0.01819,,,,,,
101,8.417,37594.52,0.11929,0.01819,,,,,,
101.1,8.425,37563.42,0.11954,0.01819,,,,,,
101.2,8.434,37517.53,0.11979,0.01818,,,,,,
101.3,8.442,37486.48,0.12005,0.01818,,,,,,
101.4,8.45,37455.32,0.12032,0.01818,,,,,,
101.5,8.458,37422.73,0.12058,0.01818,,,,,,
101.6,8.467,37398.26,0.12083,0.01818,,,,,,
101.7,8.475,37374.91,0.12109,0.01818,,,,,,
101.8,8.484,37345.41,0.12135,0.01818,,,,,,
101.9,8.492,37294.68,0.12161,0.01818,,,,,,
102,8.5,37265.66,0.12186,0.01818,,,,,,
102.1,8.508,37213.72,0.12211,0.01818,,,,,,
102.2,8.517,37185.7,0.12237,0.01818,,,,,,
102.3,8.525,37180.11,0.12263,0.01818,,,,,,
102.4,8.534,37150.32,0.12288,0.01817,,,,,,
102.5,8.542,37102.65,0.12315,0.01817,,,,,,
102.6,8.55,37081.23,0.12341,0.01817,,,,,,
102.7,8.558,37037.54,0.12366,0.01817,,,,,,
102.8,8.567,36997.67,0.12393,0.01817,,,,,,
102.9,8.575,36980.78,0.1242,0.01817,,,,,,
103,8.584,36942.47,0.12446,0.01817,,,,,,
103.1,8.592,36898.14,0.12472,0.01817,,,,,,
103.2,8.6,36877.53,0.12497,0.01817,,,,,,
103.3,8.609,36840.3,0.12522,0.01817,,,,,,
103.4,8.617,36793.56,0.12549,0.01817,,,,,,
103.5,8.625,36772.77,0.12575,0.01817,,,,,,
103.6,8.634,36748.16,0.12601,0.01817,,,,,,
103.7,8.642,36701.34,0.12628,0.01816,,,,,,
103.8,8.65,36663.33,0.12654,0.01816,,,,,,
103.9,8.659,36620.68,0.12681,0.01816,,,,,,
104,8.667,36582.43,0.12708,0.01816,,,,,,
104.1,8.675,36568.59,0.12735,0.01816,,,,,,
104.2,8.684,36529.78,0.12761,0.01816,,,,,,
104.3,8.692,36487.89,0.12787,0.01816,,,,,,
104.4,8.7,36456.77,0.12815,0.01816,,,,,,
104.5,8.709,36411.95,0.12842,0.01815,,,,,,
104.6,8.717,36370.88,0.12869,0.01815,,,,,,
104.7,8.725,36350.12,0.12896,0.01815,,,,,,
104.8,8.733,36313.85,0.12923,0.01815,,,,,,
104.9,8.742,36272.66,0.1295,0.01815,,,,,,
105,8.75,36234.25,0.12978,0.01815,,,,,,
105.1,8.759,36183.15,0.13005,0.01815,,,,,,
105.2,8.767,36154.05,0.13032,0.01815,,,,,,
105.3,8.775,36126.63,0.13059,0.01814,,,,,,
105.4,8.784,36092.63,0.13087,0.01814,,,,,,
105.5,8.792,36054.6,0.13115,0.01814,,,,,,
105.6,8.8,36006.7,0.13143,0.01814,,,,,,
105.7,8.809,35962.47,0.1317,0.01814,,,,,,
105.8,8.817,35943.01,0.13198,0.01814,,,,,,
105.9,8.825,35906.53,0.13226,0.01814,,,,,,
106,8.834,35848.84,0.13255,0.01814,,,,,,
106.1,8.842,35814.55,0.13283,0.01814,,,,,,
106.2,8.85,35771.27,0.13311,0.01814,,,,,,
106.3,8.859,35745.17,0.13338,0.01814,,,,,,
106.4,8.867,35705.64,0.13366,0.01813,,,,,,
106.5,8.875,35667.38,0.13394,0.01814,,,,,,
106.6,8.884,35623.91,0.13422,0.01813,,,,,,
106.7,8.892,35574.19,0.13451,0.01813,,,,,,
106.8,8.9,35532.9,0.13479,0.01813,,,,,,
106.9,8.909,35511.24,0.13508,0.01813,,,,,,
107,8.917,35473.01,0.13536,0.01813,,,,,,
107.1,8.925,35424.22,0.13565,0.01813,,,,,,
107.2,8.934,35362.74,0.13593,0.01812,,,,,,
107.3,8.942,35325.4,0.13621,0.01812,,,,,,
107.4,8.95,35299.21,0.1365,0.01812,,,,,,
107.5,8.959,35243.08,0.13679,0.01812,,,,,,
107.6,8.967,35216.9,0.13707,0.01812,,,,,,
107.7,8.975,35164.09,0.13736,0.01812,,,,,,
107.8,8.984,35119.83,0.13765,0.01812,,,,,,
107.9,8.992,35083.83,0.13795,0.01812,,,,,,
108,9,35019.73,0.13824,0.01812,,,,,,
108.1,9.008,34968.69,0.13854,0.01812,,,,,,
108.2,9.017,34925.48,0.13883,0.01812,,,,,,
108.3,9.025,34906.25,0.13912,0.01811,,,,,,
108.4,9.034,34849.23,0.13942,0.01811,,,,,,
108.5,9.042,34778.47,0.13972,0.01811,,,,,,
108.6,9.05,34717.77,0.14002,0.01811,,,,,,
108.7,9.059,34693.38,0.14032,0.01811,,,,,,
108.8,9.067,34634.11,0.14063,0.01811,,,,,,
108.9,9.075,34575.52,0.14094,0.01811,,,,,,
109,9.084,34505.14,0.14125,0.01811,,,,,,
109.1,9.092,34451.66,0.14157,0.01811,,,,,,
109.2,9.1,34365.6,0.14189,0.0181,,,,,,
109.3,9.109,34257.94,0.14226,0.0181,,,,,,
109.4,9.117,34040.96,0.1427,0.01809,,,,,,
109.5,9.125,33454.04,0.14344,0.01808,,,,,,
109.552,9.13,16728.68,0.15167,0.01792,,,,,,